Workbook

Sheet Exited_had_CN
A1: Company
A2: 3M
A3: Aisin
A4: Apollo Global Management
A5: Bank of New York Mellon
A6: EXOR Group
A7: General Electric
A8: JFE Holdings
A9: Jabil
A10: L'Oreal
A11: Nippon Steel Corporation
A12: Nippon Telegraph and Telephone
... A15: Vibra Energia

Sheet Exited_no_CN
A1: Company
A2: AIG
A3: Arrow Electronics
A4: Aviation Industry Corp. of China
A5: Bunge
A6: Caixa Economica Federal
A7: Centrica
A8: China Electronics Technology Group
A9: China National Nuclear
A10: China State Shipbuilding
A11: Credit Mutuel Group
A12: Fomento Economico Mexicano
... A23: Truist Financial

Sheet Stayed_CN_to_CN
A1: Company
A2: Alibaba Group Holding
A3: Alimentation Couche-Tard
A4: Apple
A5: BNP Paribas
A6: Bank of China
A7: Bosch Group
A8: COSCO Shipping
A9: Carrefour
A10: Charter Communications
A11: China State Construction Engineering
A12: Cigna
... A65: Zijin Mining Group

Sheet Stayed_CN_to_No
A1: Company | B1: 2024_NZ | C1: 2024_CN | D1: 2024_CC | E1: 2025_SBTi | F1: 2025_Net_Zero | G1: 2025_CN | H1: 2025_Carbon_Credits | I1: carbon credit note | J1: Column1 | K1: Column2
A2: ACS | C2: 1 | E2: 0 | F2: 0 | G2: 0 | H2: 1
A3: AT&T | C3: 1 | D3: 1 | E3: 1 | F3: 1 | G3: 0 | H3: 1
A4: AXA | B4: 1 | C4: 1 | D4: 1 | E4: 1 | F4: 1 | G4: 0 | H4: 1
A5: Allianz | B5: 1 | C5: 1 | D5: 1 | E5: 0 | F5: 1 | G5: 0 | H5: 0 | I5: Carbon removal and carbon credits In the past reporting year, we did not use carbon removal and associated carbon credits when accounting for our GHG and the associated reduction targets. Our net-zero targets will likely require the use of atmospheric carbon removal in the respective net-zero targets year. For this, we expect to only use high-quality carbon removal. Our focus remains on GHG emission reductions | J5: https://www.allianz.com/content/dam/onemarketing/azcom/Allianz_com/sustainability/documents/Allianz_Group_Sustainability_Report_2023-web.pdf
A6: American Express | B6: 1 | C6: 1 | D6: 1 | E6: 1 | F6: 1 | G6: 0 | H6: 1
A7: ArcelorMittal | B7: 1 | C7: 1 | D7: 1 | E7: 0 | F7: 1 | G7: 0 | H7: 1
A8: BMW Group | B8: 1 | C8: 1 | D8: 1 | E8: 1 | F8: 0 | G8: 0 | H8: 1
A9: Banco Bilbao Vizcaya Argentaria | B9: 1 | C9: 1 | D9: 1 | E9: 0 | F9: 1 | G9: 0 | H9: 1
A10: Banco Bradesco | B10: 1 | C10: 1 | D10: 1 | E10: 0 | F10: 1 | G10: 0 | H10: 1
A11: Banco Santander | B11: 1 | C11: 1 | D11: 1 | E11: 0 | F11: 1 | G11: 0 | H11: 1
A12: Banco do Brasil | C12: 1 | D12: 1 | E12: 1 | F12: 0 | G12: 0 | H12: 1
A13: Bank of America | B13: 1 | C13: 1 | D13: 1 | E13: 0 | F13: 1 | G13: 0 | H13: 1
A14: Bank of Montreal | B14: 1 | C14: 1 | D14: 1 | E14: 0 | F14: 0 | G14: 0 | H14: 1
A15: Bank of Nova Scotia | B15: 1 | C15: 1 | D15: 1 | E15: 0 | F15: 1 | G15: 0 | H15: 1
A16: Bayer | B16: 1 | C16: 1 | D16: 1 | E16: 1 | F16: 1 | G16: 0 | H16: 0
A17: Best Buy | B17: 1 | C17: 1 | D17: 1 | E17: 1 | F17: 1 | G17: 0 | H17: 0
A18: Boeing | C18: 1 | D18: 1 | E18: 0 | F18: 0 | G18: 0 | H18: 1
A19: CRRC Group | C19: 1 | E19: 0 | F19: 0 | G19: 0 | H19: 0 | I19: Government aligned | J19: https://crrcgc.cc/Portals/73/Uploads/Files/2024/4-25/638496536538053810.pdf
A20: CVS Health | B20: 1 | C20: 1 | E20: 1 | F20: 1 | G20: 0 | H20: 0
A21: Canadian Imperial Bank of Commerce | B21: 1 | C21: 1 | D21: 1 | E21: 0 | F21: 1 | G21: 0 | H21: 1
A22: Capital One Financial | C22: 1 | E22: 0 | F22: 0 | G22: 0 | H22: 0 | I22: emission reduction not cn
A23: China Baowu Steel Group | C23: 1 | E23: 0 | F23: 0 | G23: 0 | H23: 1 | I23: dual | J23: https://www.bhp-china.cn/media-and-insights/news/2023/12/bhp-completes-pilot-carbon-offset-transaction-with-baowu.html
A24: China National Offshore Oil | C24: 1 | D24: 1 | E24: 0 | F24: 0 | G24: 0 | H24: 1 | I24: dual
A25: Commonwealth Bank of Australia | B25: 1 | C25: 1 | D25: 1 | E25: 0 | F25: 1 | G25: 0 | H25: 1
A26: Compass Group | B26: 1 | C26: 1 | D26: 1 | E26: 1 | F26: 1 | G26: 0 | H26: 0
A27: Contemporary Amperex Technology | C27: 1 | E27: 0 | F27: 0 | G27: 0 | H27: 0 | I27: dual
A28: Credit Agricole | C28: 1 | D28: 1 | E28: 1 | F28: 1 | G28: 0 | H28: 0
A29: DZ Bank | C29: 1 | D29: 1 | E29: 0 | F29: 1 | G29: 0 | H29: 0
A30: Delta Air Lines | B30: 1 | C30: 1 | D30: 1 | E30: 1 | F30: 1 | G30: 0 | H30: 0
A31: Deutsche Bahn | C31: 1 | E31: 1 | F31: 1 | G31: 0 | H31: 1
A32: ENI | B32: 1 | C32: 1 | D32: 1 | E32: 0 | F32: 1 | G32: 0 | H32: 1
A33: Elevance Health | B33: 1 | C33: 1 | E33: 1 | F33: 1 | G33: 0 | H33: 1
A34: Equinor | B34: 1 | C34: 1 | E34: 0 | F34: 1 | G34: 0 | H34: 1
A35: General Dynamics | C35: 1 | E35: 0 | F35: 0 | G35: 0 | H35: 0 | I35: subs have nz , company itself has other goals that will put them in the path of neutrality but that’s not mentioned as a target | J35: https://www.gd.com/responsibility/environmental-responsibility
A36: Goldman Sachs Group | B36: 1 | C36: 1 | D36: 1 | E36: 0 | F36: 1 | G36: 0 | H36: 1
A37: Groupe BPCE | C37: 1 | D37: 1 | E37: 0 | F37: 1 | G37: 0 | H37: 0
A38: HBIS Group | C38: 1 | E38: 0 | F38: 0 | G38: 0 | H38: 0 | I38: gov aligned
A39: HP | B39: 1 | C39: 1 | D39: 1 | E39: 1 | F39: 1 | G39: 0 | H39: 1
A40: Heineken | B40: 1 | C40: 1 | E40: 1 | F40: 1 | G40: 0 | H40: 1
...

Sheet Stayed_No_to_CN
A1: Company
A2: BYD
A3: CITIC Group
A4: China Huaneng Group
A5: China Merchants Bank
A6: China Railway Construction
A7: GS Caltex
A8: HD Hyundai
A9: HDFC Bank
A10: Hunan Iron & Steel Group
A11: Industrial Bank
A12: Jiangxi Copper
... A22: X5 Retail Group

Sheet Stayed_No_to_No
A1: Company
A2: ABB
A3: AEON
A4: AIA Group
A5: ANZ Group Holdings
A6: AbbVie
A7: Abbott Laboratories
A8: Accenture
A9: Agricultural Bank of China
A10: Air France-KLM Group
A11: Airbus
A12: Albertsons
... A289: Zhejiang Rongsheng Holding Group

Sheet Added_with_CN
A1: Company
A2: Amgen
A3: ICICI Bank
A4: JerÃ³nimo Martins
A5: Nippon Steel

Sheet Added_no_CN
A1: Company
A2: BAE Systems
A3: Bank of New York (BNY)
A4: Bunge Global
A5: CBRE Group
A6: Caixa EconÃ´mica Federal
A7: China General Technology
A8: Country Garden Holdings
A9: CrÃ©dit Mutuel Group
A10: Fomento EconÃ³mico Mexicano
A11: GE Vernova
A12: General Electric (GE Aerospace)
... A29: Shandong Gold Group
A30: St. James's Place | C30: cc | D30: nz-portfolio | E30: cn | F30: We joined the Net Zero Asset Owner Alliance (NZAOA) in 2020, making a public commitment that all our investment portfolios will be carbon neutral by 2050. We also became a signatory to United Nations Global Compact in 2020. | G30: https://www.sjp.co.uk/sites/sjp-corp/files/SJP/shareholders/esg-reporting-hub/2025_Carbon_Disclosure_Project_Climate_Change_Questionnaire.pdf
A31: Sumitomo Life Insurance
A32: Westpac Banking
A33: Wistron | B33: had sbt and net zero in the file | C33: sbti short | D33: nz | E33: cv | G33: https://esg.wistron.com/en/environment/TCNFD/ClimateGoals

Sheet all no cn
A1: all no cn | B1: 2025 | C1: 2024 | D1: why difference
A2: =Added_no_CN!A2 -> BAE Systems
A3: =Added_no_CN!A3 -> Bank of New York (BNY)
A4: =Added_no_CN!A4 -> Bunge Global
A5: =Added_no_CN!A5 -> CBRE Group
A6: =Added_no_CN!A6 -> Caixa EconÃ´mica Federal
A7: =Added_no_CN!A7 -> China General Technology
A8: =Added_no_CN!A8 -> Country Garden Holdings
A9: =Added_no_CN!A9 -> CrÃ©dit Mutuel Group
A10: =Added_no_CN!A10 -> Fomento EconÃ³mico Mexicano
A11: =Added_no_CN!A11 -> GE Vernova
A12: =Added_no_CN!A12 -> General Electric (GE Aerospace)
A13: =Added_no_CN!A13 -> GuideWell Mutual Holding
... A33: =Added_no_CN!A33 -> Wistron
A34: =Stayed_CN_to_No!A2 -> ACS
A35: =Stayed_CN_to_No!A3 -> AT&T
A36: =Stayed_CN_to_No!A4 -> AXA
A37: =Stayed_CN_to_No!A5 -> Allianz
A38: =Stayed_CN_to_No!A6 -> American Express
A39: =Stayed_CN_to_No!A7 -> ArcelorMittal
A40: =Stayed_CN_to_No!A8 -> BMW Group
A41: =Stayed_CN_to_No!A9 -> Banco Bilbao Vizcaya Argentaria
A42: =Stayed_CN_to_No!A10 -> Banco Bradesco
A43: =Stayed_CN_to_No!A11 -> Banco Santander
A44: =Stayed_CN_to_No!A12 -> Banco do Brasil
A45: =Stayed_CN_to_No!A13 -> Bank of America
... A351: =Stayed_CN_to_No!A319 -> 0
