Workbook
Name GF500_DB: "C:\Users\AniyaBegheri\FG500\[GF500_Database_Merged.csv.xlsx]Table1'"

Sheet FG500_DataCollection_FY26 (2)
A1: Profile (FG500) | D1: Details (FG500) | N1: RE100 | Q1: SBTi | AC1: NZ Tracker Definition | AI1: Carbon Neutral | AO1: Net Zero | AV1: Use of carbon credits | AX1: Other reduction targets | BD1: Other | BG1: Binary | CL1: actions include all | CP1: number of companies with any commitments | CT1: DO NOT REOVE
CW2: 2024 Data | CX2: 2024 Data | CY2: 2024 Data | CZ2: 2024 Data | DA2: 2024 Data | DB2: 2024 Data | DC2: 2024 Data | DD2: 2024 Data | DE2: 2024 Data | DF2: 2024 Data | DG2: 2024 Data | DH2: 2024 Data | DI2: 2024 Data | DJ2: 2024 Data | DK2: 2024 Data | DL2: 2024 Data | DM2: 2024 Data | DN2: 2024 Data | DO2: 2024 Data | DP2: 2024 Data | DQ2: 2024 Data | DR2: 2024 Data | DS2: 2024 Data | DT2: Last year checks | DZ2: this year
A3: 2025 Rank | B3: 2024 rank | C3: Company name | D3: Sector (Fortune) | E3: Sector (final classification) | F3: Country | G3: Region | H3: Revenue ($M) usable | I3: Profits ($M) usable | J3: Profits (% change) | K3: Assets ($M) | L3: Employees | M3: Years on list (2025) | N3: RE100 (Y/N) | O3: Joining year | P3: Target year | Q3: In SBTI database? | R3: Near Term SBT (Y = yes, N=no) | S3: Target status (T = target set, C = committed, N=No, R=Removed) | T3: Target classification (near term) - temp | U3: Target year (near term) (earlier of the two dates if there were two) | V3: Long term - Target Status | W3: Long term - Target Classification | X3: Long term - Target Year | Y3: Net zero committed (SBTi) (Y = yes, N = no) | Z3: SBTi NZ Target Status | AA3: Net zero Target year (SBTi) | AB3: notes | AC3: NZ Tracker_End target (in their words) | AD3: NZ Tracker Target Grouping | AE3: Scope 1 | AF3: Scope 2 | AG3: Scope 3 | AH3: Carbon neutral scope(s) - Scope 1,2,3 (NZ Tracker) | AI3: Carbon neutral commitment (C = company, V = value chain, G= Government, S=Subsidiary, U = unspecified, N=no) | AJ3: CN (Y/N) | AK3: Carbon neutral claim (in their words) | AL3: Target year | AM3: Source | AN3: Notes (including climate positive) | AO3: Net zero commitment (V = value chain, C = company, U = unclear, S=Subsidiary) | AP3: NZ (Y/N) | AQ3: Primary net zero scope (in their words) | AR3: Primary net zero claim (in their words) | AS3: Net zero target year | AT3: Source | AU3: Notes | AV3: Carbon credits (Y = yes, N = no, R = removals only, U = unclear).1 | AW3: Removals | AX3: Separate Removal Target | AY3: Other reduction target (Y = yes) (either companies w/ no SBT or w/ SBT "C") | AZ3: Target details (Text) | BA3: Target Year | BB3: Source | BC3: Notes | BD3: Who did it? | BE3: When? | BF3: Oher Sources | BG3: RE100 <=2024 | BH3: RE100 2025-2030 | BI3: RE100>2030 | BJ3: All RE | BK3: SBTi ST <= 2025 | BL3: SBTi ST 2026-2030 | BM3: SBTi ST > 2030 | BN3: All SBTi ST | BO3: SBTi NZ <= 2024 | BP3: SBTi NZ 2026-2030 | BQ3: SBTi NZ > 2030 | BR3: Other NZ <= 2025 | BS3: Other NZ 2025-2030 | BT3: Other NZ > 2030 | BU3: CN <=2025 | BV3: CN 2026-2030 | BW3: CN 2031-2060 | BX3: CN <= 2024 | BY3: CN 2025-2030 | BZ3: CN > 2030 | CA3: All CN | CB3: ALL CN | CC3: Total NZ <=2025 | CD3: Total NZ 2026-2030 | CE3: Total NZ > 2030 | CF3: All NZ | CG3: CN/NZ-OLD | CH3: CN?NZ-NEW | CI3: Other Emission Reduction <=2024 | CJ3: Other Emission Reduction 2025-2030 | CK3: Other Emission Reduction > 2030 | CL3: actions already achieved | CM3: actions due by 2030 | CN3: actions due after 2030 | CO3: ALL Actions | CP3: One of the actions | CQ3: Carbon Credits (Y) | CR3: Carbon Credits (No) | CS3: Carbon Credits (Not Specified) | CT3: SBTi ST 2026-2030 | CU3: NZ both | CV3: NZ latest target year | CW3: CN already achieved | CX3: CN 2024-2030 | CY3: CN 2031-2050 | CZ3: Any CN | DA3: NZ already achieved | DB3: NZ 2024-2030 | DC3: NZ 2031-2050 | DD3: Any NZ | DE3: SBT already achieved | DF3: SBT 2024-2030 | DG3: SBT 2031-2050 | DH3: Any SBT | DI3: RE100 already achieved | DJ3: RE100 2024-2030 | DK3: RE100 2031-2050 | DL3: Any RE100 | DM3: CN/NZ - IF THE COMPANY HAS A Ccn or nz target | DN3: CN/NZ 2030 | DO3: CN/NZ 2050 | DP3: will use cabon credits | DQ3: will NOT use carbon credits | DR3: any target | DS3: any target already achived | DT3: sbti | DU3: nz-sbti | DV3: nz | DW3: cn | DX3: cn-cc | DY3: nz-cc | DZ3: sbti | EA3: nz-sbti | EB3: nz | EC3: cn | ED3: cn-cc | EE3: nz-cc | EF3: nz years
A4: 1 | B4: 1 | C4: Walmart | D4: General Merchandisers | E4: Retail | F4: U.S. | G4: North America | H4: $680,985 | I4: $19,436 | J4: 0.253 | K4: $260,823 | L4: 2100000 | M4: 31 | N4: Y | O4: 2015 | P4: 2035 | Q4: Y | R4: Y | S4: Targets set | T4: 1.5°C | U4: 2030 | Y4: N | Z4: Commitment removed | AC4: Zero emissions | AD4: Net Zero | AE4: Yes | AF4: Yes | AG4: No | AH4: 1,2 | AJ4: N | AO4: C | AP4: Y | AQ4: 1,2 | AR4: "Goal: Achieve zero emissions across global operations by 2040 (Scopes 1 & 2)" (Website, as of 14/08/2025: https://corporate.walmart.com/purpose/esgreport/environmental/climate-change) | AS4: 2040 | AV4: No | AW4: No | AX4: No | AY4: N | BG4: =IF(AND($N4="Y",$P4<=2025),1,0) -> 0 | BH4: =IF(AND($N4="Y",AND($P4>2025,$P4<=2030)),1,0) -> 0 | BI4: =IF(AND($N4="Y",$P4>2030),1,0) -> 1 | BJ4: =MAX(BG4:BI4) -> 1 | BK4: =IF(AND($R4="Y",$U4<=2025),1,0) -> 0 | BL4: =IF(AND($R4="Y",AND($U4>2025,$U4<=2030)),1,0) -> 1 | BM4: =IF(AND($R4="Y",$U4>2030),1,0) -> 0 | BN4: =MAX(BK4:BM4) -> 1 | BO4: =IF(AND($Y4="Y",$AA4<=2025),1,0) -> 0 | BP4: =IF(AND($Y4="Y",AND($AA4>2025,$AA4<=2030)),1,0) -> 0 | BQ4: =IF(AND($Y4="Y",$AA4>2030),1,0) -> 0 | BR4: =IF(AND($AP4="Y",$AS4<=2025),1,0) -> 0 | BS4: =IF(AND($AP4="Y",AND($AS4>2025,$AS4<=2030)),1,0) -> 0 | BT4: =IF(AND($AP4="Y",$AS4>2030),1,0) -> 1 | BU4: =IF(AND(AL4<=2025,CF4=0,AJ4="Y"),1,0) -> 0 | BV4: =IF(AND(AL4>=2026,AL4<=2030,AJ4="Y",CF4=0),1,0) -> 0 | BW4: =IF(AND(AL4>=2031,CF4=0,AJ4="Y"),1,0) -> 0 | BX4: =IF(AND($AJ4="Y",$AL4<=2024),1,0) -> 0 | BY4: =IF(AND($AJ4="Y",AND($AL4>2024,$AL4<=2030)),1,0) -> 0 | BZ4: =IF(AND($AJ4="Y",$AL4>2030),1,0) -> 0 | CA4: =MAX(BX4:BZ4) -> 0 | CB4: =IF(AND(CF4=0,AJ4="Y"),1,0) -> 0 | CC4: =MAX($BO4,$BR4) -> 0 | CD4: =MAX($BP4,$BS4) -> 0 | CE4: =MAX($BQ4,$BT4) -> 1 | CF4: =MAX(CC4:CE4) -> 1 | CG4: =MAX($CF4,$CA4) -> 1 | CH4: =MAX(CF4,CB4) -> 1 | CI4: =IF(AND($AY4="Y",$BA4<=2024),1,0) -> 0 | CJ4: =IF(AND($AY4="Y",AND($BA4>2024,$BA4<=2030)),1,0) -> 0 | CK4: =IF(AND($AY4="Y",$BA4>2030),1,0) -> 0 | CL4: =SUM(CC4,BU4,BK4,BG4) -> 0 | CM4: =SUM(CD4,BV4,BL4,BH4) -> 1 | CN4: =SUM(CE4,BW4,BM4,BI4) -> 2 | CO4: =CF4+CB4+BN4+BJ4 -> 3 | CP4: =MAX(CH4,BN4,BJ4) -> 1 | CQ4: =IF($AV4="Yes",1,0) -> 0 | CR4: =IF($AV4="No",1,0) -> 1 | CS4: =IF($AV4="Not Specified",1,0) -> 0 | CT4: =IF(OR(AND(U4>=2026,U4<=2030),AND(X4>=2026,X4<=2030)),1,"") -> 1 | CU4: =AA4&" "&AS4 -> 2040 | CV4: =MAX(AA4,AS4) -> 2040 | CW4: 0 | CX4: 0 | CY4: 0 | CZ4: 0 | DA4: 0 | DB4: 0 | DC4: 1 | DD4: 1 | DE4: 0 | DF4: 1 | DG4: 0 | DH4: 1 | DI4: 0 | DJ4: 0 | DK4: 1 | DL4: 1 | DM4: 1 | DN4: 0 | DO4: 1 | DP4: 0 | DQ4: 1 | DR4: 1 | DS4: 0 | DT4: Y | DU4: No | DV4: C | DW4: N | DX4: 0 | DY4: N | DZ4: =Q4 -> Y | EA4: =Z4 -> Commitment removed | EB4: =AP4 -> Y | EC4: =AJ4 -> N | ED4: =AV4 -> No | EF4: =MAX(AS4,AA4) -> 2040
A5: 2 | B5: 2 | C5: Amazon | D5: Internet Services and Retailing | E5: Retail | F5: U.S. | G5: North America | H5: $637,959 | I5: $59,248 | J5: 0.947 | K5: $624,894 | L5: 1556000 | M5: 17 | N5: N | Q5: Y | R5: N | S5: Commitment removed | AC5: Net zero | AD5: Net Zero | AE5: Not Specified | AF5: Not Specified | AG5: Partial | AJ5: N | AO5: C | AP5: Y | AR5: In 2019, we co-founded and committed to The Climate Pledge‚Äîour goal to reach net-zero carbon emissions by 2040, 10 years ahead of the Paris Agreement. (sustainability report 2024 p. 6) | AS5: 2040 | AV5: Yes | AW5: Yes (nature-based removals e.g. Forestation, soil carbon enhancement) | AX5: No | AY5: N | BG5: =IF(AND($N5="Y",$P5<=2025),1,0) -> 0 | BH5: =IF(AND($N5="Y",AND($P5>2025,$P5<=2030)),1,0) -> 0 | BI5: =IF(AND($N5="Y",$P5>2030),1,0) -> 0 | BJ5: =MAX(BG5:BI5) -> 0 | BK5: =IF(AND($R5="Y",$U5<=2025),1,0) -> 0 | BL5: =IF(AND($R5="Y",AND($U5>2025,$U5<=2030)),1,0) -> 0 | BM5: =IF(AND($R5="Y",$U5>2030),1,0) -> 0 | BN5: =MAX(BK5:BM5) -> 0 | BO5: =IF(AND($Y5="Y",$AA5<=2025),1,0) -> 0 | BP5: =IF(AND($Y5="Y",AND($AA5>2025,$AA5<=2030)),1,0) -> 0 | BQ5: =IF(AND($Y5="Y",$AA5>2030),1,0) -> 0 | BR5: =IF(AND($AP5="Y",$AS5<=2025),1,0) -> 0 | BS5: =IF(AND($AP5="Y",AND($AS5>2025,$AS5<=2030)),1,0) -> 0 | BT5: =IF(AND($AP5="Y",$AS5>2030),1,0) -> 1 | BU5: =IF(AND(AL5<=2025,CF5=0,AJ5="Y"),1,0) -> 0 | BV5: =IF(AND(AL5>=2026,AL5<=2030,AJ5="Y",CF5=0),1,0) -> 0 | BW5: =IF(AND(AL5>=2031,CF5=0,AJ5="Y"),1,0) -> 0 | BX5: =IF(AND($AJ5="Y",$AL5<=2024),1,0) -> 0 | BY5: =IF(AND($AJ5="Y",AND($AL5>2024,$AL5<=2030)),1,0) -> 0 | BZ5: =IF(AND($AJ5="Y",$AL5>2030),1,0) -> 0 | CA5: =MAX(BX5:BZ5) -> 0 | CB5: =IF(AND(CF5=0,AJ5="Y"),1,0) -> 0 | CC5: =MAX($BO5,$BR5) -> 0 | CD5: =MAX($BP5,$BS5) -> 0 | CE5: =MAX($BQ5,$BT5) -> 1 | CF5: =MAX(CC5:CE5) -> 1 | CG5: =MAX($CF5,$CA5) -> 1 | CH5: =MAX(CF5,CB5) -> 1 | CI5: =IF(AND($AY5="Y",$BA5<=2024),1,0) -> 0 | CJ5: =IF(AND($AY5="Y",AND($BA5>2024,$BA5<=2030)),1,0) -> 0 | CK5: =IF(AND($AY5="Y",$BA5>2030),1,0) -> 0 | CL5: =SUM(CC5,BU5,BK5,BG5) -> 0 | CM5: =SUM(CD5,BV5,BL5,BH5) -> 0 | CN5: =SUM(CE5,BW5,BM5,BI5) -> 1 | CO5: =CF5+CB5+BN5+BJ5 -> 1 | CP5: =MAX(CH5,BN5,BJ5) -> 1 | CQ5: =IF($AV5="Yes",1,0) -> 1 | CR5: =IF($AV5="No",1,0) -> 0 | CS5: =IF($AV5="Not Specified",1,0) -> 0 | CT5: =IF(OR(AND(U5>=2026,U5<=2030),AND(X5>=2026,X5<=2030)),1,"") | CU5: =AA5&" "&AS5 -> 2040 | CV5: =MAX(AA5,AS5) -> 2040 | CW5: 0 | CX5: 0 | CY5: 0 | CZ5: 0 | DA5: 0 | DB5: 0 | DC5: 1 | DD5: 1 | DE5: 0 | DF5: 0 | DG5: 0 | DH5: 0 | DI5: 0 | DJ5: 0 | DK5: 0 | DL5: 0 | DM5: 1 | DN5: 0 | DO5: 1 | DP5: 1 | DQ5: 0 | DR5: 1 | DS5: 0 | DT5: N | DU5: No | DV5: C | DW5: N | DX5: 0 | DY5: Y | DZ5: =Q5 -> Y | EA5: =Z5 | EB5: =AP5 -> Y | EC5: =AJ5 -> N | ED5: =AV5 -> Yes | EF5: =MAX(AS5,AA5) -> 2040
A6: 3 | B6: 3 | C6: State Grid | D6: Utilities | E6: Energy and utilities | F6: China | G6: Asia | H6: $548,414.4 | I6: $10,044.9 | J6: 0.091 | K6: $797,694 | L6: 1354310 | M6: 25 | N6: N | Q6: N | R6: N | AI6: G | AJ6: N | AL6: 2060 | AM6: http://www.sgcc.com.cn/u/cms/sgcc_main/other/202012/20201217092925545833884.pdf | AP6: N | AV6: Not Specified | AY6: N | BG6: =IF(AND($N6="Y",$P6<=2025),1,0) -> 0 | BH6: =IF(AND($N6="Y",AND($P6>2025,$P6<=2030)),1,0) -> 0 | BI6: =IF(AND($N6="Y",$P6>2030),1,0) -> 0 | BJ6: =MAX(BG6:BI6) -> 0 | BK6: =IF(AND($R6="Y",$U6<=2025),1,0) -> 0 | BL6: =IF(AND($R6="Y",AND($U6>2025,$U6<=2030)),1,0) -> 0 | BM6: =IF(AND($R6="Y",$U6>2030),1,0) -> 0 | BN6: =MAX(BK6:BM6) -> 0 | BO6: =IF(AND($Y6="Y",$AA6<=2025),1,0) -> 0 | BP6: =IF(AND($Y6="Y",AND($AA6>2025,$AA6<=2030)),1,0) -> 0 | BQ6: =IF(AND($Y6="Y",$AA6>2030),1,0) -> 0 | BR6: =IF(AND($AP6="Y",$AS6<=2025),1,0) -> 0 | BS6: =IF(AND($AP6="Y",AND($AS6>2025,$AS6<=2030)),1,0) -> 0 | BT6: =IF(AND($AP6="Y",$AS6>2030),1,0) -> 0 | BU6: =IF(AND(AL6<=2025,CF6=0,AJ6="Y"),1,0) -> 0 | BV6: =IF(AND(AL6>=2026,AL6<=2030,AJ6="Y",CF6=0),1,0) -> 0 | BW6: =IF(AND(AL6>=2031,CF6=0,AJ6="Y"),1,0) -> 0 | BX6: =IF(AND($AJ6="Y",$AL6<=2024),1,0) -> 0 | BY6: =IF(AND($AJ6="Y",AND($AL6>2024,$AL6<=2030)),1,0) -> 0 | BZ6: =IF(AND($AJ6="Y",$AL6>2030),1,0) -> 0 | CA6: =MAX(BX6:BZ6) -> 0 | CB6: =IF(AND(CF6=0,AJ6="Y"),1,0) -> 0 | CC6: =MAX($BO6,$BR6) -> 0 | CD6: =MAX($BP6,$BS6) -> 0 | CE6: =MAX($BQ6,$BT6) -> 0 | CF6: =MAX(CC6:CE6) -> 0 | CG6: =MAX($CF6,$CA6) -> 0 | CH6: =MAX(CF6,CB6) -> 0 | CI6: =IF(AND($AY6="Y",$BA6<=2024),1,0) -> 0 | CJ6: =IF(AND($AY6="Y",AND($BA6>2024,$BA6<=2030)),1,0) -> 0 | CK6: =IF(AND($AY6="Y",$BA6>2030),1,0) -> 0 | CL6: =SUM(CC6,BU6,BK6,BG6) -> 0 | CM6: =SUM(CD6,BV6,BL6,BH6) -> 0 | CN6: =SUM(CE6,BW6,BM6,BI6) -> 0 | CO6: =CF6+CB6+BN6+BJ6 -> 0 | CP6: =MAX(CH6,BN6,BJ6) -> 0 | CQ6: =IF($AV6="Yes",1,0) -> 0 | CR6: =IF($AV6="No",1,0) -> 0 | CS6: =IF($AV6="Not Specified",1,0) -> 1 | CT6: =IF(OR(AND(U6>=2026,U6<=2030),AND(X6>=2026,X6<=2030)),1,"") | CU6: =AA6&" "&AS6 | CV6: =MAX(AA6,AS6) -> 0 | CW6: 0 | CX6: 0 | CY6: 0 | CZ6: 0 | DA6: 0 | DB6: 0 | DC6: 0 | DD6: 0 | DE6: 0 | DF6: 0 | DG6: 0 | DH6: 0 | DI6: 0 | DJ6: 0 | DK6: 0 | DL6: 0 | DM6: 0 | DN6: 0 | DO6: 0 | DP6: 0 | DQ6: 0 | DR6: 0 | DS6: 0 | DT6: N | DU6: 0 | DV6: N | DW6: N | DX6: 0 | DY6: 0 | DZ6: =Q6 -> N | EA6: =Z6 | EB6: =AP6 -> N | EC6: =AJ6 -> N | ED6: =AV6 -> Not Specified | EF6: =MAX(AS6,AA6) -> 0
A7: 4 | B7: 4 | C7: Saudi Aramco | D7: Mining, Crude-Oil Production | E7: Metals and mining | F7: Saudi Arabia | G7: Other | H7: $480,193.5 | I7: $104,982.3 | J7: -0.13 | K7: $645,097.2 | L7: 75118 | M7: 7 | N7: N | Q7: N | R7: N | AC7: Net zero | AD7: Net Zero | AE7: Yes | AF7: Yes | AG7: No | AH7: 1,2 | AJ7: N | AO7: C | AP7: Y | AQ7: 1,2 | AR7: 'We have an ambition to reach net-zero Scope 1 and Scope 2 GHG emissions by 2050 across all our wholly-owned operated assets. (see p22 of the 2024 Aramco Sustainability Report). | AS7: 2050 | AV7: Yes | AW7: Yes (nature-based and CCS-based removals) | AX7: No | AY7: N | BG7: =IF(AND($N7="Y",$P7<=2025),1,0) -> 0 | BH7: =IF(AND($N7="Y",AND($P7>2025,$P7<=2030)),1,0) -> 0 | BI7: =IF(AND($N7="Y",$P7>2030),1,0) -> 0 | BJ7: =MAX(BG7:BI7) -> 0 | BK7: =IF(AND($R7="Y",$U7<=2025),1,0) -> 0 | BL7: =IF(AND($R7="Y",AND($U7>2025,$U7<=2030)),1,0) -> 0 | BM7: =IF(AND($R7="Y",$U7>2030),1,0) -> 0 | BN7: =MAX(BK7:BM7) -> 0 | BO7: =IF(AND($Y7="Y",$AA7<=2025),1,0) -> 0 | BP7: =IF(AND($Y7="Y",AND($AA7>2025,$AA7<=2030)),1,0) -> 0 | BQ7: =IF(AND($Y7="Y",$AA7>2030),1,0) -> 0 | BR7: =IF(AND($AP7="Y",$AS7<=2025),1,0) -> 0 | BS7: =IF(AND($AP7="Y",AND($AS7>2025,$AS7<=2030)),1,0) -> 0 | BT7: =IF(AND($AP7="Y",$AS7>2030),1,0) -> 1 | BU7: =IF(AND(AL7<=2025,CF7=0,AJ7="Y"),1,0) -> 0 | BV7: =IF(AND(AL7>=2026,AL7<=2030,AJ7="Y",CF7=0),1,0) -> 0 | BW7: =IF(AND(AL7>=2031,CF7=0,AJ7="Y"),1,0) -> 0 | BX7: =IF(AND($AJ7="Y",$AL7<=2024),1,0) -> 0 | BY7: =IF(AND($AJ7="Y",AND($AL7>2024,$AL7<=2030)),1,0) -> 0 | BZ7: =IF(AND($AJ7="Y",$AL7>2030),1,0) -> 0 | CA7: =MAX(BX7:BZ7) -> 0 | CB7: =IF(AND(CF7=0,AJ7="Y"),1,0) -> 0 | CC7: =MAX($BO7,$BR7) -> 0 | CD7: =MAX($BP7,$BS7) -> 0 | CE7: =MAX($BQ7,$BT7) -> 1 | CF7: =MAX(CC7:CE7) -> 1 | CG7: =MAX($CF7,$CA7) -> 1 | CH7: =MAX(CF7,CB7) -> 1 | CI7: =IF(AND($AY7="Y",$BA7<=2024),1,0) -> 0 | CJ7: =IF(AND($AY7="Y",AND($BA7>2024,$BA7<=2030)),1,0) -> 0 | CK7: =IF(AND($AY7="Y",$BA7>2030),1,0) -> 0 | CL7: =SUM(CC7,BU7,BK7,BG7) -> 0 | CM7: =SUM(CD7,BV7,BL7,BH7) -> 0 | CN7: =SUM(CE7,BW7,BM7,BI7) -> 1 | CO7: =CF7+CB7+BN7+BJ7 -> 1 | CP7: =MAX(CH7,BN7,BJ7) -> 1 | CQ7: =IF($AV7="Yes",1,0) -> 1 | CR7: =IF($AV7="No",1,0) -> 0 | CS7: =IF($AV7="Not Specified",1,0) -> 0 | CT7: =IF(OR(AND(U7>=2026,U7<=2030),AND(X7>=2026,X7<=2030)),1,"") | CU7: =AA7&" "&AS7 -> 2050 | CV7: =MAX(AA7,AS7) -> 2050 | CW7: 0 | CX7: 0 | CY7: 0 | CZ7: 0 | DA7: 0 | DB7: 0 | DC7: 1 | DD7: 1 | DE7: 0 | DF7: 0 | DG7: 0 | DH7: 0 | DI7: 0 | DJ7: 0 | DK7: 0 | DL7: 0 | DM7: 1 | DN7: 0 | DO7: 1 | DP7: 1 | DQ7: 0 | DR7: 1 | DS7: 0 | DT7: N | DU7: 0 | DV7: C | DW7: N | DX7: 0 | DY7: Y | DZ7: =Q7 -> N | EA7: =Z7 | EB7: =AP7 -> Y | EC7: =AJ7 -> N | ED7: =AV7 -> Yes | EF7: =MAX(AS7,AA7) -> 2050
A8: 5 | B8: 6 | C8: China National Petroleum | D8: Petroleum Refining | E8: Oil and gas | F8: China | G8: Asia | H8: $412,645.3 | I8: $22,424 | J8: 0.053 | K8: $607,615.1 | L8: 985155 | M8: 25 | N8: N | Q8: N | R8: N | AC8: Net zero | AD8: Net Zero | AE8: Yes | AF8: Yes | AG8: Not Specified | AH8: 1,2 | AI8: G | AJ8: N | AL8: 2060 | AO8: C | AP8: Y | AQ8: 1,2 | AR8: The 2024 report frequently mentions ‚Äúcarbon neutrality,‚Äù ‚Äúzero-carbon,‚Äù and the global ‚Äúnet-zero‚Äù context (including NZE-2050), it does not specify a corporate-wide net-zero year target for PetroChina itself ‚Äî it frames the ambition as ongoing pursuit of the national carbon-peak and carbon-neutrality goals. | AS8: 2050 | AV8: Not Specified | AW8: No | AX8: No | AY8: N | BG8: =IF(AND($N8="Y",$P8<=2025),1,0) -> 0 | BH8: =IF(AND($N8="Y",AND($P8>2025,$P8<=2030)),1,0) -> 0 | BI8: =IF(AND($N8="Y",$P8>2030),1,0) -> 0 | BJ8: =MAX(BG8:BI8) -> 0 | BK8: =IF(AND($R8="Y",$U8<=2025),1,0) -> 0 | BL8: =IF(AND($R8="Y",AND($U8>2025,$U8<=2030)),1,0) -> 0 | BM8: =IF(AND($R8="Y",$U8>2030),1,0) -> 0 | BN8: =MAX(BK8:BM8) -> 0 | BO8: =IF(AND($Y8="Y",$AA8<=2025),1,0) -> 0 | BP8: =IF(AND($Y8="Y",AND($AA8>2025,$AA8<=2030)),1,0) -> 0 | BQ8: =IF(AND($Y8="Y",$AA8>2030),1,0) -> 0 | BR8: =IF(AND($AP8="Y",$AS8<=2025),1,0) -> 0 | BS8: =IF(AND($AP8="Y",AND($AS8>2025,$AS8<=2030)),1,0) -> 0 | BT8: =IF(AND($AP8="Y",$AS8>2030),1,0) -> 1 | BU8: =IF(AND(AL8<=2025,CF8=0,AJ8="Y"),1,0) -> 0 | BV8: =IF(AND(AL8>=2026,AL8<=2030,AJ8="Y",CF8=0),1,0) -> 0 | BW8: =IF(AND(AL8>=2031,CF8=0,AJ8="Y"),1,0) -> 0 | BX8: =IF(AND($AJ8="Y",$AL8<=2024),1,0) -> 0 | BY8: =IF(AND($AJ8="Y",AND($AL8>2024,$AL8<=2030)),1,0) -> 0 | BZ8: =IF(AND($AJ8="Y",$AL8>2030),1,0) -> 0 | CA8: =MAX(BX8:BZ8) -> 0 | CB8: =IF(AND(CF8=0,AJ8="Y"),1,0) -> 0 | CC8: =MAX($BO8,$BR8) -> 0 | CD8: =MAX($BP8,$BS8) -> 0 | CE8: =MAX($BQ8,$BT8) -> 1 | CF8: =MAX(CC8:CE8) -> 1 | CG8: =MAX($CF8,$CA8) -> 1 | CH8: =MAX(CF8,CB8) -> 1 | CI8: =IF(AND($AY8="Y",$BA8<=2024),1,0) -> 0 | CJ8: =IF(AND($AY8="Y",AND($BA8>2024,$BA8<=2030)),1,0) -> 0 | CK8: =IF(AND($AY8="Y",$BA8>2030),1,0) -> 0 | CL8: =SUM(CC8,BU8,BK8,BG8) -> 0 | CM8: =SUM(CD8,BV8,BL8,BH8) -> 0 | CN8: =SUM(CE8,BW8,BM8,BI8) -> 1 | CO8: =CF8+CB8+BN8+BJ8 -> 1 | CP8: =MAX(CH8,BN8,BJ8) -> 1 | CQ8: =IF($AV8="Yes",1,0) -> 0 | CR8: =IF($AV8="No",1,0) -> 0 | CS8: =IF($AV8="Not Specified",1,0) -> 1 | CT8: =IF(OR(AND(U8>=2026,U8<=2030),AND(X8>=2026,X8<=2030)),1,"") | CU8: =AA8&" "&AS8 -> 2050 | CV8: =MAX(AA8,AS8) -> 2050 | CW8: 0 | CX8: 0 | CY8: 0 | CZ8: 0 | DA8: 0 | DB8: 0 | DC8: 0 | DD8: 0 | DE8: 0 | DF8: 0 | DG8: 0 | DH8: 0 | DI8: 0 | DJ8: 0 | DK8: 0 | DL8: 0 | DM8: 0 | DN8: 0 | DO8: 0 | DP8: 0 | DQ8: 0 | DR8: 0 | DS8: 0 | DT8: N | DU8: 0 | DV8: I | DW8: G | DX8: Y, g | DY8: 0 | DZ8: =Q8 -> N | EA8: =Z8 | EB8: =AP8 -> Y | EC8: =AJ8 -> N | ED8: =AV8 -> Not Specified | EF8: =MAX(AS8,AA8) -> 2050
A9: 6 | B9: 5 | C9: Sinopec Group | D9: Petroleum Refining | E9: Oil and gas | F9: China | G9: Asia | H9: $407,490.1 | I9: $8,036.4 | J9: -0.145 | K9: $375,395.1 | L9: 495096 | M9: 27 | N9: N | Q9: N | R9: N | AC9: Carbon neutral(ity) | AD9: Carbon Neutral | AE9: Yes | AF9: Yes | AG9: Not Specified | AH9: 1,2 | AI9: C | AJ9: Y | AK9: Strive to achieve carbon neutrality around 2050. | AL9: 2050 | AP9: N | AV9: Yes | AW9: Yes (nature-based removals e.g. Forestation, soil carbon enhancement) | AX9: No | AY9: N | BG9: =IF(AND($N9="Y",$P9<=2025),1,0) -> 0 | BH9: =IF(AND($N9="Y",AND($P9>2025,$P9<=2030)),1,0) -> 0 | BI9: =IF(AND($N9="Y",$P9>2030),1,0) -> 0 | BJ9: =MAX(BG9:BI9) -> 0 | BK9: =IF(AND($R9="Y",$U9<=2025),1,0) -> 0 | BL9: =IF(AND($R9="Y",AND($U9>2025,$U9<=2030)),1,0) -> 0 | BM9: =IF(AND($R9="Y",$U9>2030),1,0) -> 0 | BN9: =MAX(BK9:BM9) -> 0 | BO9: =IF(AND($Y9="Y",$AA9<=2025),1,0) -> 0 | BP9: =IF(AND($Y9="Y",AND($AA9>2025,$AA9<=2030)),1,0) -> 0 | BQ9: =IF(AND($Y9="Y",$AA9>2030),1,0) -> 0 | BR9: =IF(AND($AP9="Y",$AS9<=2025),1,0) -> 0 | BS9: =IF(AND($AP9="Y",AND($AS9>2025,$AS9<=2030)),1,0) -> 0 | BT9: =IF(AND($AP9="Y",$AS9>2030),1,0) -> 0 | BU9: =IF(AND(AL9<=2025,CF9=0,AJ9="Y"),1,0) -> 0 | BV9: =IF(AND(AL9>=2026,AL9<=2030,AJ9="Y",CF9=0),1,0) -> 0 | BW9: =IF(AND(AL9>=2031,CF9=0,AJ9="Y"),1,0) -> 1 | BX9: =IF(AND($AJ9="Y",$AL9<=2024),1,0) -> 0 | BY9: =IF(AND($AJ9="Y",AND($AL9>2024,$AL9<=2030)),1,0) -> 0 | BZ9: =IF(AND($AJ9="Y",$AL9>2030),1,0) -> 1 | CA9: =MAX(BX9:BZ9) -> 1 | CB9: =IF(AND(CF9=0,AJ9="Y"),1,0) -> 1 | CC9: =MAX($BO9,$BR9) -> 0 | CD9: =MAX($BP9,$BS9) -> 0 | CE9: =MAX($BQ9,$BT9) -> 0 | CF9: =MAX(CC9:CE9) -> 0 | CG9: =MAX($CF9,$CA9) -> 1 | CH9: =MAX(CF9,CB9) -> 1 | CI9: =IF(AND($AY9="Y",$BA9<=2024),1,0) -> 0 | CJ9: =IF(AND($AY9="Y",AND($BA9>2024,$BA9<=2030)),1,0) -> 0 | CK9: =IF(AND($AY9="Y",$BA9>2030),1,0) -> 0 | CL9: =SUM(CC9,BU9,BK9,BG9) -> 0 | CM9: =SUM(CD9,BV9,BL9,BH9) -> 0 | CN9: =SUM(CE9,BW9,BM9,BI9) -> 1 | CO9: =CF9+CB9+BN9+BJ9 -> 1 | CP9: =MAX(CH9,BN9,BJ9) -> 1 | CQ9: =IF($AV9="Yes",1,0) -> 1 | CR9: =IF($AV9="No",1,0) -> 0 | CS9: =IF($AV9="Not Specified",1,0) -> 0 | CT9: =IF(OR(AND(U9>=2026,U9<=2030),AND(X9>=2026,X9<=2030)),1,"") | CU9: =AA9&" "&AS9 | CV9: =MAX(AA9,AS9) -> 0 | CW9: 0 | CX9: 0 | CY9: 0 | CZ9: 0 | DA9: 0 | DB9: 0 | DC9: 0 | DD9: 0 | DE9: 0 | DF9: 0 | DG9: 0 | DH9: 0 | DI9: 0 | DJ9: 0 | DK9: 0 | DL9: 0 | DM9: 0 | DN9: 0 | DO9: 0 | DP9: 0 | DQ9: 0 | DR9: 0 | DS9: 0 | DT9: N | DU9: 0 | DV9: N | DW9: G | DX9: U | DY9: 0 | DZ9: =Q9 -> N | EA9: =Z9 | EB9: =AP9 -> N | EC9: =AJ9 -> Y | ED9: =AV9 -> Yes | EF9: =MAX(AS9,AA9) -> 0
A10: 7 | B10: 8 | C10: UnitedHealth Group | D10: Health Care: Insurance and Managed Care | E10: Health care and pharmaceuticals | F10: U.S. | G10: North America | H10: $400,278 | I10: $14,405 | J10: -0.356 | K10: $298,278 | L10: 400000 | M10: 29 | N10: N | Q10: Y | R10: Y | S10: Targets set | T10: 1.5°C | U10: 2030 | Y10: N | Z10: Committed | AC10: Net zero | AD10: Net Zero | AE10: Yes | AF10: Yes | AG10: No | AH10: 1,2 | AJ10: N | AO10: C | AP10: Y | AQ10: 1,2 | AR10: Achieving operational net-zero by 2035 We will continue to pursue our ambition to achieve net-zero emissions in scopes 1 and 2 by 2035 across our global operations | AS10: 2035 | AV10: Not Specified | AW10: Not Specified | AX10: No | AY10: N | BG10: =IF(AND($N10="Y",$P10<=2025),1,0) -> 0 | BH10: =IF(AND($N10="Y",AND($P10>2025,$P10<=2030)),1,0) -> 0 | BI10: =IF(AND($N10="Y",$P10>2030),1,0) -> 0 | BJ10: =MAX(BG10:BI10) -> 0 | BK10: =IF(AND($R10="Y",$U10<=2025),1,0) -> 0 | BL10: =IF(AND($R10="Y",AND($U10>2025,$U10<=2030)),1,0) -> 1 | BM10: =IF(AND($R10="Y",$U10>2030),1,0) -> 0 | BN10: =MAX(BK10:BM10) -> 1 | BO10: =IF(AND($Y10="Y",$AA10<=2025),1,0) -> 0 | BP10: =IF(AND($Y10="Y",AND($AA10>2025,$AA10<=2030)),1,0) -> 0 | BQ10: =IF(AND($Y10="Y",$AA10>2030),1,0) -> 0 | BR10: =IF(AND($AP10="Y",$AS10<=2025),1,0) -> 0 | BS10: =IF(AND($AP10="Y",AND($AS10>2025,$AS10<=2030)),1,0) -> 0 | BT10: =IF(AND($AP10="Y",$AS10>2030),1,0) -> 1 | BU10: =IF(AND(AL10<=2025,CF10=0,AJ10="Y"),1,0) -> 0 | BV10: =IF(AND(AL10>=2026,AL10<=2030,AJ10="Y",CF10=0),1,0) -> 0 | BW10: =IF(AND(AL10>=2031,CF10=0,AJ10="Y"),1,0) -> 0 | BX10: =IF(AND($AJ10="Y",$AL10<=2024),1,0) -> 0 | BY10: =IF(AND($AJ10="Y",AND($AL10>2024,$AL10<=2030)),1,0) -> 0 | BZ10: =IF(AND($AJ10="Y",$AL10>2030),1,0) -> 0 | CA10: =MAX(BX10:BZ10) -> 0 | CB10: =IF(AND(CF10=0,AJ10="Y"),1,0) -> 0 | CC10: =MAX($BO10,$BR10) -> 0 | CD10: =MAX($BP10,$BS10) -> 0 | CE10: =MAX($BQ10,$BT10) -> 1 | CF10: =MAX(CC10:CE10) -> 1 | CG10: =MAX($CF10,$CA10) -> 1 | CH10: =MAX(CF10,CB10) -> 1 | CI10: =IF(AND($AY10="Y",$BA10<=2024),1,0) -> 0 | CJ10: =IF(AND($AY10="Y",AND($BA10>2024,$BA10<=2030)),1,0) -> 0 | CK10: =IF(AND($AY10="Y",$BA10>2030),1,0) -> 0 | CL10: =SUM(CC10,BU10,BK10,BG10) -> 0 | CM10: =SUM(CD10,BV10,BL10,BH10) -> 1 | CN10: =SUM(CE10,BW10,BM10,BI10) -> 1 | CO10: =CF10+CB10+BN10+BJ10 -> 2 | CP10: =MAX(CH10,BN10,BJ10) -> 1 | CQ10: =IF($AV10="Yes",1,0) -> 0 | CR10: =IF($AV10="No",1,0) -> 0 | CS10: =IF($AV10="Not Specified",1,0) -> 1 | CT10: =IF(OR(AND(U10>=2026,U10<=2030),AND(X10>=2026,X10<=2030)),1,"") -> 1 | CU10: =AA10&" "&AS10 -> 2035 | CV10: =MAX(AA10,AS10) -> 2035 | CW10: 0 | CX10: 0 | CY10: 0 | CZ10: 0 | DA10: 0 | DB10: 0 | DC10: 1 | DD10: 1 | DE10: 0 | DF10: 1 | DG10: 0 | DH10: 1 | DI10: 0 | DJ10: 0 | DK10: 0 | DL10: 0 | DM10: 1 | DN10: 0 | DO10: 1 | DP10: 1 | DQ10: 0 | DR10: 1 | DS10: 0 | DT10: N | DU10: Yes | DV10: C | DW10: N | DX10: 0 | DY10: Y | DZ10: =Q10 -> Y | EA10: =Z10 -> Committed | EB10: =AP10 -> Y | EC10: =AJ10 -> N | ED10: =AV10 -> Not Specified | EF10: =MAX(AS10,AA10) -> 2035
A11: 8 | B11: 7 | C11: Apple | D11: Computers | E11: Technology | F11: U.S. | G11: North America | H11: $391,035 | I11: $93,736 | J11: -0.034 | K11: $364,980 | L11: 164000 | M11: 23 | N11: Y | O11: 2016 | P11: 2021 | Q11: Y | R11: Y | S11: Targets set | T11: 1.5°C | U11: 2030 | AC11: Carbon neutral(ity) | AD11: Carbon Neutral | AE11: Yes | AF11: Yes | AG11: Yes | AH11: 1,2,3 | AI11: C,V | AJ11: Y | AK11: We‚Äôre committed to our ambitious, sciencebased Apple 2030 goal to reduce our collective scope 1, 2, and 3 emissions ‚ upstream and downstream ‚ by 75 percent before balancing the remaining emissions with high-quality carbon removals. To achieve this goal, we're reducing emissions across our value chain and directing our efforts toward decarbonizing the largest sources of emissions. (pg 10) | AL11: 2030 | AP11: N | AV11: Yes | AW11: Yes (nature-based removals e.g. Forestation, soil carbon enhancement) | AX11: Yes | AY11: N | BG11: =IF(AND($N11="Y",$P11<=2025),1,0) -> 1 | BH11: =IF(AND($N11="Y",AND($P11>2025,$P11<=2030)),1,0) -> 0 | BI11: =IF(AND($N11="Y",$P11>2030),1,0) -> 0 | BJ11: =MAX(BG11:BI11) -> 1 | BK11: =IF(AND($R11="Y",$U11<=2025),1,0) -> 0 | BL11: =IF(AND($R11="Y",AND($U11>2025,$U11<=2030)),1,0) -> 1 | BM11: =IF(AND($R11="Y",$U11>2030),1,0) -> 0 | BN11: =MAX(BK11:BM11) -> 1 | BO11: =IF(AND($Y11="Y",$AA11<=2025),1,0) -> 0 | BP11: =IF(AND($Y11="Y",AND($AA11>2025,$AA11<=2030)),1,0) -> 0 | BQ11: =IF(AND($Y11="Y",$AA11>2030),1,0) -> 0 | BR11: =IF(AND($AP11="Y",$AS11<=2025),1,0) -> 0 | BS11: =IF(AND($AP11="Y",AND($AS11>2025,$AS11<=2030)),1,0) -> 0 | BT11: =IF(AND($AP11="Y",$AS11>2030),1,0) -> 0 | BU11: =IF(AND(AL11<=2025,CF11=0,AJ11="Y"),1,0) -> 0 | BV11: =IF(AND(AL11>=2026,AL11<=2030,AJ11="Y",CF11=0),1,0) -> 1 | BW11: =IF(AND(AL11>=2031,CF11=0,AJ11="Y"),1,0) -> 0 | BX11: =IF(AND($AJ11="Y",$AL11<=2024),1,0) -> 0 | BY11: =IF(AND($AJ11="Y",AND($AL11>2024,$AL11<=2030)),1,0) -> 1 | BZ11: =IF(AND($AJ11="Y",$AL11>2030),1,0) -> 0 | CA11: =MAX(BX11:BZ11) -> 1 | CB11: =IF(AND(CF11=0,AJ11="Y"),1,0) -> 1 | CC11: =MAX($BO11,$BR11) -> 0 | CD11: =MAX($BP11,$BS11) -> 0 | CE11: =MAX($BQ11,$BT11) -> 0 | CF11: =MAX(CC11:CE11) -> 0 | CG11: =MAX($CF11,$CA11) -> 1 | CH11: =MAX(CF11,CB11) -> 1 | CI11: =IF(AND($AY11="Y",$BA11<=2024),1,0) -> 0 | CJ11: =IF(AND($AY11="Y",AND($BA11>2024,$BA11<=2030)),1,0) -> 0 | CK11: =IF(AND($AY11="Y",$BA11>2030),1,0) -> 0 | CL11: =SUM(CC11,BU11,BK11,BG11) -> 1 | CM11: =SUM(CD11,BV11,BL11,BH11) -> 2 | CN11: =SUM(CE11,BW11,BM11,BI11) -> 0 | CO11: =CF11+CB11+BN11+BJ11 -> 3 | CP11: =MAX(CH11,BN11,BJ11) -> 1 | CQ11: =IF($AV11="Yes",1,0) -> 1 | CR11: =IF($AV11="No",1,0) -> 0 | CS11: =IF($AV11="Not Specified",1,0) -> 0 | CT11: =IF(OR(AND(U11>=2026,U11<=2030),AND(X11>=2026,X11<=2030)),1,"") -> 1 | CU11: =AA11&" "&AS11 | CV11: =MAX(AA11,AS11) -> 0 | CW11: 1 | CX11: 0 | CY11: 0 | CZ11: 1 | DA11: 0 | DB11: 0 | DC11: 0 | DD11: 0 | DE11: 0 | DF11: 1 | DG11: 0 | DH11: 1 | DI11: 1 | DJ11: 0 | DK11: 0 | DL11: 1 | DM11: 1 | DN11: 1 | DO11: 1 | DP11: 1 | DQ11: 0 | DR11: 1 | DS11: 1 | DT11: Y | DU11: No | DV11: N | DW11: C, V | DX11: R | DY11: 0 | DZ11: =Q11 -> Y | EA11: =Z11 | EB11: =AP11 -> N | EC11: =AJ11 -> Y | ED11: =AV11 -> Yes | EF11: =MAX(AS11,AA11) -> 0
A12: 9 | B12: 10 | C12: CVS Health | D12: Health Care: Pharmacy and Other Services | E12: Health care and pharmaceuticals | F12: U.S. | G12: North America | H12: $372,809 | I12: $4,614 | J12: -0.447 | K12: $253,215 | L12: 259500 | M12: 30 | N12: N | Q12: Y | R12: Y | S12: Targets set | T12: 1.5°C | U12: 2030 | V12: Targets set | W12: 1.5°C | X12: 2050 | Y12: Y | Z12: Targets set | AA12: 2050 | AC12: Net zero | AD12: Net Zero | AE12: Yes | AF12: Yes | AG12: Yes | AH12: 1,2,3 | AJ12: N | AO12: C,V | AP12: Y | AQ12: 1,2,3 | AR12: *CVS health is one of the first companies in the world to have our net zero targets validated by the Science-Based Targets initiative's (SBTi) net zero methodology. This set us on the path to achieving net zero emissions from our direct operations by 2048 and across their value chain by 2050. They also committed to achieving carbon neutrality by 2030. *Reduce absolute scope: 1, 2 and 3 (value chain) emissions by 90% by 2050. | AS12: 2050 | AV12: Yes | AW12: Not Specified | AX12: No | AY12: N | BG12: =IF(AND($N12="Y",$P12<=2025),1,0) -> 0 | BH12: =IF(AND($N12="Y",AND($P12>2025,$P12<=2030)),1,0) -> 0 | BI12: =IF(AND($N12="Y",$P12>2030),1,0) -> 0 | BJ12: =MAX(BG12:BI12) -> 0 | BK12: =IF(AND($R12="Y",$U12<=2025),1,0) -> 0 | BL12: =IF(AND($R12="Y",AND($U12>2025,$U12<=2030)),1,0) -> 1 | BM12: =IF(AND($R12="Y",$U12>2030),1,0) -> 0 | BN12: =MAX(BK12:BM12) -> 1 | BO12: =IF(AND($Y12="Y",$AA12<=2025),1,0) -> 0 | BP12: =IF(AND($Y12="Y",AND($AA12>2025,$AA12<=2030)),1,0) -> 0 | BQ12: =IF(AND($Y12="Y",$AA12>2030),1,0) -> 1 | BR12: =IF(AND($AP12="Y",$AS12<=2025),1,0) -> 0 | BS12: =IF(AND($AP12="Y",AND($AS12>2025,$AS12<=2030)),1,0) -> 0 | BT12: =IF(AND($AP12="Y",$AS12>2030),1,0) -> 1 | BU12: =IF(AND(AL12<=2025,CF12=0,AJ12="Y"),1,0) -> 0 | BV12: =IF(AND(AL12>=2026,AL12<=2030,AJ12="Y",CF12=0),1,0) -> 0 | BW12: =IF(AND(AL12>=2031,CF12=0,AJ12="Y"),1,0) -> 0 | BX12: =IF(AND($AJ12="Y",$AL12<=2024),1,0) -> 0 | BY12: =IF(AND($AJ12="Y",AND($AL12>2024,$AL12<=2030)),1,0) -> 0 | BZ12: =IF(AND($AJ12="Y",$AL12>2030),1,0) -> 0 | CA12: =MAX(BX12:BZ12) -> 0 | CB12: =IF(AND(CF12=0,AJ12="Y"),1,0) -> 0 | CC12: =MAX($BO12,$BR12) -> 0 | CD12: =MAX($BP12,$BS12) -> 0 | CE12: =MAX($BQ12,$BT12) -> 1 | CF12: =MAX(CC12:CE12) -> 1 | CG12: =MAX($CF12,$CA12) -> 1 | CH12: =MAX(CF12,CB12) -> 1 | CI12: =IF(AND($AY12="Y",$BA12<=2024),1,0) -> 0 | CJ12: =IF(AND($AY12="Y",AND($BA12>2024,$BA12<=2030)),1,0) -> 0 | CK12: =IF(AND($AY12="Y",$BA12>2030),1,0) -> 0 | CL12: =SUM(CC12,BU12,BK12,BG12) -> 0 | CM12: =SUM(CD12,BV12,BL12,BH12) -> 1 | CN12: =SUM(CE12,BW12,BM12,BI12) -> 1 | CO12: =CF12+CB12+BN12+BJ12 -> 2 | CP12: =MAX(CH12,BN12,BJ12) -> 1 | CQ12: =IF($AV12="Yes",1,0) -> 1 | CR12: =IF($AV12="No",1,0) -> 0 | CS12: =IF($AV12="Not Specified",1,0) -> 0 | CT12: =IF(OR(AND(U12>=2026,U12<=2030),AND(X12>=2026,X12<=2030)),1,"") -> 1 | CU12: =AA12&" "&AS12 -> 2050 2050 | CV12: =MAX(AA12,AS12) -> 2050 | CW12: 0 | CX12: 1 | CY12: 0 | CZ12: 1 | DA12: 0 | DB12: 0 | DC12: 1 | DD12: 1 | DE12: 0 | DF12: 1 | DG12: 0 | DH12: 1 | DI12: 0 | DJ12: 0 | DK12: 0 | DL12: 0 | DM12: 1 | DN12: 1 | DO12: 1 | DP12: 0 | DQ12: 0 | DR12: 1 | DS12: 0 | DT12: Y | DU12: Yes | DV12: C, V | DW12: C | DX12: U | DY12: U | DZ12: =Q12 -> Y | EA12: =Z12 -> Targets set | EB12: =AP12 -> Y | EC12: =AJ12 -> N | ED12: =AV12 -> Yes | EF12: =MAX(AS12,AA12) -> 2050
A13: 10 | B13: 9 | C13: Berkshire Hathaway | D13: Insurance: Property and Casualty | E13: Financial services | F13: U.S. | G13: North America | H13: $371,433 | I13: $88,995 | J13: -0.075 | K13: $1,153,881 | L13: 392400 | M13: 29 | N13: N | Q13: N | R13: N | AC13: No target | AD13: No Target | AE13: Not Specified | AF13: Not Specified | AG13: Not Specified | AJ13: N | AP13: N | AV13: Not Specified | AW13: Not Specified | AX13: No | AY13: N | BG13: =IF(AND($N13="Y",$P13<=2025),1,0) -> 0 | BH13: =IF(AND($N13="Y",AND($P13>2025,$P13<=2030)),1,0) -> 0 | BI13: =IF(AND($N13="Y",$P13>2030),1,0) -> 0 | BJ13: =MAX(BG13:BI13) -> 0 | BK13: =IF(AND($R13="Y",$U13<=2025),1,0) -> 0 | BL13: =IF(AND($R13="Y",AND($U13>2025,$U13<=2030)),1,0) -> 0 | BM13: =IF(AND($R13="Y",$U13>2030),1,0) -> 0 | BN13: =MAX(BK13:BM13) -> 0 | BO13: =IF(AND($Y13="Y",$AA13<=2025),1,0) -> 0 | BP13: =IF(AND($Y13="Y",AND($AA13>2025,$AA13<=2030)),1,0) -> 0 | BQ13: =IF(AND($Y13="Y",$AA13>2030),1,0) -> 0 | BR13: =IF(AND($AP13="Y",$AS13<=2025),1,0) -> 0 | BS13: =IF(AND($AP13="Y",AND($AS13>2025,$AS13<=2030)),1,0) -> 0 | BT13: =IF(AND($AP13="Y",$AS13>2030),1,0) -> 0 | BU13: =IF(AND(AL13<=2025,CF13=0,AJ13="Y"),1,0) -> 0 | BV13: =IF(AND(AL13>=2026,AL13<=2030,AJ13="Y",CF13=0),1,0) -> 0 | BW13: =IF(AND(AL13>=2031,CF13=0,AJ13="Y"),1,0) -> 0 | BX13: =IF(AND($AJ13="Y",$AL13<=2024),1,0) -> 0 | BY13: =IF(AND($AJ13="Y",AND($AL13>2024,$AL13<=2030)),1,0) -> 0 | BZ13: =IF(AND($AJ13="Y",$AL13>2030),1,0) -> 0 | CA13: =MAX(BX13:BZ13) -> 0 | CB13: =IF(AND(CF13=0,AJ13="Y"),1,0) -> 0 | CC13: =MAX($BO13,$BR13) -> 0 | CD13: =MAX($BP13,$BS13) -> 0 | CE13: =MAX($BQ13,$BT13) -> 0 | CF13: =MAX(CC13:CE13) -> 0 | CG13: =MAX($CF13,$CA13) -> 0 | CH13: =MAX(CF13,CB13) -> 0 | CI13: =IF(AND($AY13="Y",$BA13<=2024),1,0) -> 0 | CJ13: =IF(AND($AY13="Y",AND($BA13>2024,$BA13<=2030)),1,0) -> 0 | CK13: =IF(AND($AY13="Y",$BA13>2030),1,0) -> 0 | CL13: =SUM(CC13,BU13,BK13,BG13) -> 0 | CM13: =SUM(CD13,BV13,BL13,BH13) -> 0 | CN13: =SUM(CE13,BW13,BM13,BI13) -> 0 | CO13: =CF13+CB13+BN13+BJ13 -> 0 | CP13: =MAX(CH13,BN13,BJ13) -> 0 | CQ13: =IF($AV13="Yes",1,0) -> 0 | CR13: =IF($AV13="No",1,0) -> 0 | CS13: =IF($AV13="Not Specified",1,0) -> 1 | CT13: =IF(OR(AND(U13>=2026,U13<=2030),AND(X13>=2026,X13<=2030)),1,"") | CU13: =AA13&" "&AS13 | CV13: =MAX(AA13,AS13) -> 0 | CW13: 0 | CX13: 0 | CY13: 0 | CZ13: 0 | DA13: 0 | DB13: 0 | DC13: 0 | DD13: 0 | DE13: 0 | DF13: 0 | DG13: 0 | DH13: 0 | DI13: 0 | DJ13: 0 | DK13: 0 | DL13: 0 | DM13: 0 | DN13: 0 | DO13: 0 | DP13: 0 | DQ13: 0 | DR13: 0 | DS13: 0 | DT13: N | DU13: 0 | DV13: N | DW13: N | DX13: 0 | DY13: 0 | DZ13: =Q13 -> N | EA13: =Z13 | EB13: =AP13 -> N | EC13: =AJ13 -> N | ED13: =AV13 -> Not Specified | EF13: =MAX(AS13,AA13) -> 0
A14: 11 | B14: 16 | C14: McKesson | D14: Wholesalers: Health Care | E14: Health care and pharmaceuticals | F14: U.S. | G14: North America | H14: $359,051 | I14: $3,295 | J14: 0.098 | K14: $75,140 | L14: 44000 | M14: 31 | N14: N | Q14: Y | R14: Y | S14: Targets set | T14: 1.5°C | U14: 2032 | AC14: Other | AD14: Other Emission Reduction | AE14: Yes | AF14: Yes | AG14: Partial | AH14: 1,2 | AJ14: N | AP14: N | AV14: Not Specified | AW14: Not Specified | AX14: No | AY14: Y | AZ14: Mckesson has established the strategy to reduce GHG emissions from 2021, but has not clearly described about their end target (net zero). | BA14: 2032 | BG14: =IF(AND($N14="Y",$P14<=2025),1,0) -> 0 | BH14: =IF(AND($N14="Y",AND($P14>2025,$P14<=2030)),1,0) -> 0 | BI14: =IF(AND($N14="Y",$P14>2030),1,0) -> 0 | BJ14: =MAX(BG14:BI14) -> 0 | BK14: =IF(AND($R14="Y",$U14<=2025),1,0) -> 0 | BL14: =IF(AND($R14="Y",AND($U14>2025,$U14<=2030)),1,0) -> 0 | BM14: =IF(AND($R14="Y",$U14>2030),1,0) -> 1 | BN14: =MAX(BK14:BM14) -> 1 | BO14: =IF(AND($Y14="Y",$AA14<=2025),1,0) -> 0 | BP14: =IF(AND($Y14="Y",AND($AA14>2025,$AA14<=2030)),1,0) -> 0 | BQ14: =IF(AND($Y14="Y",$AA14>2030),1,0) -> 0 | BR14: =IF(AND($AP14="Y",$AS14<=2025),1,0) -> 0 | BS14: =IF(AND($AP14="Y",AND($AS14>2025,$AS14<=2030)),1,0) -> 0 | BT14: =IF(AND($AP14="Y",$AS14>2030),1,0) -> 0 | BU14: =IF(AND(AL14<=2025,CF14=0,AJ14="Y"),1,0) -> 0 | BV14: =IF(AND(AL14>=2026,AL14<=2030,AJ14="Y",CF14=0),1,0) -> 0 | BW14: =IF(AND(AL14>=2031,CF14=0,AJ14="Y"),1,0) -> 0 | BX14: =IF(AND($AJ14="Y",$AL14<=2024),1,0) -> 0 | BY14: =IF(AND($AJ14="Y",AND($AL14>2024,$AL14<=2030)),1,0) -> 0 | BZ14: =IF(AND($AJ14="Y",$AL14>2030),1,0) -> 0 | CA14: =MAX(BX14:BZ14) -> 0 | CB14: =IF(AND(CF14=0,AJ14="Y"),1,0) -> 0 | CC14: =MAX($BO14,$BR14) -> 0 | CD14: =MAX($BP14,$BS14) -> 0 | CE14: =MAX($BQ14,$BT14) -> 0 | CF14: =MAX(CC14:CE14) -> 0 | CG14: =MAX($CF14,$CA14) -> 0 | CH14: =MAX(CF14,CB14) -> 0 | CI14: =IF(AND($AY14="Y",$BA14<=2024),1,0) -> 0 | CJ14: =IF(AND($AY14="Y",AND($BA14>2024,$BA14<=2030)),1,0) -> 0 | CK14: =IF(AND($AY14="Y",$BA14>2030),1,0) -> 1 | CL14: =SUM(CC14,BU14,BK14,BG14) -> 0 | CM14: =SUM(CD14,BV14,BL14,BH14) -> 0 | CN14: =SUM(CE14,BW14,BM14,BI14) -> 1 | CO14: =CF14+CB14+BN14+BJ14 -> 1 | CP14: =MAX(CH14,BN14,BJ14) -> 1 | CQ14: =IF($AV14="Yes",1,0) -> 0 | CR14: =IF($AV14="No",1,0) -> 0 | CS14: =IF($AV14="Not Specified",1,0) -> 1 | CT14: =IF(OR(AND(U14>=2026,U14<=2030),AND(X14>=2026,X14<=2030)),1,"") | CU14: =AA14&" "&AS14 | CV14: =MAX(AA14,AS14) -> 0 | CW14: 0 | CX14: 0 | CY14: 0 | CZ14: 0 | DA14: 0 | DB14: 0 | DC14: 0 | DD14: 0 | DE14: 0 | DF14: 0 | DG14: 1 | DH14: 1 | DI14: 0 | DJ14: 0 | DK14: 0 | DL14: 0 | DM14: 0 | DN14: 0 | DO14: 0 | DP14: 0 | DQ14: 0 | DR14: 1 | DS14: 0 | DT14: Y | DU14: No | DV14: N | DW14: N | DX14: 0 | DY14: 0 | DZ14: =Q14 -> Y | EA14: =Z14 | EB14: =AP14 -> N | EC14: =AJ14 -> N | ED14: =AV14 -> Not Specified | EF14: =MAX(AS14,AA14) -> 0
A15: 12 | B15: 11 | C15: Volkswagen | D15: Motor Vehicles | E15: Automotive | F15: Germany | G15: Europe | H15: $351,093.3 | I15: $12,275.3 | J15: -0.316 | K15: $655,316.8 | L15: 646501 | M15: 31 | N15: N | Q15: Y | R15: Y | S15: Targets set | T15: 1.5Â°C/2Â°C | U15: 2030 | AC15: Carbon neutral(ity) | AD15: Carbon Neutral | AE15: Yes | AF15: Yes | AG15: Partial | AH15: 1,2 | AI15: C | AJ15: Y | AK15: achieve net carbon neutrality by 2050 (pg 236) | AL15: 2050 | AP15: N | AV15: Yes | AW15: Yes (nature-based removals e.g. Forestation, soil carbon enhancement) | AX15: No | AY15: N | BG15: =IF(AND($N15="Y",$P15<=2025),1,0) -> 0 | BH15: =IF(AND($N15="Y",AND($P15>2025,$P15<=2030)),1,0) -> 0 | BI15: =IF(AND($N15="Y",$P15>2030),1,0) -> 0 | BJ15: =MAX(BG15:BI15) -> 0 | BK15: =IF(AND($R15="Y",$U15<=2025),1,0) -> 0 | BL15: =IF(AND($R15="Y",AND($U15>2025,$U15<=2030)),1,0) -> 1 | BM15: =IF(AND($R15="Y",$U15>2030),1,0) -> 0 | BN15: =MAX(BK15:BM15) -> 1 | BO15: =IF(AND($Y15="Y",$AA15<=2025),1,0) -> 0 | BP15: =IF(AND($Y15="Y",AND($AA15>2025,$AA15<=2030)),1,0) -> 0 | BQ15: =IF(AND($Y15="Y",$AA15>2030),1,0) -> 0 | BR15: =IF(AND($AP15="Y",$AS15<=2025),1,0) -> 0 | BS15: =IF(AND($AP15="Y",AND($AS15>2025,$AS15<=2030)),1,0) -> 0 | BT15: =IF(AND($AP15="Y",$AS15>2030),1,0) -> 0 | BU15: =IF(AND(AL15<=2025,CF15=0,AJ15="Y"),1,0) -> 0 | BV15: =IF(AND(AL15>=2026,AL15<=2030,AJ15="Y",CF15=0),1,0) -> 0 | BW15: =IF(AND(AL15>=2031,CF15=0,AJ15="Y"),1,0) -> 1 | BX15: =IF(AND($AJ15="Y",$AL15<=2024),1,0) -> 0 | BY15: =IF(AND($AJ15="Y",AND($AL15>2024,$AL15<=2030)),1,0) -> 0 | BZ15: =IF(AND($AJ15="Y",$AL15>2030),1,0) -> 1 | CA15: =MAX(BX15:BZ15) -> 1 | CB15: =IF(AND(CF15=0,AJ15="Y"),1,0) -> 1 | CC15: =MAX($BO15,$BR15) -> 0 | CD15: =MAX($BP15,$BS15) -> 0 | CE15: =MAX($BQ15,$BT15) -> 0 | CF15: =MAX(CC15:CE15) -> 0 | CG15: =MAX($CF15,$CA15) -> 1 | CH15: =MAX(CF15,CB15) -> 1 | CI15: =IF(AND($AY15="Y",$BA15<=2024),1,0) -> 0 | CJ15: =IF(AND($AY15="Y",AND($BA15>2024,$BA15<=2030)),1,0) -> 0 | CK15: =IF(AND($AY15="Y",$BA15>2030),1,0) -> 0 | CL15: =SUM(CC15,BU15,BK15,BG15) -> 0 | CM15: =SUM(CD15,BV15,BL15,BH15) -> 1 | CN15: =SUM(CE15,BW15,BM15,BI15) -> 1 | CO15: =CF15+CB15+BN15+BJ15 -> 2 | CP15: =MAX(CH15,BN15,BJ15) -> 1 | CQ15: =IF($AV15="Yes",1,0) -> 1 | CR15: =IF($AV15="No",1,0) -> 0 | CS15: =IF($AV15="Not Specified",1,0) -> 0 | CT15: =IF(OR(AND(U15>=2026,U15<=2030),AND(X15>=2026,X15<=2030)),1,"") -> 1 | CU15: =AA15&" "&AS15 | CV15: =MAX(AA15,AS15) -> 0 | CW15: 0 | CX15: 0 | CY15: 1 | CZ15: 1 | DA15: 0 | DB15: 0 | DC15: 0 | DD15: 0 | DE15: 0 | DF15: 1 | DG15: 0 | DH15: 1 | DI15: 0 | DJ15: 0 | DK15: 0 | DL15: 0 | DM15: 1 | DN15: 0 | DO15: 1 | DP15: 1 | DQ15: 0 | DR15: 1 | DS15: 0 | DT15: Y | DU15: No | DV15: N | DW15: V | DX15: Y | DY15: 0 | DZ15: =Q15 -> Y | EA15: =Z15 | EB15: =AP15 -> N | EC15: =AJ15 -> Y | ED15: =AV15 -> Yes | EF15: =MAX(AS15,AA15) -> 0
A16: 13 | B16: 17 | C16: Alphabet | D16: Internet Services and Retailing | E16: Retail | F16: U.S. | G16: North America | H16: $350,018 | I16: $100,118 | J16: 0.357 | K16: $450,256 | L16: 183323 | M16: 17 | N16: N | Q16: Y | R16: Y | S16: Targets set | T16: 1.5°C | U16: 2030 | AC16: Net zero | AD16: Net Zero | AE16: Yes | AF16: Yes | AG16: Yes | AH16: 1,2,3 | AJ16: N | AO16: C,V | AP16: Y | AQ16: 1,2,3 | AR16: We aim to run on 24/7 carbon-free energy on every grid where we operate by 2030. Reduce 50% of our combined Scope 1, 2 (market-based), and 3 absolute emissions (versus our 2019 baseline) before 2030 | AS16: 2030 | AV16: No | AW16: Yes (nature-based and CCS-based removals) | AX16: Yes | AY16: N | BG16: =IF(AND($N16="Y",$P16<=2025),1,0) -> 0 | BH16: =IF(AND($N16="Y",AND($P16>2025,$P16<=2030)),1,0) -> 0 | BI16: =IF(AND($N16="Y",$P16>2030),1,0) -> 0 | BJ16: =MAX(BG16:BI16) -> 0 | BK16: =IF(AND($R16="Y",$U16<=2025),1,0) -> 0 | BL16: =IF(AND($R16="Y",AND($U16>2025,$U16<=2030)),1,0) -> 1 | BM16: =IF(AND($R16="Y",$U16>2030),1,0) -> 0 | BN16: =MAX(BK16:BM16) -> 1 | BO16: =IF(AND($Y16="Y",$AA16<=2025),1,0) -> 0 | BP16: =IF(AND($Y16="Y",AND($AA16>2025,$AA16<=2030)),1,0) -> 0 | BQ16: =IF(AND($Y16="Y",$AA16>2030),1,0) -> 0 | BR16: =IF(AND($AP16="Y",$AS16<=2025),1,0) -> 0 | BS16: =IF(AND($AP16="Y",AND($AS16>2025,$AS16<=2030)),1,0) -> 1 | BT16: =IF(AND($AP16="Y",$AS16>2030),1,0) -> 0 | BU16: =IF(AND(AL16<=2025,CF16=0,AJ16="Y"),1,0) -> 0 | BV16: =IF(AND(AL16>=2026,AL16<=2030,AJ16="Y",CF16=0),1,0) -> 0 | BW16: =IF(AND(AL16>=2031,CF16=0,AJ16="Y"),1,0) -> 0 | BX16: =IF(AND($AJ16="Y",$AL16<=2024),1,0) -> 0 | BY16: =IF(AND($AJ16="Y",AND($AL16>2024,$AL16<=2030)),1,0) -> 0 | BZ16: =IF(AND($AJ16="Y",$AL16>2030),1,0) -> 0 | CA16: =MAX(BX16:BZ16) -> 0 | CB16: =IF(AND(CF16=0,AJ16="Y"),1,0) -> 0 | CC16: =MAX($BO16,$BR16) -> 0 | CD16: =MAX($BP16,$BS16) -> 1 | CE16: =MAX($BQ16,$BT16) -> 0 | CF16: =MAX(CC16:CE16) -> 1 | CG16: =MAX($CF16,$CA16) -> 1 | CH16: =MAX(CF16,CB16) -> 1 | CI16: =IF(AND($AY16="Y",$BA16<=2024),1,0) -> 0 | CJ16: =IF(AND($AY16="Y",AND($BA16>2024,$BA16<=2030)),1,0) -> 0 | CK16: =IF(AND($AY16="Y",$BA16>2030),1,0) -> 0 | CL16: =SUM(CC16,BU16,BK16,BG16) -> 0 | CM16: =SUM(CD16,BV16,BL16,BH16) -> 2 | CN16: =SUM(CE16,BW16,BM16,BI16) -> 0 | CO16: =CF16+CB16+BN16+BJ16 -> 2 | CP16: =MAX(CH16,BN16,BJ16) -> 1 | CQ16: =IF($AV16="Yes",1,0) -> 0 | CR16: =IF($AV16="No",1,0) -> 1 | CS16: =IF($AV16="Not Specified",1,0) -> 0 | CT16: =IF(OR(AND(U16>=2026,U16<=2030),AND(X16>=2026,X16<=2030)),1,"") -> 1 | CU16: =AA16&" "&AS16 -> 2030 | CV16: =MAX(AA16,AS16) -> 2030 | CW16: 0 | CX16: 0 | CY16: 0 | CZ16: 0 | DA16: 0 | DB16: 1 | DC16: 0 | DD16: 1 | DE16: 0 | DF16: 1 | DG16: 0 | DH16: 1 | DI16: 0 | DJ16: 0 | DK16: 0 | DL16: 0 | DM16: 1 | DN16: 0 | DO16: 1 | DP16: 1 | DQ16: 0 | DR16: 1 | DS16: 0 | DT16: N | DU16: No | DV16: V | DW16: N | DX16: 0 | DY16: Y | DZ16: =Q16 -> Y | EA16: =Z16 | EB16: =AP16 -> Y | EC16: =AJ16 -> N | ED16: =AV16 -> No | EF16: =MAX(AS16,AA16) -> 2030
A17: 14 | B17: 12 | C17: Exxon Mobil | D17: Petroleum Refining | E17: Oil and gas | F17: U.S. | G17: North America | H17: $349,585 | I17: $33,680 | J17: -0.065 | K17: $453,475 | L17: 60900 | M17: 31 | N17: N | Q17: N | R17: N | AC17: Net zero | AD17: Net Zero | AE17: Yes | AF17: Yes | AG17: No | AH17: 1,2 | AJ17: N | AO17: C | AP17: Y | AQ17: 1,2 | AR17: "In January 2022, we announced a 2050 net-zero GHG ambition for our operated assets, which requires new advancements in technology and practical government policies." (covers Scopes 1 and 2) p7 | AS17: 2050 | AV17: Yes | AW17: Yes (CCS-based removals e.g. BECCS, DACCS) | AX17: No | AY17: N | BG17: =IF(AND($N17="Y",$P17<=2025),1,0) -> 0 | BH17: =IF(AND($N17="Y",AND($P17>2025,$P17<=2030)),1,0) -> 0 | BI17: =IF(AND($N17="Y",$P17>2030),1,0) -> 0 | BJ17: =MAX(BG17:BI17) -> 0 | BK17: =IF(AND($R17="Y",$U17<=2025),1,0) -> 0 | BL17: =IF(AND($R17="Y",AND($U17>2025,$U17<=2030)),1,0) -> 0 | BM17: =IF(AND($R17="Y",$U17>2030),1,0) -> 0 | BN17: =MAX(BK17:BM17) -> 0 | BO17: =IF(AND($Y17="Y",$AA17<=2025),1,0) -> 0 | BP17: =IF(AND($Y17="Y",AND($AA17>2025,$AA17<=2030)),1,0) -> 0 | BQ17: =IF(AND($Y17="Y",$AA17>2030),1,0) -> 0 | BR17: =IF(AND($AP17="Y",$AS17<=2025),1,0) -> 0 | BS17: =IF(AND($AP17="Y",AND($AS17>2025,$AS17<=2030)),1,0) -> 0 | BT17: =IF(AND($AP17="Y",$AS17>2030),1,0) -> 1 | BU17: =IF(AND(AL17<=2025,CF17=0,AJ17="Y"),1,0) -> 0 | BV17: =IF(AND(AL17>=2026,AL17<=2030,AJ17="Y",CF17=0),1,0) -> 0 | BW17: =IF(AND(AL17>=2031,CF17=0,AJ17="Y"),1,0) -> 0 | BX17: =IF(AND($AJ17="Y",$AL17<=2024),1,0) -> 0 | BY17: =IF(AND($AJ17="Y",AND($AL17>2024,$AL17<=2030)),1,0) -> 0 | BZ17: =IF(AND($AJ17="Y",$AL17>2030),1,0) -> 0 | CA17: =MAX(BX17:BZ17) -> 0 | CB17: =IF(AND(CF17=0,AJ17="Y"),1,0) -> 0 | CC17: =MAX($BO17,$BR17) -> 0 | CD17: =MAX($BP17,$BS17) -> 0 | CE17: =MAX($BQ17,$BT17) -> 1 | CF17: =MAX(CC17:CE17) -> 1 | CG17: =MAX($CF17,$CA17) -> 1 | CH17: =MAX(CF17,CB17) -> 1 | CI17: =IF(AND($AY17="Y",$BA17<=2024),1,0) -> 0 | CJ17: =IF(AND($AY17="Y",AND($BA17>2024,$BA17<=2030)),1,0) -> 0 | CK17: =IF(AND($AY17="Y",$BA17>2030),1,0) -> 0 | CL17: =SUM(CC17,BU17,BK17,BG17) -> 0 | CM17: =SUM(CD17,BV17,BL17,BH17) -> 0 | CN17: =SUM(CE17,BW17,BM17,BI17) -> 1 | CO17: =CF17+CB17+BN17+BJ17 -> 1 | CP17: =MAX(CH17,BN17,BJ17) -> 1 | CQ17: =IF($AV17="Yes",1,0) -> 1 | CR17: =IF($AV17="No",1,0) -> 0 | CS17: =IF($AV17="Not Specified",1,0) -> 0 | CT17: =IF(OR(AND(U17>=2026,U17<=2030),AND(X17>=2026,X17<=2030)),1,"") | CU17: =AA17&" "&AS17 -> 2050 | CV17: =MAX(AA17,AS17) -> 2050 | CW17: 0 | CX17: 0 | CY17: 0 | CZ17: 0 | DA17: 0 | DB17: 0 | DC17: 1 | DD17: 1 | DE17: 0 | DF17: 0 | DG17: 0 | DH17: 0 | DI17: 0 | DJ17: 0 | DK17: 0 | DL17: 0 | DM17: 1 | DN17: 0 | DO17: 1 | DP17: 1 | DQ17: 0 | DR17: 1 | DS17: 0 | DT17: N | DU17: 0 | DV17: C | DW17: N | DX17: 0 | DY17: Y | DZ17: =Q17 -> N | EA17: =Z17 | EB17: =AP17 -> Y | EC17: =AJ17 -> N | ED17: =AV17 -> Yes | EF17: =MAX(AS17,AA17) -> 2050
A18: 15 | B18: 15 | C18: Toyota Motor | D18: Motor Vehicles | E18: Automotive | F18: Japan | G18: Asia | H18: $315,110.2 | I18: $31,257.9 | J18: -0.086 | K18: $624,466.9 | L18: 383853 | M18: 31 | N18: N | Q18: Y | R18: Y | S18: Targets set | T18: 1.5°C / Well-below 2°C | U18: 2035 | AC18: Carbon neutral(ity) | AD18: Carbon Neutral | AE18: Yes | AF18: Yes | AG18: Yes | AH18: 1,2,3 | AI18: C,V | AJ18: Y | AK18: 2050: Achieve CN for GHG emissions throughout the life cycle, for average GHG emissions for new vehicles, for GHG emissions from corporate activities (pg 21 & 54) ** Applies to GHG emissions from the business activities of Toyota Motor Corporation and consolidated subsidiaries due to energy consumption and GHG emissions from business partners and customers in relation to vehicles under Toyota Motor Corporation and consolidated subsidiary brands. (Per vehicle, Scope1, 2, and 3) (Target for 2050 includes Toyota Motor Corporation and some consolidated subsidiaries.) | AL18: 2050 | AP18: N | AV18: Not Specified | AW18: Yes (CCS-based removals e.g. BECCS, DACCS) | AX18: No | AY18: N | BG18: =IF(AND($N18="Y",$P18<=2025),1,0) -> 0 | BH18: =IF(AND($N18="Y",AND($P18>2025,$P18<=2030)),1,0) -> 0 | BI18: =IF(AND($N18="Y",$P18>2030),1,0) -> 0 | BJ18: =MAX(BG18:BI18) -> 0 | BK18: =IF(AND($R18="Y",$U18<=2025),1,0) -> 0 | BL18: =IF(AND($R18="Y",AND($U18>2025,$U18<=2030)),1,0) -> 0 | BM18: =IF(AND($R18="Y",$U18>2030),1,0) -> 1 | BN18: =MAX(BK18:BM18) -> 1 | BO18: =IF(AND($Y18="Y",$AA18<=2025),1,0) -> 0 | BP18: =IF(AND($Y18="Y",AND($AA18>2025,$AA18<=2030)),1,0) -> 0 | BQ18: =IF(AND($Y18="Y",$AA18>2030),1,0) -> 0 | BR18: =IF(AND($AP18="Y",$AS18<=2025),1,0) -> 0 | BS18: =IF(AND($AP18="Y",AND($AS18>2025,$AS18<=2030)),1,0) -> 0 | BT18: =IF(AND($AP18="Y",$AS18>2030),1,0) -> 0 | BU18: =IF(AND(AL18<=2025,CF18=0,AJ18="Y"),1,0) -> 0 | BV18: =IF(AND(AL18>=2026,AL18<=2030,AJ18="Y",CF18=0),1,0) -> 0 | BW18: =IF(AND(AL18>=2031,CF18=0,AJ18="Y"),1,0) -> 1 | BX18: =IF(AND($AJ18="Y",$AL18<=2024),1,0) -> 0 | BY18: =IF(AND($AJ18="Y",AND($AL18>2024,$AL18<=2030)),1,0) -> 0 | BZ18: =IF(AND($AJ18="Y",$AL18>2030),1,0) -> 1 | CA18: =MAX(BX18:BZ18) -> 1 | CB18: =IF(AND(CF18=0,AJ18="Y"),1,0) -> 1 | CC18: =MAX($BO18,$BR18) -> 0 | CD18: =MAX($BP18,$BS18) -> 0 | CE18: =MAX($BQ18,$BT18) -> 0 | CF18: =MAX(CC18:CE18) -> 0 | CG18: =MAX($CF18,$CA18) -> 1 | CH18: =MAX(CF18,CB18) -> 1 | CI18: =IF(AND($AY18="Y",$BA18<=2024),1,0) -> 0 | CJ18: =IF(AND($AY18="Y",AND($BA18>2024,$BA18<=2030)),1,0) -> 0 | CK18: =IF(AND($AY18="Y",$BA18>2030),1,0) -> 0 | CL18: =SUM(CC18,BU18,BK18,BG18) -> 0 | CM18: =SUM(CD18,BV18,BL18,BH18) -> 0 | CN18: =SUM(CE18,BW18,BM18,BI18) -> 2 | CO18: =CF18+CB18+BN18+BJ18 -> 2 | CP18: =MAX(CH18,BN18,BJ18) -> 1 | CQ18: =IF($AV18="Yes",1,0) -> 0 | CR18: =IF($AV18="No",1,0) -> 0 | CS18: =IF($AV18="Not Specified",1,0) -> 1 | CT18: =IF(OR(AND(U18>=2026,U18<=2030),AND(X18>=2026,X18<=2030)),1,"") | CU18: =AA18&" "&AS18 | CV18: =MAX(AA18,AS18) -> 0 | CW18: 0 | CX18: 0 | CY18: 1 | CZ18: 1 | DA18: 0 | DB18: 0 | DC18: 0 | DD18: 0 | DE18: 0 | DF18: 1 | DG18: 0 | DH18: 1 | DI18: 0 | DJ18: 0 | DK18: 0 | DL18: 0 | DM18: 1 | DN18: 0 | DO18: 1 | DP18: 1 | DQ18: 0 | DR18: 1 | DS18: 0 | DT18: Y | DU18: No | DV18: N | DW18: V | DX18: Y | DY18: 0 | DZ18: =Q18 -> Y | EA18: =Z18 | EB18: =AP18 -> N | EC18: =AJ18 -> Y | ED18: =AV18 -> Not Specified | EF18: =MAX(AS18,AA18) -> 0
A19: 16 | B19: 14 | C19: China State Construction Engineering | D19: Engineering & Construction | E19: Engineering and construction | F19: China | G19: Asia | H19: $304,121.3 | I19: $3,667.4 | J19: -0.161 | K19: $438,013.2 | L19: 361249 | M19: 14 | N19: N | Q19: N | R19: N | AC19: Carbon neutral(ity) | AD19: Carbon Neutral | AE19: Yes | AF19: Yes | AG19: Not Specified | AH19: 1,2 | AI19: C | AJ19: Y | AK19: CSCEC will possess global core competitiveness in green, low carbon development, with world class capabilities in low-carbon industries, products, construction, and operations. We will secure a leading position in both domestic and global operations. The Company will realize the green transformation of production methods and play a pivotal role in the construction industry‚Äôs path to carbon neutrality, contributing significantly to China‚Äôs goal of carbon neutrality | AL19: 2060 | AP19: N | AV19: Not Specified | AW19: Not Specified | AX19: No | AY19: N | BG19: =IF(AND($N19="Y",$P19<=2025),1,0) -> 0 | BH19: =IF(AND($N19="Y",AND($P19>2025,$P19<=2030)),1,0) -> 0 | BI19: =IF(AND($N19="Y",$P19>2030),1,0) -> 0 | BJ19: =MAX(BG19:BI19) -> 0 | BK19: =IF(AND($R19="Y",$U19<=2025),1,0) -> 0 | BL19: =IF(AND($R19="Y",AND($U19>2025,$U19<=2030)),1,0) -> 0 | BM19: =IF(AND($R19="Y",$U19>2030),1,0) -> 0 | BN19: =MAX(BK19:BM19) -> 0 | BO19: =IF(AND($Y19="Y",$AA19<=2025),1,0) -> 0 | BP19: =IF(AND($Y19="Y",AND($AA19>2025,$AA19<=2030)),1,0) -> 0 | BQ19: =IF(AND($Y19="Y",$AA19>2030),1,0) -> 0 | BR19: =IF(AND($AP19="Y",$AS19<=2025),1,0) -> 0 | BS19: =IF(AND($AP19="Y",AND($AS19>2025,$AS19<=2030)),1,0) -> 0 | BT19: =IF(AND($AP19="Y",$AS19>2030),1,0) -> 0 | BU19: =IF(AND(AL19<=2025,CF19=0,AJ19="Y"),1,0) -> 0 | BV19: =IF(AND(AL19>=2026,AL19<=2030,AJ19="Y",CF19=0),1,0) -> 0 | BW19: =IF(AND(AL19>=2031,CF19=0,AJ19="Y"),1,0) -> 1 | BX19: =IF(AND($AJ19="Y",$AL19<=2024),1,0) -> 0 | BY19: =IF(AND($AJ19="Y",AND($AL19>2024,$AL19<=2030)),1,0) -> 0 | BZ19: =IF(AND($AJ19="Y",$AL19>2030),1,0) -> 1 | CA19: =MAX(BX19:BZ19) -> 1 | CB19: =IF(AND(CF19=0,AJ19="Y"),1,0) -> 1 | CC19: =MAX($BO19,$BR19) -> 0 | CD19: =MAX($BP19,$BS19) -> 0 | CE19: =MAX($BQ19,$BT19) -> 0 | CF19: =MAX(CC19:CE19) -> 0 | CG19: =MAX($CF19,$CA19) -> 1 | CH19: =MAX(CF19,CB19) -> 1 | CI19: =IF(AND($AY19="Y",$BA19<=2024),1,0) -> 0 | CJ19: =IF(AND($AY19="Y",AND($BA19>2024,$BA19<=2030)),1,0) -> 0 | CK19: =IF(AND($AY19="Y",$BA19>2030),1,0) -> 0 | CL19: =SUM(CC19,BU19,BK19,BG19) -> 0 | CM19: =SUM(CD19,BV19,BL19,BH19) -> 0 | CN19: =SUM(CE19,BW19,BM19,BI19) -> 1 | CO19: =CF19+CB19+BN19+BJ19 -> 1 | CP19: =MAX(CH19,BN19,BJ19) -> 1 | CQ19: =IF($AV19="Yes",1,0) -> 0 | CR19: =IF($AV19="No",1,0) -> 0 | CS19: =IF($AV19="Not Specified",1,0) -> 1 | CT19: =IF(OR(AND(U19>=2026,U19<=2030),AND(X19>=2026,X19<=2030)),1,"") | CU19: =AA19&" "&AS19 | CV19: =MAX(AA19,AS19) -> 0 | CW19: 0 | CX19: 0 | CY19: 1 | CZ19: 1 | DA19: 0 | DB19: 0 | DC19: 0 | DD19: 0 | DE19: 0 | DF19: 0 | DG19: 0 | DH19: 0 | DI19: 0 | DJ19: 0 | DK19: 0 | DL19: 0 | DM19: 1 | DN19: 0 | DO19: 1 | DP19: 0 | DQ19: 0 | DR19: 1 | DS19: 0 | DT19: N | DU19: 0 | DV19: N | DW19: C | DX19: U | DY19: 0 | DZ19: =Q19 -> N | EA19: =Z19 | EB19: =AP19 -> N | EC19: =AJ19 -> Y | ED19: =AV19 -> Not Specified | EF19: =MAX(AS19,AA19) -> 0
A20: 17 | B20: 18 | C20: Cencora | D20: Wholesalers: Health Care | E20: Health care and pharmaceuticals | F20: U.S. | G20: North America | H20: $293,958.6 | I20: $1,509.1 | J20: -0.135 | K20: $67,101.7 | L20: 44000 | M20: 26 | N20: N | Q20: Y | R20: Y | S20: Targets set | T20: 1.5°C | U20: 2032 | AC20: Emissions reduction target | AD20: Other Emission Reduction | AE20: Yes | AF20: Yes | AG20: Yes | AH20: 1,2,3 | AJ20: N | AP20: N | AV20: Not Specified | AW20: Not Specified | AX20: No | AY20: Y | AZ20: "Cencora has a fully verified science-based target to reduce absolute Scope 1 and 2 greenhouse gas emissions 54.6% by FY2032 from a FY2019 base year. Cencora also commits that 82% of its suppliers by spend, covering purchased goods and services, will have science-based targets by FY2027" (Page 7, Cencora FY23 ESG Reporting Index). | BA20: 2032 | BG20: =IF(AND($N20="Y",$P20<=2025),1,0) -> 0 | BH20: =IF(AND($N20="Y",AND($P20>2025,$P20<=2030)),1,0) -> 0 | BI20: =IF(AND($N20="Y",$P20>2030),1,0) -> 0 | BJ20: =MAX(BG20:BI20) -> 0 | BK20: =IF(AND($R20="Y",$U20<=2025),1,0) -> 0 | BL20: =IF(AND($R20="Y",AND($U20>2025,$U20<=2030)),1,0) -> 0 | BM20: =IF(AND($R20="Y",$U20>2030),1,0) -> 1 | BN20: =MAX(BK20:BM20) -> 1 | BO20: =IF(AND($Y20="Y",$AA20<=2025),1,0) -> 0 | BP20: =IF(AND($Y20="Y",AND($AA20>2025,$AA20<=2030)),1,0) -> 0 | BQ20: =IF(AND($Y20="Y",$AA20>2030),1,0) -> 0 | BR20: =IF(AND($AP20="Y",$AS20<=2025),1,0) -> 0 | BS20: =IF(AND($AP20="Y",AND($AS20>2025,$AS20<=2030)),1,0) -> 0 | BT20: =IF(AND($AP20="Y",$AS20>2030),1,0) -> 0 | BU20: =IF(AND(AL20<=2025,CF20=0,AJ20="Y"),1,0) -> 0 | BV20: =IF(AND(AL20>=2026,AL20<=2030,AJ20="Y",CF20=0),1,0) -> 0 | BW20: =IF(AND(AL20>=2031,CF20=0,AJ20="Y"),1,0) -> 0 | BX20: =IF(AND($AJ20="Y",$AL20<=2024),1,0) -> 0 | BY20: =IF(AND($AJ20="Y",AND($AL20>2024,$AL20<=2030)),1,0) -> 0 | BZ20: =IF(AND($AJ20="Y",$AL20>2030),1,0) -> 0 | CA20: =MAX(BX20:BZ20) -> 0 | CB20: =IF(AND(CF20=0,AJ20="Y"),1,0) -> 0 | CC20: =MAX($BO20,$BR20) -> 0 | CD20: =MAX($BP20,$BS20) -> 0 | CE20: =MAX($BQ20,$BT20) -> 0 | CF20: =MAX(CC20:CE20) -> 0 | CG20: =MAX($CF20,$CA20) -> 0 | CH20: =MAX(CF20,CB20) -> 0 | CI20: =IF(AND($AY20="Y",$BA20<=2024),1,0) -> 0 | CJ20: =IF(AND($AY20="Y",AND($BA20>2024,$BA20<=2030)),1,0) -> 0 | CK20: =IF(AND($AY20="Y",$BA20>2030),1,0) -> 1 | CL20: =SUM(CC20,BU20,BK20,BG20) -> 0 | CM20: =SUM(CD20,BV20,BL20,BH20) -> 0 | CN20: =SUM(CE20,BW20,BM20,BI20) -> 1 | CO20: =CF20+CB20+BN20+BJ20 -> 1 | CP20: =MAX(CH20,BN20,BJ20) -> 1 | CQ20: =IF($AV20="Yes",1,0) -> 0 | CR20: =IF($AV20="No",1,0) -> 0 | CS20: =IF($AV20="Not Specified",1,0) -> 1 | CT20: =IF(OR(AND(U20>=2026,U20<=2030),AND(X20>=2026,X20<=2030)),1,"") | CU20: =AA20&" "&AS20 | CV20: =MAX(AA20,AS20) -> 0 | CW20: 0 | CX20: 0 | CY20: 0 | CZ20: 0 | DA20: 0 | DB20: 0 | DC20: 0 | DD20: 0 | DE20: 0 | DF20: 1 | DG20: 0 | DH20: 1 | DI20: 0 | DJ20: 0 | DK20: 0 | DL20: 0 | DM20: 0 | DN20: 0 | DO20: 0 | DP20: 0 | DQ20: 0 | DR20: 1 | DS20: 0 | DT20: Y | DU20: No | DV20: N | DW20: N | DX20: 0 | DY20: 0 | DZ20: =Q20 -> Y | EA20: =Z20 | EB20: =AP20 -> N | EC20: =AJ20 -> N | ED20: =AV20 -> Not Specified | EF20: =MAX(AS20,AA20) -> 0
A21: 18 | B21: 13 | C21: Shell | D21: Petroleum Refining | E21: Oil and gas | F21: Britain | G21: Europe | H21: $289,029 | I21: $16,094 | J21: -0.169 | K21: $387,609 | L21: 96000 | M21: 31 | N21: N | Q21: N | R21: N | AC21: Net zero | AD21: Net Zero | AE21: Yes | AF21: Yes | AG21: Yes | AH21: 1,2,3 | AJ21: N | AO21: C,V | AP21: Y | AQ21: 1,2,3 | AR21: "Net-zero emissions by 2025 (Scope 1, 2 and 3)" p93 2024 report Scope 3: "Reduce the net carbon intensity (NCI) of the energy products we sell by 100% by 2050 (2016 baseline)" (Annual Report 2024, p. 15; Energy Transition Strategy 2024, pp. 9 & 10) | AS21: 2050 | AV21: Yes | AW21: Yes (nature-based and CCS-based removals) | AX21: No | AY21: N | BG21: =IF(AND($N21="Y",$P21<=2025),1,0) -> 0 | BH21: =IF(AND($N21="Y",AND($P21>2025,$P21<=2030)),1,0) -> 0 | BI21: =IF(AND($N21="Y",$P21>2030),1,0) -> 0 | BJ21: =MAX(BG21:BI21) -> 0 | BK21: =IF(AND($R21="Y",$U21<=2025),1,0) -> 0 | BL21: =IF(AND($R21="Y",AND($U21>2025,$U21<=2030)),1,0) -> 0 | BM21: =IF(AND($R21="Y",$U21>2030),1,0) -> 0 | BN21: =MAX(BK21:BM21) -> 0 | BO21: =IF(AND($Y21="Y",$AA21<=2025),1,0) -> 0 | BP21: =IF(AND($Y21="Y",AND($AA21>2025,$AA21<=2030)),1,0) -> 0 | BQ21: =IF(AND($Y21="Y",$AA21>2030),1,0) -> 0 | BR21: =IF(AND($AP21="Y",$AS21<=2025),1,0) -> 0 | BS21: =IF(AND($AP21="Y",AND($AS21>2025,$AS21<=2030)),1,0) -> 0 | BT21: =IF(AND($AP21="Y",$AS21>2030),1,0) -> 1 | BU21: =IF(AND(AL21<=2025,CF21=0,AJ21="Y"),1,0) -> 0 | BV21: =IF(AND(AL21>=2026,AL21<=2030,AJ21="Y",CF21=0),1,0) -> 0 | BW21: =IF(AND(AL21>=2031,CF21=0,AJ21="Y"),1,0) -> 0 | BX21: =IF(AND($AJ21="Y",$AL21<=2024),1,0) -> 0 | BY21: =IF(AND($AJ21="Y",AND($AL21>2024,$AL21<=2030)),1,0) -> 0 | BZ21: =IF(AND($AJ21="Y",$AL21>2030),1,0) -> 0 | CA21: =MAX(BX21:BZ21) -> 0 | CB21: =IF(AND(CF21=0,AJ21="Y"),1,0) -> 0 | CC21: =MAX($BO21,$BR21) -> 0 | CD21: =MAX($BP21,$BS21) -> 0 | CE21: =MAX($BQ21,$BT21) -> 1 | CF21: =MAX(CC21:CE21) -> 1 | CG21: =MAX($CF21,$CA21) -> 1 | CH21: =MAX(CF21,CB21) -> 1 | CI21: =IF(AND($AY21="Y",$BA21<=2024),1,0) -> 0 | CJ21: =IF(AND($AY21="Y",AND($BA21>2024,$BA21<=2030)),1,0) -> 0 | CK21: =IF(AND($AY21="Y",$BA21>2030),1,0) -> 0 | CL21: =SUM(CC21,BU21,BK21,BG21) -> 0 | CM21: =SUM(CD21,BV21,BL21,BH21) -> 0 | CN21: =SUM(CE21,BW21,BM21,BI21) -> 1 | CO21: =CF21+CB21+BN21+BJ21 -> 1 | CP21: =MAX(CH21,BN21,BJ21) -> 1 | CQ21: =IF($AV21="Yes",1,0) -> 1 | CR21: =IF($AV21="No",1,0) -> 0 | CS21: =IF($AV21="Not Specified",1,0) -> 0 | CT21: =IF(OR(AND(U21>=2026,U21<=2030),AND(X21>=2026,X21<=2030)),1,"") | CU21: =AA21&" "&AS21 -> 2050 | CV21: =MAX(AA21,AS21) -> 2050 | CW21: 0 | CX21: 0 | CY21: 0 | CZ21: 0 | DA21: 0 | DB21: 0 | DC21: 1 | DD21: 1 | DE21: 0 | DF21: 0 | DG21: 0 | DH21: 0 | DI21: 0 | DJ21: 0 | DK21: 0 | DL21: 0 | DM21: 1 | DN21: 0 | DO21: 1 | DP21: 1 | DQ21: 0 | DR21: 1 | DS21: 0 | DT21: N | DU21: 0 | DV21: V | DW21: N | DX21: 0 | DY21: Y | DZ21: =Q21 -> N | EA21: =Z21 | EB21: =AP21 -> Y | EC21: =AJ21 -> N | ED21: =AV21 -> Yes | EF21: =MAX(AS21,AA21) -> 2050
