Workbook

Sheet 2024
A1: Rank | B1: Company Name | C1: 2023 rank | D1: Target summary | E1: Who dunnit? | F1: Date completed | G1: compared with 2023 data? | H1: Profits usable ($M) | I1: Sector (Fortune) | J1: Sector (final classification) | K1: Country | L1: Region | M1: RE100 (Y/N) | N1: Joining year | O1: Target year | P1: SBT (Y = yes, N=no) | Q1: Target status - NT | R1: Target classification NT - temp | S1: Target year NT (earlier of the two dates if there were two) - if committed, then year set to 2030 | T1: Net zero committed (SBTi) | U1: SBTi NZ approved year | V1: Commitment date (SBTi) | W1: Commitment year (SBTi) | X1: Carbon neutral commitment (C = company, V = value chain, G= Government, S = subsidiary, U = unspecified, x = less than 50% of rev, N=no) | Y1: Carbon neutral scope(s) (in their words) (+ indicates two targets/ a later target) | Z1: Carbon neutral claim (in their words) | AA1: Carbon neutral commitment - EARLY | AB1: Earlier carbon neutral target year | AC1: Earlier carbon neutral announcement year | AD1: Carbon neutral commitment - LATE | AE1: Later carbon neutral target year | AF1: Later carbon neutral announcement year | AG1: Carbon credits (Y = yes, N = no, R = removals only, U = unclear) | AH1: Souce Date | AI1: Source Target Mention (Y or N) | AJ1: Sustainability report | AK1: Press release | AL1: Source | AM1: Notes (including climate positive) | AN1: Net zero commitment (V = value chain, C = company, S = subsidiary, U = unclear, x = less than 50% rev) | AO1: Primary net zero scope (in their words) | AP1: Primary net zero claim (in their words) | AQ1: Net Zero Target - EARLY | AR1: Earlier net zero target year | AS1: Earlier net zero announcement year | AT1: Net Zero Target - LATE | AU1: Later net zero target year | AV1: Later net zero announcement year | AW1: Carbon credits (Y = yes, N = no, R = removals only, U = unclear).1 | AX1: Source.1 | AY1: Souce Date.1 | AZ1: Source Target Mention (Y or N).1 | BA1: Sustainability report.1 | BB1: Press release.1 | BC1: Notes | BD1: Reduction targets for Decarbonization (V = value chain, C = company) | BE1: Source.2 | BF1: Using Carbon Credits without target (Y=yes, N=No) | BG1: Source.3 | BH1: Questions | BI1: Interesting points | BJ1: CN already achieved | BK1: CN 2024-2030 | BL1: CN 2031-2050 | BM1: Any CN | BN1: NZ already achieved | BO1: NZ 2024-2030 | BP1: NZ 2031-2050 | BQ1: Any NZ | BR1: SBT already achieved | BS1: SBT 2024-2030 | BT1: SBT 2031-2050 | BU1: Any SBT | BV1: RE100 already achieved | BW1: RE100 2024-2030 | BX1: RE100 2031-2050 | BY1: Any RE100 | BZ1: CN/NZ - does the company have a voluntary CN or NZ target? | CA1: CN/NZ by 2030 | CB1: CN/NZ by 2050 | CC1: will use cabon credits | CD1: will NOT use carbon credits | CE1: any commitment | CF1: any commitment already achieved | CG1: any commitment by 2030 | CH1: any commitment by 2050 | CI1: NZ covering VC already achieved | CJ1: NZ covering VC 2024-2030 | CK1: NZ covering VC 2031-2050 | CL1: Any NZ covering VC | CM1: NZ year
A2: 489 | B2: 3M | C2: 443 | D2: =CONCATENATE((IF(BM2=1, "CN", "")),(IF(BQ2=1, " NZ", "")),(IF(BU2=1, " SBT", "")),(IF(BY2=1, " RE100", ""))) -> CN SBT RE100 | E2: DT * | F2: 45511 | G2: DT | H2: -6995 | J2: Chemicals | K2: United States of America (USA) | L2: North America | M2: Y | N2: 2019 | O2: 2050 | P2: N | Q2: Committed | S2: 2030 | T2: No | V2: 45231 | W2: 2023 | X2: C | Y2: operations | Z2: carbon neutral | AA2: C | AB2: 2050 | AC2: 2021 | AG2: Y | AI2: Y | AL2: https://multimedia.3m.com/mws/media/2395043O/3m-2024-global-impact-report.pdf | AN2: N | AQ2: N | BL2: 1 | BM2: 1 | BS2: 1 | BU2: 1 | BX2: 1 | BY2: 1 | BZ2: 1 | CB2: 1 | CC2: 1 | CE2: 1 | CG2: 1 | CH2: 1
A3: 498 | B3: ABB | D3: =CONCATENATE((IF(BM3=1, "CN", "")),(IF(BQ3=1, " NZ", "")),(IF(BU3=1, " SBT", "")),(IF(BY3=1, " RE100", ""))) -> NZ SBT RE100 | E3: AJ | F3: 45512 | H3: 3745 | I3: Industrial Machinery | J3: Industrial goods | K3: Switzerland | L3: Europe | M3: Y | N3: 2021 | O3: 2030 | P3: Y | Q3: Targets Set | R3: 1.5°C | S3: 2030 | T3: Yes | U3: 2050 | V3: 01/05/2021 | W3: 2021 | X3: N | AA3: N | AN3: V | AO3: SBTi approved so value chain | AP3: Net Zero | AQ3: V | AR3: 2050 | AS3: 2021 | AW3: R | AX3: https://global.abb/group/en/sustainability | AY3: 2023 | AZ3: Y | BA3: https://search.abb.com/library/Download.aspx?DocumentID=9AKK108469A1083&LanguageCode=en&DocumentPartId=&Action=Launch | BP3: 1 | BQ3: 1 | BS3: 1 | BU3: 1 | BW3: 1 | BY3: 1 | BZ3: 1 | CB3: 1 | CC3: 1 | CE3: 1 | CG3: 1 | CH3: 1 | CK3: 1 | CL3: 1 | CM3: =MAX(U3,AR3) -> 2050 | CR3: SBTi short term | CU3: RE100 | CX3: Carbon Neutral | DA3: Net Zero | DD3: sum
A4: 376 | B4: Abbott Laboratories | C4: 338 | D4: =CONCATENATE((IF(BM4=1, "CN", "")),(IF(BQ4=1, " NZ", "")),(IF(BU4=1, " SBT", "")),(IF(BY4=1, " RE100", ""))) -> SBT | E4: EC | F4: 45482 | G4: DT | H4: 5723 | J4: Health care and pharmaceuticals | K4: United States of America (USA) | L4: North America | M4: N | P4: Y | Q4: Targets Set | R4: Well-below 2Â°C | S4: 2030 | T4: No | V4: 44805 | W4: 2022 | X4: N | AA4: N | AN4: N | AQ4: N | BD4: C | BE4: https://www.abbott.com/content/dam/corp/abbott/en-us/hub-new/Abbott-2023-Global-Sustainability-Report-June-2024.pdf | BS4: 1 | BU4: 1 | CE4: 1 | CG4: 1 | CH4: 1 | CQ4: Sector | CR4: <=2024 | CS4: 2025-2030 | CT4: 2031-2060 | CU4: <=2024 | CV4: 2025-2030 | CW4: 2031-2060 | CX4: <=2024 | CY4: 2025-2030 | CZ4: 2031-2060 | DA4: <=2024 | DB4: 2025-2030 | DC4: 2031-2060 | DE4: Yes | DF4: No | DG4: Unspecified
A5: 259 | B5: AbbVie | C5: 240 | D5: =CONCATENATE((IF(BM5=1, "CN", "")),(IF(BQ5=1, " NZ", "")),(IF(BU5=1, " SBT", "")),(IF(BY5=1, " RE100", ""))) -> NZ SBT | E5: DT | F5: 45477 | G5: DT | H5: 4863 | J5: Health care and pharmaceuticals | K5: United States of America (USA) | L5: North America | M5: N | P5: Y | Q5: Targets Set | R5: 1.5Â°C | S5: 2030 | T5: No | V5: 45017 | W5: 2023 | X5: N | AA5: N | AN5: C | AO5: Scope 1 and 2 | AP5: Net Zero | AQ5: C | AR5: 2050 | AS5: 2021 | AW5: Y | AX5: https://www.abbvie.co.uk/content/dam/abbvie-dotcom/gb/documents/OCTOBER%20UK-ABBV-230401%20-%20Carbon%20Reduction%20Plan.pdf https://www.abbvie.com/sustainability/environmental-social-and-governance/environmental-sustainability.html#:~:text=In%20our%20determined%20effort%20to,and%20use%20cleaner%20energy%20sources | BP5: 1 | BQ5: 1 | BS5: 1 | BU5: 1 | BZ5: 1 | CB5: 1 | CC5: 1 | CE5: 1 | CG5: 1 | CH5: 1 | CM5: =MAX(U5,AR5) -> 2050 | CQ5: Aerospace and defense | CR5: =COUNTIFS($J$2:$J$501,CQ5,$S$2:$S$501,"<=2024") -> 0 | CS5: =COUNTIFS($J$2:$J$501,CQ5,$S$2:$S$501,">=2025",$S$2:$S$501,"<=2030") -> 1 | CT5: =COUNTIFS($J$2:$J$501,CQ5,$S$2:$S$501,">2030") -> 0 | CU5: =COUNTIFS($J$2:$J$501,CQ5,$O$2:$O$501,"<=2024") -> 0 | CV5: =COUNTIFS($J$2:$J$501,CQ5,$O$2:$O$501,">=2025",$O$2:$O$501,"<=2030") -> 0 | CW5: =COUNTIFS($J$2:$J$501,CQ5,$O$5:$O$504,">2030") -> 0 | CX5: =COUNTIFS($J$2:$J$501,CQ5,$AB$2:$AB$501,"<=2024") -> 1 | CY5: =COUNTIFS($J$2:$J$501,CQ5,$AB$2:$AB$501,">=2024",$AB$2:$AB$501,"<=2030") -> 0 | CZ5: =COUNTIFS($J$2:$J$501,CQ5,$AB$2:$AB$501,">2030") -> 1 | DA5: =COUNTIFS($J$2:$J$501,CQ5,$CM$2:$CM$501,"<=2024") -> 0 | DB5: =COUNTIFS($J$2:$J$501,CQ5,$CM$2:$CM$501,">=2025",$CM$2:$CM$501,"<=2030") -> 0 | DC5: =COUNTIFS($J$2:$J$501,CQ5,$CM$2:$CM$501,">2030") -> 4 | DD5: =SUM(CR5:DC5) -> 7 | DE5: =COUNTIFS($J$2:$J$501, CQ5, $CC$2:$CC$501, "1") -> 4 | DF5: =COUNTIFS($J$2:$J$501, CQ5, $CD$2:$CD$501, "1") -> 0 | DG5: =COUNTIF($J$2:$J$501, CQ5)-DF5-DE5 -> 6
A6: 211 | B6: Accenture | C6: 220 | D6: =CONCATENATE((IF(BM6=1, "CN", "")),(IF(BQ6=1, " NZ", "")),(IF(BU6=1, " SBT", "")),(IF(BY6=1, " RE100", ""))) -> NZ SBT RE100 | E6: DT | F6: 45477 | G6: DT | H6: 6871.6 | J6: Financial services | K6: Ireland | L6: Europe | M6: Y | N6: 2019 | O6: 2023 | P6: Y | Q6: Targets Set | R6: 1.5Â°C | S6: 2030 | T6: Yes | U6: 2040 | V6: 45444 | W6: 2024 | X6: N | AA6: N | AN6: V | AO6: Scope 1, 2 and 3 | AP6: Net Zero | AQ6: V | AR6: 2040 | AS6: 2020 | AW6: Y | AX6: https://www.accenture.com/content/dam/accenture/final/corporate/corporate-initiatives/sustainability/document/360-Value-Report-2023.pdf | BP6: 1 | BQ6: 1 | BS6: 1 | BU6: 1 | BV6: 1 | BY6: 1 | BZ6: 1 | CA6: 1 | CB6: 1 | CC6: 1 | CE6: 1 | CF6: 1 | CG6: 1 | CH6: 1 | CK6: 1 | CL6: 1 | CM6: =MAX(U6,AR6) -> 2040 | CQ6: Automotive | CR6: =COUNTIFS($J$2:$J$501,CQ6,$S$2:$S$501,"<=2024") -> 0 | CS6: =COUNTIFS($J$2:$J$501,CQ6,$S$2:$S$501,">=2025",$S$2:$S$501,"<=2030") -> 16 | CT6: =COUNTIFS($J$2:$J$501,CQ6,$S$2:$S$501,">2030") -> 3 | CU6: =COUNTIFS($J$2:$J$501,CQ6,$O$2:$O$501,"<=2024") -> 0 | CV6: =COUNTIFS($J$2:$J$501,CQ6,$O$2:$O$501,">=2025",$O$2:$O$501,"<=2030") -> 1 | CW6: =COUNTIFS($J$2:$J$501,CQ6,$O$5:$O$504,">2030") -> 2 | CX6: =COUNTIFS($J$2:$J$501,CQ6,$AB$2:$AB$501,"<=2024") -> 2 | CY6: =COUNTIFS($J$2:$J$501,CQ6,$AB$2:$AB$501,">=2024",$AB$2:$AB$501,"<=2030") -> 3 | CZ6: =COUNTIFS($J$2:$J$501,CQ6,$AB$2:$AB$501,">2030") -> 21 | DA6: =COUNTIFS($J$2:$J$501,CQ6,$CM$2:$CM$501,"<=2024") -> 0 | DB6: =COUNTIFS($J$2:$J$501,CQ6,$CM$2:$CM$501,">=2025",$CM$2:$CM$501,"<=2030") -> 0 | DC6: =COUNTIFS($J$2:$J$501,CQ6,$CM$2:$CM$501,">2030") -> 7 | DD6: =SUM(CR6:DC6) -> 55 | DE6: =COUNTIFS($J$2:$J$501, CQ6, $CC$2:$CC$501, "1") -> 17 | DF6: =COUNTIFS($J$2:$J$501, CQ6, $CD$2:$CD$501, "1") -> 0 | DG6: =COUNTIF($J$2:$J$501, CQ6)-DF6-DE6 -> 20
A7: 391 | B7: ACS | C7: 428 | D7: =CONCATENATE((IF(BM7=1, "CN", "")),(IF(BQ7=1, " NZ", "")),(IF(BU7=1, " SBT", "")),(IF(BY7=1, " RE100", ""))) -> CN | E7: AJ | F7: 45511 | G7: AJ | H7: 843.4 | J7: Engineering and construction | K7: Spain | L7: Europe | M7: N | P7: N | X7: C | Y7: scope 1 and 2 emissions | Z7: climate neutral | AA7: C | AB7: 2045 | AC7: 2021 | AG7: U | AH7: 2024 | AI7: Y | AJ7: https://www.grupoacs.com/ficheros_editor/File/03_accionistas_inversores/06_junta_general_accionistas/2024/5%20Informaci%C3%B3n%20no%20financiera.pdf | AL7: https://www.grupoacs.com/sostenibilidad/estrategia-de-sostenibilidad/plan-director-sostenibilidad-2025/ | AN7: N | AQ7: N | BL7: 1 | BM7: 1 | BZ7: 1 | CB7: 1 | CE7: 1 | CH7: 1 | CQ7: Chemicals | CR7: =COUNTIFS($J$2:$J$501,CQ7,$S$2:$S$501,"<=2024") -> 0 | CS7: =COUNTIFS($J$2:$J$501,CQ7,$S$2:$S$501,">=2025",$S$2:$S$501,"<=2030") -> 2 | CT7: =COUNTIFS($J$2:$J$501,CQ7,$S$2:$S$501,">2030") -> 1 | CU7: =COUNTIFS($J$2:$J$501,CQ7,$O$2:$O$501,"<=2024") -> 0 | CV7: =COUNTIFS($J$2:$J$501,CQ7,$O$2:$O$501,">=2025",$O$2:$O$501,"<=2030") -> 0 | CW7: =COUNTIFS($J$2:$J$501,CQ7,$O$5:$O$504,">2030") -> 0 | CX7: =COUNTIFS($J$2:$J$501,CQ7,$AB$2:$AB$501,"<=2024") -> 0 | CY7: =COUNTIFS($J$2:$J$501,CQ7,$AB$2:$AB$501,">=2024",$AB$2:$AB$501,"<=2030") -> 1 | CZ7: =COUNTIFS($J$2:$J$501,CQ7,$AB$2:$AB$501,">2030") -> 4 | DA7: =COUNTIFS($J$2:$J$501,CQ7,$CM$2:$CM$501,"<=2024") -> 0 | DB7: =COUNTIFS($J$2:$J$501,CQ7,$CM$2:$CM$501,">=2025",$CM$2:$CM$501,"<=2030") -> 0 | DC7: =COUNTIFS($J$2:$J$501,CQ7,$CM$2:$CM$501,">2030") -> 3 | DD7: =SUM(CR7:DC7) -> 11 | DE7: =COUNTIFS($J$2:$J$501, CQ7, $CC$2:$CC$501, "1") -> 5 | DF7: =COUNTIFS($J$2:$J$501, CQ7, $CD$2:$CD$501, "1") -> 0 | DG7: =COUNTIF($J$2:$J$501, CQ7)-DF7-DE7 -> 5
A8: 203 | B8: AEON | C8: 189 | D8: =CONCATENATE((IF(BM8=1, "CN", "")),(IF(BQ8=1, " NZ", "")),(IF(BU8=1, " SBT", "")),(IF(BY8=1, " RE100", ""))) -> NZ SBT RE100 | E8: EC | F8: 45477 | G8: DT | H8: 312.2 | J8: Retail | K8: Japan | L8: Asia | M8: Y | N8: 2018 | O8: 2030 | P8: Y | Q8: Targets Set | R8: 1.5Â°C | S8: 2030 | T8: Yes | V8: 44409 | W8: 2021 | X8: N | AA8: N | AN8: C | AO8: our stores | AP8: Net Zero | AQ8: C | AR8: 2040 | AS8: 2021 | AW8: Y | AX8: https://ssl4.eir-parts.net/doc/8267/ir_material_for_fiscal_ym23/116815/00.pdf | AY8: 2023 | AZ8: Y | BA8: https://www.aeon-jreit.co.jp/en/sustainability/pdf/report/Sustainability_Report_all_e_2023_.pdf | BP8: 1 | BQ8: 1 | BS8: 1 | BU8: 1 | BW8: 1 | BY8: 1 | BZ8: 1 | CB8: 1 | CC8: 1 | CE8: 1 | CG8: 1 | CH8: 1 | CM8: =MAX(U8,AR8) -> 2040 | CQ8: Energy and utilities | CR8: =COUNTIFS($J$2:$J$501,CQ8,$S$2:$S$501,"<=2024") -> 1 | CS8: =COUNTIFS($J$2:$J$501,CQ8,$S$2:$S$501,">=2025",$S$2:$S$501,"<=2030") -> 5 | CT8: =COUNTIFS($J$2:$J$501,CQ8,$S$2:$S$501,">2030") -> 2 | CU8: =COUNTIFS($J$2:$J$501,CQ8,$O$2:$O$501,"<=2024") -> 0 | CV8: =COUNTIFS($J$2:$J$501,CQ8,$O$2:$O$501,">=2025",$O$2:$O$501,"<=2030") -> 0 | CW8: =COUNTIFS($J$2:$J$501,CQ8,$O$5:$O$504,">2030") -> 0 | CX8: =COUNTIFS($J$2:$J$501,CQ8,$AB$2:$AB$501,"<=2024") -> 1 | CY8: =COUNTIFS($J$2:$J$501,CQ8,$AB$2:$AB$501,">=2024",$AB$2:$AB$501,"<=2030") -> 2 | CZ8: =COUNTIFS($J$2:$J$501,CQ8,$AB$2:$AB$501,">2030") -> 12 | DA8: =COUNTIFS($J$2:$J$501,CQ8,$CM$2:$CM$501,"<=2024") -> 0 | DB8: =COUNTIFS($J$2:$J$501,CQ8,$CM$2:$CM$501,">=2025",$CM$2:$CM$501,"<=2030") -> 0 | DC8: =COUNTIFS($J$2:$J$501,CQ8,$CM$2:$CM$501,">2030") -> 8 | DD8: =SUM(CR8:DC8) -> 31 | DE8: =COUNTIFS($J$2:$J$501, CQ8, $CC$2:$CC$501, "1") -> 9 | DF8: =COUNTIFS($J$2:$J$501, CQ8, $CD$2:$CD$501, "1") -> 0 | DG8: =COUNTIF($J$2:$J$501, CQ8)-DF8-DE8 -> 13
A9: 34 | B9: Agricultural Bank of China | C9: 32 | D9: =CONCATENATE((IF(BM9=1, "CN", "")),(IF(BQ9=1, " NZ", "")),(IF(BU9=1, " SBT", "")),(IF(BY9=1, " RE100", ""))) | E9: EC | F9: 45474 | G9: DT | H9: 38048.7 | J9: Financial services | K9: China | L9: Asia | M9: N | P9: N | X9: G | Y9: operations | Z9: carbon neutrality | AA9: G | AB9: 2060 | AC9: 2023 | AL9: https://www.abchina.com/en/aboutus/csr-report/202403/P020240328668627319429.pdf | AN9: N | AQ9: N | BH9: they offset but don't specify why. Also have the Governement target - could put down as 2060 as per the gov target? | CQ9: Engineering and construction | CR9: =COUNTIFS($J$2:$J$501,CQ9,$S$2:$S$501,"<=2024") -> 0 | CS9: =COUNTIFS($J$2:$J$501,CQ9,$S$2:$S$501,">=2025",$S$2:$S$501,"<=2030") -> 3 | CT9: =COUNTIFS($J$2:$J$501,CQ9,$S$2:$S$501,">2030") -> 0 | CU9: =COUNTIFS($J$2:$J$501,CQ9,$O$2:$O$501,"<=2024") -> 1 | CV9: =COUNTIFS($J$2:$J$501,CQ9,$O$2:$O$501,">=2025",$O$2:$O$501,"<=2030") -> 0 | CW9: =COUNTIFS($J$2:$J$501,CQ9,$O$5:$O$504,">2030") -> 1 | CX9: =COUNTIFS($J$2:$J$501,CQ9,$AB$2:$AB$501,"<=2024") -> 0 | CY9: =COUNTIFS($J$2:$J$501,CQ9,$AB$2:$AB$501,">=2024",$AB$2:$AB$501,"<=2030") -> 0 | CZ9: =COUNTIFS($J$2:$J$501,CQ9,$AB$2:$AB$501,">2030") -> 8 | DA9: =COUNTIFS($J$2:$J$501,CQ9,$CM$2:$CM$501,"<=2024") -> 0 | DB9: =COUNTIFS($J$2:$J$501,CQ9,$CM$2:$CM$501,">=2025",$CM$2:$CM$501,"<=2030") -> 0 | DC9: =COUNTIFS($J$2:$J$501,CQ9,$CM$2:$CM$501,">2030") -> 1 | DD9: =SUM(CR9:DC9) -> 14 | DE9: =COUNTIFS($J$2:$J$501, CQ9, $CC$2:$CC$501, "1") -> 1 | DF9: =COUNTIFS($J$2:$J$501, CQ9, $CD$2:$CD$501, "1") -> 0 | DG9: =COUNTIF($J$2:$J$501, CQ9)-DF9-DE9 -> 17
A10: 446 | B10: AIA Group | D10: =CONCATENATE((IF(BM10=1, "CN", "")),(IF(BQ10=1, " NZ", "")),(IF(BU10=1, " SBT", "")),(IF(BY10=1, " RE100", ""))) -> NZ SBT | E10: AJ | F10: 45512 | H10: 3764 | I10: Insurance: Life, Health (stock) | J10: Financial services | K10: Hong Kong | L10: Asia | M10: N | P10: Y | Q10: Targets Set | R10: 1.5°C | S10: 2030 | T10: No | V10: 01/11/2023 | W10: 2023 | X10: N | AA10: N | AN10: C | AO10: company | AP10: Net Zero | AQ10: C | AR10: 2050 | AS10: 2021 | AW10: U | AX10: https://www.aia.com/content/dam/group-wise/en/docs/ESG/AIA_Group_ESG_Report_2023_Summary.pdf | AY10: 2023 | AZ10: Y | BA10: https://www.aia.com/content/dam/group-wise/en/docs/ESG/AIA_Group_ESG_Report_2023_Summary.pdf | BP10: 1 | BQ10: 1 | BS10: 1 | BU10: 1 | BZ10: 1 | CB10: 1 | CE10: 1 | CG10: 1 | CH10: 1 | CM10: =MAX(U10,AR10) -> 2050 | CQ10: Financial services | CR10: =COUNTIFS($J$2:$J$501,CQ10,$S$2:$S$501,"<=2024") -> 0 | CS10: =COUNTIFS($J$2:$J$501,CQ10,$S$2:$S$501,">=2025",$S$2:$S$501,"<=2030") -> 17 | CT10: =COUNTIFS($J$2:$J$501,CQ10,$S$2:$S$501,">2030") -> 1 | CU10: =COUNTIFS($J$2:$J$501,CQ10,$O$2:$O$501,"<=2024") -> 11 | CV10: =COUNTIFS($J$2:$J$501,CQ10,$O$2:$O$501,">=2025",$O$2:$O$501,"<=2030") -> 9 | CW10: =COUNTIFS($J$2:$J$501,CQ10,$O$5:$O$504,">2030") -> 2 | CX10: =COUNTIFS($J$2:$J$501,CQ10,$AB$2:$AB$501,"<=2024") -> 29 | CY10: =COUNTIFS($J$2:$J$501,CQ10,$AB$2:$AB$501,">=2024",$AB$2:$AB$501,"<=2030") -> 13 | CZ10: =COUNTIFS($J$2:$J$501,CQ10,$AB$2:$AB$501,">2030") -> 25 | DA10: =COUNTIFS($J$2:$J$501,CQ10,$CM$2:$CM$501,"<=2024") -> 0 | DB10: =COUNTIFS($J$2:$J$501,CQ10,$CM$2:$CM$501,">=2025",$CM$2:$CM$501,"<=2030") -> 15 | DC10: =COUNTIFS($J$2:$J$501,CQ10,$CM$2:$CM$501,">2030") -> 52 | DD10: =SUM(CR10:DC10) -> 174 | DE10: =COUNTIFS($J$2:$J$501, CQ10, $CC$2:$CC$501, "1") -> 67 | DF10: =COUNTIFS($J$2:$J$501, CQ10, $CD$2:$CD$501, "1") -> 2 | DG10: =COUNTIF($J$2:$J$501, CQ10)-DF10-DE10 -> 58
A11: 324 | B11: AIG | C11: 248 | D11: =CONCATENATE((IF(BM11=1, "CN", "")),(IF(BQ11=1, " NZ", "")),(IF(BU11=1, " SBT", "")),(IF(BY11=1, " RE100", ""))) -> NZ | E11: AJ | F11: 45477 | G11: AJ | H11: 3643 | J11: Financial services | K11: United States of America (USA) | L11: North America | M11: N | P11: N | X11: N | AA11: N | AN11: C+F | AO11: operations and underwriting and investments portfolios | AP11: Net Zero GHG emissions | AQ11: C+F | AR11: 2050 | AS11: 2022 | AW11: U | AX11: https://aig.gcs-web.com/node/53226/pdf | BF11: N | BP11: 1 | BQ11: 1 | BZ11: 1 | CB11: 1 | CE11: 1 | CH11: 1 | CK11: 1 | CL11: 1 | CM11: =MAX(U11,AR11) -> 2050 | CQ11: Food, beverages and agriculture | CR11: =COUNTIFS($J$2:$J$501,CQ11,$S$2:$S$501,"<=2024") -> 0 | CS11: =COUNTIFS($J$2:$J$501,CQ11,$S$2:$S$501,">=2025",$S$2:$S$501,"<=2030") -> 15 | CT11: =COUNTIFS($J$2:$J$501,CQ11,$S$2:$S$501,">2030") -> 1 | CU11: =COUNTIFS($J$2:$J$501,CQ11,$O$2:$O$501,"<=2024") -> 1 | CV11: =COUNTIFS($J$2:$J$501,CQ11,$O$2:$O$501,">=2025",$O$2:$O$501,"<=2030") -> 3 | CW11: =COUNTIFS($J$2:$J$501,CQ11,$O$5:$O$504,">2030") -> 2 | CX11: =COUNTIFS($J$2:$J$501,CQ11,$AB$2:$AB$501,"<=2024") -> 0 | CY11: =COUNTIFS($J$2:$J$501,CQ11,$AB$2:$AB$501,">=2024",$AB$2:$AB$501,"<=2030") -> 3 | CZ11: =COUNTIFS($J$2:$J$501,CQ11,$AB$2:$AB$501,">2030") -> 0 | DA11: =COUNTIFS($J$2:$J$501,CQ11,$CM$2:$CM$501,"<=2024") -> 0 | DB11: =COUNTIFS($J$2:$J$501,CQ11,$CM$2:$CM$501,">=2025",$CM$2:$CM$501,"<=2030") -> 0 | DC11: =COUNTIFS($J$2:$J$501,CQ11,$CM$2:$CM$501,">2030") -> 13 | DD11: =SUM(CR11:DC11) -> 38 | DE11: =COUNTIFS($J$2:$J$501, CQ11, $CC$2:$CC$501, "1") -> 8 | DF11: =COUNTIFS($J$2:$J$501, CQ11, $CD$2:$CD$501, "1") -> 0 | DG11: =COUNTIF($J$2:$J$501, CQ11)-DF11-DE11 -> 13
A12: 496 | B12: Air France-KLM Group | D12: =CONCATENATE((IF(BM12=1, "CN", "")),(IF(BQ12=1, " NZ", "")),(IF(BU12=1, " SBT", "")),(IF(BY12=1, " RE100", ""))) -> NZ SBT | E12: AJ | F12: 45512 | H12: 1009.7 | I12: Airlines | J12: Transportation and logistics | K12: France | L12: Europe | M12: N | P12: Y | Q12: Targets Set | R12: Well-below 2°C | S12: 2030 | T12: No | V12: 01/01/2023 | W12: 2023 | X12: N | AA12: N | AN12: C | AO12: activities | AP12: Net Zero | AQ12: C | AR12: 2050 | AS12: 2021 | AW12: U | AX12: https://www.airfranceklm.com/en/our-commitments | AY12: 2022 | AZ12: Y | BA12: https://sustainabilityreport.airfranceklm.com/sustainability-report-2022-en/ | BP12: 1 | BQ12: 1 | BS12: 1 | BU12: 1 | BZ12: 1 | CB12: 1 | CE12: 1 | CG12: 1 | CH12: 1 | CM12: =MAX(U12,AR12) -> 2050 | CQ12: Health care and pharmaceuticals | CR12: =COUNTIFS($J$2:$J$501,CQ12,$S$2:$S$501,"<=2024") -> 0 | CS12: =COUNTIFS($J$2:$J$501,CQ12,$S$2:$S$501,">=2025",$S$2:$S$501,"<=2030") -> 15 | CT12: =COUNTIFS($J$2:$J$501,CQ12,$S$2:$S$501,">2030") -> 1 | CU12: =COUNTIFS($J$2:$J$501,CQ12,$O$2:$O$501,"<=2024") -> 1 | CV12: =COUNTIFS($J$2:$J$501,CQ12,$O$2:$O$501,">=2025",$O$2:$O$501,"<=2030") -> 8 | CW12: =COUNTIFS($J$2:$J$501,CQ12,$O$5:$O$504,">2030") -> 2 | CX12: =COUNTIFS($J$2:$J$501,CQ12,$AB$2:$AB$501,"<=2024") -> 1 | CY12: =COUNTIFS($J$2:$J$501,CQ12,$AB$2:$AB$501,">=2024",$AB$2:$AB$501,"<=2030") -> 8 | CZ12: =COUNTIFS($J$2:$J$501,CQ12,$AB$2:$AB$501,">2030") -> 3 | DA12: =COUNTIFS($J$2:$J$501,CQ12,$CM$2:$CM$501,"<=2024") -> 0 | DB12: =COUNTIFS($J$2:$J$501,CQ12,$CM$2:$CM$501,">=2025",$CM$2:$CM$501,"<=2030") -> 1 | DC12: =COUNTIFS($J$2:$J$501,CQ12,$CM$2:$CM$501,">2030") -> 14 | DD12: =SUM(CR12:DC12) -> 54 | DE12: =COUNTIFS($J$2:$J$501, CQ12, $CC$2:$CC$501, "1") -> 12 | DF12: =COUNTIFS($J$2:$J$501, CQ12, $CD$2:$CD$501, "1") -> 1 | DG12: =COUNTIF($J$2:$J$501, CQ12)-DF12-DE12 -> 12
A13: 183 | B13: Airbus | C13: 219 | D13: =CONCATENATE((IF(BM13=1, "CN", "")),(IF(BQ13=1, " NZ", "")),(IF(BU13=1, " SBT", "")),(IF(BY13=1, " RE100", ""))) -> NZ SBT | E13: DT - AJ | F13: 45477 | G13: DT | H13: 4096.1 | J13: Aerospace and defense | K13: Netherlands | L13: Europe | M13: N | P13: Y | Q13: Targets Set | R13: 1.5Â°C | S13: 2030 | T13: No | V13: 44958 | W13: 2023 | X13: N | AA13: N | AN13: C | AO13: undefined | AP13: Net Zero | AQ13: C | AR13: 2050 | AS13: 2020 | AW13: Y | AX13: https://www.airbus.com/en/sustainability/respecting-the-planet/decarbonisation | BP13: 1 | BQ13: 1 | BS13: 1 | BU13: 1 | BZ13: 1 | CB13: 1 | CC13: 1 | CE13: 1 | CG13: 1 | CH13: 1 | CM13: =MAX(U13,AR13) -> 2050 | CQ13: Household and personal products | CR13: =COUNTIFS($J$2:$J$501,CQ13,$S$2:$S$501,"<=2024") -> 0 | CS13: =COUNTIFS($J$2:$J$501,CQ13,$S$2:$S$501,">=2025",$S$2:$S$501,"<=2030") -> 4 | CT13: =COUNTIFS($J$2:$J$501,CQ13,$S$2:$S$501,">2030") -> 0 | CU13: =COUNTIFS($J$2:$J$501,CQ13,$O$2:$O$501,"<=2024") -> 0 | CV13: =COUNTIFS($J$2:$J$501,CQ13,$O$2:$O$501,">=2025",$O$2:$O$501,"<=2030") -> 3 | CW13: =COUNTIFS($J$2:$J$501,CQ13,$O$5:$O$504,">2030") -> 0 | CX13: =COUNTIFS($J$2:$J$501,CQ13,$AB$2:$AB$501,"<=2024") -> 1 | CY13: =COUNTIFS($J$2:$J$501,CQ13,$AB$2:$AB$501,">=2024",$AB$2:$AB$501,"<=2030") -> 1 | CZ13: =COUNTIFS($J$2:$J$501,CQ13,$AB$2:$AB$501,">2030") -> 0 | DA13: =COUNTIFS($J$2:$J$501,CQ13,$CM$2:$CM$501,"<=2024") -> 0 | DB13: =COUNTIFS($J$2:$J$501,CQ13,$CM$2:$CM$501,">=2025",$CM$2:$CM$501,"<=2030") -> 0 | DC13: =COUNTIFS($J$2:$J$501,CQ13,$CM$2:$CM$501,">2030") -> 5 | DD13: =SUM(CR13:DC13) -> 14 | DE13: =COUNTIFS($J$2:$J$501, CQ13, $CC$2:$CC$501, "1") -> 2 | DF13: =COUNTIFS($J$2:$J$501, CQ13, $CD$2:$CD$501, "1") -> 2 | DG13: =COUNTIF($J$2:$J$501, CQ13)-DF13-DE13 -> 3
A14: 462 | B14: Aisin | C14: 470 | D14: =CONCATENATE((IF(BM14=1, "CN", "")),(IF(BQ14=1, " NZ", "")),(IF(BU14=1, " SBT", "")),(IF(BY14=1, " RE100", ""))) -> CN SBT | E14: DT * | F14: 45511 | G14: DT | H14: 628.3 | J14: Automotive | K14: Japan | L14: Asia | M14: N | P14: Y | Q14: Targets Set | R14: 1.5Â°C | S14: 2031 | T14: No | V14: 45261 | W14: 2023 | X14: C | Y14: products and production | Z14: Carbon Neutrality | AA14: C | AB14: 2035 | AC14: 2021 | AG14: Y | AH14: 2023 | AI14: Y | AJ14: https://www.aisin.com/en/sustainability/report/pdf/aisin_ar2023_en_a3.pdf | AL14: https://www.aisin.com/en/sustainability/report/pdf/aisin_ar2022_en_a3.pdf | AN14: N | AQ14: N | BL14: 1 | BM14: 1 | BT14: 1 | BU14: 1 | BZ14: 1 | CB14: 1 | CC14: 1 | CE14: 1 | CH14: 1 | CQ14: Industrial goods | CR14: =COUNTIFS($J$2:$J$501,CQ14,$S$2:$S$501,"<=2024") -> 0 | CS14: =COUNTIFS($J$2:$J$501,CQ14,$S$2:$S$501,">=2025",$S$2:$S$501,"<=2030") -> 16 | CT14: =COUNTIFS($J$2:$J$501,CQ14,$S$2:$S$501,">2030") -> 2 | CU14: =COUNTIFS($J$2:$J$501,CQ14,$O$2:$O$501,"<=2024") -> 0 | CV14: =COUNTIFS($J$2:$J$501,CQ14,$O$2:$O$501,">=2025",$O$2:$O$501,"<=2030") -> 5 | CW14: =COUNTIFS($J$2:$J$501,CQ14,$O$5:$O$504,">2030") -> 2 | CX14: =COUNTIFS($J$2:$J$501,CQ14,$AB$2:$AB$501,"<=2024") -> 0 | CY14: =COUNTIFS($J$2:$J$501,CQ14,$AB$2:$AB$501,">=2024",$AB$2:$AB$501,"<=2030") -> 5 | CZ14: =COUNTIFS($J$2:$J$501,CQ14,$AB$2:$AB$501,">2030") -> 7 | DA14: =COUNTIFS($J$2:$J$501,CQ14,$CM$2:$CM$501,"<=2024") -> 0 | DB14: =COUNTIFS($J$2:$J$501,CQ14,$CM$2:$CM$501,">=2025",$CM$2:$CM$501,"<=2030") -> 2 | DC14: =COUNTIFS($J$2:$J$501,CQ14,$CM$2:$CM$501,">2030") -> 18 | DD14: =SUM(CR14:DC14) -> 57 | DE14: =COUNTIFS($J$2:$J$501, CQ14, $CC$2:$CC$501, "1") -> 13 | DF14: =COUNTIFS($J$2:$J$501, CQ14, $CD$2:$CD$501, "1") -> 0 | DG14: =COUNTIF($J$2:$J$501, CQ14)-DF14-DE14 -> 21
A15: 152 | B15: Albertsons | C15: 164 | D15: =CONCATENATE((IF(BM15=1, "CN", "")),(IF(BQ15=1, " NZ", "")),(IF(BU15=1, " SBT", "")),(IF(BY15=1, " RE100", ""))) -> NZ SBT | E15: DT | F15: 45476 | G15: AJ | H15: 1296 | J15: Retail | K15: United States of America (USA) | L15: North America | M15: N | P15: Y | Q15: Targets Set | R15: 1.5Â°C | S15: 2030 | T15: No | V15: 44652 | W15: 2022 | X15: N | AA15: N | AN15: C | AO15: Scope 1 and 2 | AP15: Net Zero | AQ15: C | AR15: 2040 | AS15: 2022 | AW15: Y | AX15: https://s29.q4cdn.com/239956855/files/our_impact/sustainability_doc/albcdacsiv199540_aci_23_esg-report-1-2.pdf| https://www.supermarketnews.com/sustainability/albertsons-unveils-recipe-change-esg-platform | BC15: We work with energy providers in our operating areas to purchase utility-scale renewable energy and renewable energy credits. | BP15: 1 | BQ15: 1 | BS15: 1 | BU15: 1 | BZ15: 1 | CB15: 1 | CC15: 1 | CE15: 1 | CG15: 1 | CH15: 1 | CM15: =MAX(U15,AR15) -> 2040 | CQ15: Metals and mining | CR15: =COUNTIFS($J$2:$J$501,CQ15,$S$2:$S$501,"<=2024") -> 0 | CS15: =COUNTIFS($J$2:$J$501,CQ15,$S$2:$S$501,">=2025",$S$2:$S$501,"<=2030") -> 1 | CT15: =COUNTIFS($J$2:$J$501,CQ15,$S$2:$S$501,">2030") -> 0 | CU15: =COUNTIFS($J$2:$J$501,CQ15,$O$2:$O$501,"<=2024") -> 0 | CV15: =COUNTIFS($J$2:$J$501,CQ15,$O$2:$O$501,">=2025",$O$2:$O$501,"<=2030") -> 0 | CW15: =COUNTIFS($J$2:$J$501,CQ15,$O$5:$O$504,">2030") -> 1 | CX15: =COUNTIFS($J$2:$J$501,CQ15,$AB$2:$AB$501,"<=2024") -> 0 | CY15: =COUNTIFS($J$2:$J$501,CQ15,$AB$2:$AB$501,">=2024",$AB$2:$AB$501,"<=2030") -> 0 | CZ15: =COUNTIFS($J$2:$J$501,CQ15,$AB$2:$AB$501,">2030") -> 19 | DA15: =COUNTIFS($J$2:$J$501,CQ15,$CM$2:$CM$501,"<=2024") -> 0 | DB15: =COUNTIFS($J$2:$J$501,CQ15,$CM$2:$CM$501,">=2025",$CM$2:$CM$501,"<=2030") -> 0 | DC15: =COUNTIFS($J$2:$J$501,CQ15,$CM$2:$CM$501,">2030") -> 10 | DD15: =SUM(CR15:DC15) -> 31 | DE15: =COUNTIFS($J$2:$J$501, CQ15, $CC$2:$CC$501, "1") -> 9 | DF15: =COUNTIFS($J$2:$J$501, CQ15, $CD$2:$CD$501, "1") -> 0 | DG15: =COUNTIF($J$2:$J$501, CQ15)-DF15-DE15 -> 31
A16: 70 | B16: Alibaba Group Holding | C16: 68 | D16: =CONCATENATE((IF(BM16=1, "CN", "")),(IF(BQ16=1, " NZ", "")),(IF(BU16=1, " SBT", "")),(IF(BY16=1, " RE100", ""))) -> CN SBT | E16: DT - AJ | F16: 45475 | G16: DT | H16: 11165.1 | J16: Retail | K16: China | L16: Asia | M16: N | P16: N | Q16: Committed | S16: 2030 | T16: Yes | V16: 44531 | W16: 2021 | X16: C | Y16: operations | Z16: carbon neutrality | AA16: C | AB16: 2030 | AC16: 2021 | AG16: Y | AH16: 2023 | AI16: Y | AJ16: https://data.alibabagroup.com/ecms-files/1509739361/fcaefa3d-0989-48fb-b003-fa96aa04880e/2023%20Alibaba%20ESG%20Report-Final.pdf | AL16: https://data.alibabagroup.com/ecms-files/1509739361/fcaefa3d-0989-48fb-b003-fa96aa04880e/2023%20Alibaba%20ESG%20Report-Final.pdf | AM16: In 2021, Alibaba set ambitious targets of achieving carbon neutrality in our own operations and halving the energy intensity across our value chain by 2030 and driving emission reduction of 1.5 gigatons over 15 years in our platform ecosystem s. Combining these efforts with our projects on carbon removal and carbon offsets, we have achieved a year-over-year decrease of 5.7%1 of our carbon intensity throughout the value chain | AN16: N | AQ16: N | BK16: 1 | BM16: 1 | BS16: 1 | BU16: 1 | BZ16: 1 | CA16: 1 | CB16: 1 | CC16: 1 | CE16: 1 | CG16: 1 | CH16: 1 | CQ16: Oil and gas | CR16: =COUNTIFS($J$2:$J$501,CQ16,$S$2:$S$501,"<=2024") -> 0 | CS16: =COUNTIFS($J$2:$J$501,CQ16,$S$2:$S$501,">=2025",$S$2:$S$501,"<=2030") -> 0 | CT16: =COUNTIFS($J$2:$J$501,CQ16,$S$2:$S$501,">2030") -> 0 | CU16: =COUNTIFS($J$2:$J$501,CQ16,$O$2:$O$501,"<=2024") -> 0 | CV16: =COUNTIFS($J$2:$J$501,CQ16,$O$2:$O$501,">=2025",$O$2:$O$501,"<=2030") -> 0 | CW16: =COUNTIFS($J$2:$J$501,CQ16,$O$5:$O$504,">2030") -> 3 | CX16: =COUNTIFS($J$2:$J$501,CQ16,$AB$2:$AB$501,"<=2024") -> 0 | CY16: =COUNTIFS($J$2:$J$501,CQ16,$AB$2:$AB$501,">=2024",$AB$2:$AB$501,"<=2030") -> 3 | CZ16: =COUNTIFS($J$2:$J$501,CQ16,$AB$2:$AB$501,">2030") -> 12 | DA16: =COUNTIFS($J$2:$J$501,CQ16,$CM$2:$CM$501,"<=2024") -> 0 | DB16: =COUNTIFS($J$2:$J$501,CQ16,$CM$2:$CM$501,">=2025",$CM$2:$CM$501,"<=2030") -> 0 | DC16: =COUNTIFS($J$2:$J$501,CQ16,$CM$2:$CM$501,">2030") -> 20 | DD16: =SUM(CR16:DC16) -> 38 | DE16: =COUNTIFS($J$2:$J$501, CQ16, $CC$2:$CC$501, "1") -> 22 | DF16: =COUNTIFS($J$2:$J$501, CQ16, $CD$2:$CD$501, "1") -> 0 | DG16: =COUNTIF($J$2:$J$501, CQ16)-DF16-DE16 -> 21
A17: 177 | B17: Alimentation Couche-Tard | C17: 214 | D17: =CONCATENATE((IF(BM17=1, "CN", "")),(IF(BQ17=1, " NZ", "")),(IF(BU17=1, " SBT", "")),(IF(BY17=1, " RE100", ""))) -> CN | E17: AJ | F17: 45476 | G17: DT | H17: 3090.9 | J17: Retail | K17: Canada | L17: North America | M17: N | P17: N | X17: C | Y17: scope 1 and 2 | Z17: carbon neutral | AA17: C | AB17: 2030 | AC17: 2024 | AG17: Y | AH17: 2024 | AI17: Y | AJ17: https://corpo.couche-tard.com/wp-content/uploads/2024/06/ACT_Sustainability_Report_2024.pdf | AL17: https://corpo.couche-tard.com/wp-content/uploads/2024/06/ACT_Sustainability_Report_2024.pdf | AN17: N | AQ17: N | BD17: Y | BE17: https://corpo.couche-tard.com/wp-content/uploads/2024/06/ACT_Sustainability_Report_2024.pdf | BF17: N | BI17: BAD: we aim to reduce our Scope 1 and 2Â emissions by 50%, using a range of solution including carbon credits if needed. | BK17: 1 | BM17: 1 | BZ17: 1 | CA17: 1 | CB17: 1 | CC17: 1 | CE17: 1 | CG17: 1 | CH17: 1 | CQ17: Real estate | CR17: =COUNTIFS($J$2:$J$501,CQ17,$S$2:$S$501,"<=2024") -> 0 | CS17: =COUNTIFS($J$2:$J$501,CQ17,$S$2:$S$501,">=2025",$S$2:$S$501,"<=2030") -> 0 | CT17: =COUNTIFS($J$2:$J$501,CQ17,$S$2:$S$501,">2030") -> 0 | CU17: =COUNTIFS($J$2:$J$501,CQ17,$O$2:$O$501,"<=2024") -> 0 | CV17: =COUNTIFS($J$2:$J$501,CQ17,$O$2:$O$501,">=2025",$O$2:$O$501,"<=2030") -> 0 | CW17: =COUNTIFS($J$2:$J$501,CQ17,$O$5:$O$504,">2030") -> 0 | CX17: =COUNTIFS($J$2:$J$501,CQ17,$AB$2:$AB$501,"<=2024") -> 0 | CY17: =COUNTIFS($J$2:$J$501,CQ17,$AB$2:$AB$501,">=2024",$AB$2:$AB$501,"<=2030") -> 0 | CZ17: =COUNTIFS($J$2:$J$501,CQ17,$AB$2:$AB$501,">2030") -> 2 | DA17: =COUNTIFS($J$2:$J$501,CQ17,$CM$2:$CM$501,"<=2024") -> 0 | DB17: =COUNTIFS($J$2:$J$501,CQ17,$CM$2:$CM$501,">=2025",$CM$2:$CM$501,"<=2030") -> 0 | DC17: =COUNTIFS($J$2:$J$501,CQ17,$CM$2:$CM$501,">2030") -> 0 | DD17: =SUM(CR17:DC17) -> 2 | DE17: =COUNTIFS($J$2:$J$501, CQ17, $CC$2:$CC$501, "1") -> 0 | DF17: =COUNTIFS($J$2:$J$501, CQ17, $CD$2:$CD$501, "1") -> 0 | DG17: =COUNTIF($J$2:$J$501, CQ17)-DF17-DE17 -> 3
A18: 82 | B18: Allianz | C18: 67 | D18: =CONCATENATE((IF(BM18=1, "CN", "")),(IF(BQ18=1, " NZ", "")),(IF(BU18=1, " SBT", "")),(IF(BY18=1, " RE100", ""))) -> CN NZ RE100 | E18: DT | F18: 45475 | G18: DT | H18: 9233.3 | J18: Financial services | K18: Germany | L18: Europe | M18: Y | N18: 2018 | O18: 2023 | P18: N | X18: C | Y18: operations | Z18: carbon neutral | AA18: C | AB18: 2012 | AC18: 2019 | AG18: Y | AH18: 2022 | AI18: Y | AJ18: https://www.allianz.com/content/dam/onemarketing/azcom/Allianz_com/sustainability/documents/Allianz_Group_Sustainability_Report_2022-web.pdf | AL18: https://www.allianz.com/content/dam/onemarketing/azcom/Allianz_com/sustainability/documents/Allianz_Group_Sustainability_Report_2022-web.pdf | AN18: F | AO18: Investment Portfolio | AP18: Net Zero | AQ18: F | AR18: 2050 | AS18: 2020 | AW18: R | AX18: https://www.allianz.com/content/dam/onemarketing/azcom/Allianz_com/sustainability/documents/Allianz_Group_Sustainability_Report_2023-web.pdf | BC18: ith the publication of our first comprehensive net-zero transition plan in 2023, we further detailed our commitment to achieve net-zero emissions by 2050, covering proprietary investments and, for the first time, our P&C insurance business The (1) Net Zero 2050 scenario is determined by an orderly transition to net-zero emissions by 2050 following the target to limit global warming to 1.5Â°C through stringent climate policies at the cost of moderate economic strain in the initial years. | BJ18: 1 | BM18: 1 | BP18: 1 | BQ18: 1 | BV18: 1 | BY18: 1 | BZ18: 1 | CA18: 1 | CB18: 1 | CC18: 1 | CE18: 1 | CF18: 1 | CG18: 1 | CH18: 1 | CK18: 1 | CL18: 1 | CM18: =MAX(U18,AR18) -> 2050 | CQ18: Retail | CR18: =COUNTIFS($J$2:$J$501,CQ18,$S$2:$S$501,"<=2024") -> 1 | CS18: =COUNTIFS($J$2:$J$501,CQ18,$S$2:$S$501,">=2025",$S$2:$S$501,"<=2030") -> 24 | CT18: =COUNTIFS($J$2:$J$501,CQ18,$S$2:$S$501,">2030") -> 3 | CU18: =COUNTIFS($J$2:$J$501,CQ18,$O$2:$O$501,"<=2024") -> 0 | CV18: =COUNTIFS($J$2:$J$501,CQ18,$O$2:$O$501,">=2025",$O$2:$O$501,"<=2030") -> 6 | CW18: =COUNTIFS($J$2:$J$501,CQ18,$O$5:$O$504,">2030") -> 1 | CX18: =COUNTIFS($J$2:$J$501,CQ18,$AB$2:$AB$501,"<=2024") -> 1 | CY18: =COUNTIFS($J$2:$J$501,CQ18,$AB$2:$AB$501,">=2024",$AB$2:$AB$501,"<=2030") -> 3 | CZ18: =COUNTIFS($J$2:$J$501,CQ18,$AB$2:$AB$501,">2030") -> 6 | DA18: =COUNTIFS($J$2:$J$501,CQ18,$CM$2:$CM$501,"<=2024") -> 0 | DB18: =COUNTIFS($J$2:$J$501,CQ18,$CM$2:$CM$501,">=2025",$CM$2:$CM$501,"<=2030") -> 0 | DC18: =COUNTIFS($J$2:$J$501,CQ18,$CM$2:$CM$501,">2030") -> 25 | DD18: =SUM(CR18:DC18) -> 70 | DE18: =COUNTIFS($J$2:$J$501, CQ18, $CC$2:$CC$501, "1") -> 15 | DF18: =COUNTIFS($J$2:$J$501, CQ18, $CD$2:$CD$501, "1") -> 2 | DG18: =COUNTIF($J$2:$J$501, CQ18)-DF18-DE18 -> 29
A19: 244 | B19: Allstate | C19: 276 | D19: =CONCATENATE((IF(BM19=1, "CN", "")),(IF(BQ19=1, " NZ", "")),(IF(BU19=1, " SBT", "")),(IF(BY19=1, " RE100", ""))) -> NZ | E19: EC | F19: 45477 | G19: AJ | H19: -188 | J19: Financial services | K19: United States of America (USA) | L19: North America | M19: N | P19: N | X19: N | AA19: N | AN19: C | AO19: Scope 1 and 2 emissions | AP19: Net Zero | AQ19: C | AR19: 2030 | AS19: 2022 | AW19: U | AX19: https://delivery.contenthub.allstate.com/api/public/content/2023-sustainability-report?v=67b36ebf | BC19: https://delivery.contenthub.allstate.com/api/public/content/4860fd4e881a42899a718e0db304a33e?v=878016db#:~:text=In%20December%202022%2C%20Allstate%20announced,a%20goal%20for%20financed%20emissions. | BO19: 1 | BQ19: 1 | BZ19: 1 | CA19: 1 | CB19: 1 | CE19: 1 | CG19: 1 | CH19: 1 | CM19: =MAX(U19,AR19) -> 2030 | CQ19: Technology | CR19: =COUNTIFS($J$2:$J$501,CQ19,$S$2:$S$501,"<=2024") -> 1 | CS19: =COUNTIFS($J$2:$J$501,CQ19,$S$2:$S$501,">=2025",$S$2:$S$501,"<=2030") -> 10 | CT19: =COUNTIFS($J$2:$J$501,CQ19,$S$2:$S$501,">2030") -> 3 | CU19: =COUNTIFS($J$2:$J$501,CQ19,$O$2:$O$501,"<=2024") -> 4 | CV19: =COUNTIFS($J$2:$J$501,CQ19,$O$2:$O$501,">=2025",$O$2:$O$501,"<=2030") -> 1 | CW19: =COUNTIFS($J$2:$J$501,CQ19,$O$5:$O$504,">2030") -> 0 | CX19: =COUNTIFS($J$2:$J$501,CQ19,$AB$2:$AB$501,"<=2024") -> 3 | CY19: =COUNTIFS($J$2:$J$501,CQ19,$AB$2:$AB$501,">=2024",$AB$2:$AB$501,"<=2030") -> 2 | CZ19: =COUNTIFS($J$2:$J$501,CQ19,$AB$2:$AB$501,">2030") -> 2 | DA19: =COUNTIFS($J$2:$J$501,CQ19,$CM$2:$CM$501,"<=2024") -> 2 | DB19: =COUNTIFS($J$2:$J$501,CQ19,$CM$2:$CM$501,">=2025",$CM$2:$CM$501,"<=2030") -> 3 | DC19: =COUNTIFS($J$2:$J$501,CQ19,$CM$2:$CM$501,">2030") -> 5 | DD19: =SUM(CR19:DC19) -> 36 | DE19: =COUNTIFS($J$2:$J$501, CQ19, $CC$2:$CC$501, "1") -> 11 | DF19: =COUNTIFS($J$2:$J$501, CQ19, $CD$2:$CD$501, "1") -> 0 | DG19: =COUNTIF($J$2:$J$501, CQ19)-DF19-DE19 -> 6
A20: 17 | B20: Alphabet | C20: 17 | D20: =CONCATENATE((IF(BM20=1, "CN", "")),(IF(BQ20=1, " NZ", "")),(IF(BU20=1, " SBT", "")),(IF(BY20=1, " RE100", ""))) -> NZ SBT | E20: DT | F20: 45475 | G20: AJ | H20: 73795 | J20: Technology | K20: United States of America (USA) | L20: North America | M20: N | P20: N | Q20: Committed | S20: 2030 | T20: No | V20: 44805 | W20: 2022 | X20: N | AA20: N | AN20: V | AO20: operations and value chain | AP20: Net Zero | AQ20: V | AR20: 2030 | AS20: 2020 | AW20: Y | AX20: https://www.gstatic.com/gumdrop/sustainability/google-2023-environmental-report.pdf | AY20: 2024 | AZ20: Y | BA20: https://www.gstatic.com/gumdrop/sustainability/google-2024-environmental-report.pdf | BC20: Our operational emissions are then further compensated for by high-quality carbon credits enabled through contracted carbon offset projects, which capture and destroy highly potent GHGs. Our operational emissions are then further compensated for by high-quality carbon credits enabled through contracted carbon offset projects, which capture and destroy highly potent GHGs. | BO20: 1 | BQ20: 1 | BS20: 1 | BU20: 1 | BZ20: 1 | CB20: 1 | CC20: 1 | CE20: 1 | CG20: 1 | CH20: 1 | CJ20: 1 | CL20: 1 | CM20: =MAX(U20,AR20) -> 2030 | CQ20: Telecommunications and media | CR20: =COUNTIFS($J$2:$J$501,CQ20,$S$2:$S$501,"<=2024") -> 1 | CS20: =COUNTIFS($J$2:$J$501,CQ20,$S$2:$S$501,">=2025",$S$2:$S$501,"<=2030") -> 11 | CT20: =COUNTIFS($J$2:$J$501,CQ20,$S$2:$S$501,">2030") -> 1 | CU20: =COUNTIFS($J$2:$J$501,CQ20,$O$2:$O$501,"<=2024") -> 1 | CV20: =COUNTIFS($J$2:$J$501,CQ20,$O$2:$O$501,">=2025",$O$2:$O$501,"<=2030") -> 4 | CW20: =COUNTIFS($J$2:$J$501,CQ20,$O$5:$O$504,">2030") -> 2 | CX20: =COUNTIFS($J$2:$J$501,CQ20,$AB$2:$AB$501,"<=2024") -> 0 | CY20: =COUNTIFS($J$2:$J$501,CQ20,$AB$2:$AB$501,">=2024",$AB$2:$AB$501,"<=2030") -> 3 | CZ20: =COUNTIFS($J$2:$J$501,CQ20,$AB$2:$AB$501,">2030") -> 8 | DA20: =COUNTIFS($J$2:$J$501,CQ20,$CM$2:$CM$501,"<=2024") -> 1 | DB20: =COUNTIFS($J$2:$J$501,CQ20,$CM$2:$CM$501,">=2025",$CM$2:$CM$501,"<=2030") -> 1 | DC20: =COUNTIFS($J$2:$J$501,CQ20,$CM$2:$CM$501,">2030") -> 7 | DD20: =SUM(CR20:DC20) -> 40 | DE20: =COUNTIFS($J$2:$J$501, CQ20, $CC$2:$CC$501, "1") -> 8 | DF20: =COUNTIFS($J$2:$J$501, CQ20, $CD$2:$CD$501, "1") -> 0 | DG20: =COUNTIF($J$2:$J$501, CQ20)-DF20-DE20 -> 12
A21: 214 | B21: Aluminum Corp. of China | C21: 166 | D21: =CONCATENATE((IF(BM21=1, "CN", "")),(IF(BQ21=1, " NZ", "")),(IF(BU21=1, " SBT", "")),(IF(BY21=1, " RE100", ""))) | E21: DT | F21: 45476 | G21: AJ | H21: 876.5 | J21: Metals and mining | K21: China | L21: Asia | M21: N | P21: N | X21: G | Y21: Scope 1 and 2 | Z21: Carbon Neutrality | AA21: G | AB21: 2060 | AC21: 2021 | AL21: https://www.chalco.com.cn/en/tzzgxen/tzggen/202203/P020220323614314766465.pdf | AM21: refers to the statement made by General Secretary Xi Jinping at the General Debate of the 75th session of the UN General Assembly that â€œChina will scale up its Intended Nationally Determined Contributions (INDCs) by adopting more vigorous policies and measures and aim to have CO2 emissions peak before 2030 and achieve carbon neutrality before 2060â€ | AN21: N | AQ21: N | CQ21: Transportation and logistics | CR21: =COUNTIFS($J$2:$J$501,CQ21,$S$2:$S$501,"<=2024") -> 0 | CS21: =COUNTIFS($J$2:$J$501,CQ21,$S$2:$S$501,">=2025",$S$2:$S$501,"<=2030") -> 8 | CT21: =COUNTIFS($J$2:$J$501,CQ21,$S$2:$S$501,">2030") -> 3 | CU21: =COUNTIFS($J$2:$J$501,CQ21,$O$2:$O$501,"<=2024") -> 0 | CV21: =COUNTIFS($J$2:$J$501,CQ21,$O$2:$O$501,">=2025",$O$2:$O$501,"<=2030") -> 0 | CW21: =COUNTIFS($J$2:$J$501,CQ21,$O$5:$O$504,">2030") -> 0 | CX21: =COUNTIFS($J$2:$J$501,CQ21,$AB$2:$AB$501,"<=2024") -> 1 | CY21: =COUNTIFS($J$2:$J$501,CQ21,$AB$2:$AB$501,">=2024",$AB$2:$AB$501,"<=2030") -> 0 | CZ21: =COUNTIFS($J$2:$J$501,CQ21,$AB$2:$AB$501,">2030") -> 8 | DA21: =COUNTIFS($J$2:$J$501,CQ21,$CM$2:$CM$501,"<=2024") -> 0 | DB21: =COUNTIFS($J$2:$J$501,CQ21,$CM$2:$CM$501,">=2025",$CM$2:$CM$501,"<=2030") -> 0 | DC21: =COUNTIFS($J$2:$J$501,CQ21,$CM$2:$CM$501,">2030") -> 9 | DD21: =SUM(CR21:DC21) -> 29 | DE21: =COUNTIFS($J$2:$J$501, CQ21, $CC$2:$CC$501, "1") -> 5 | DF21: =COUNTIFS($J$2:$J$501, CQ21, $CD$2:$CD$501, "1") -> 1 | DG21: =COUNTIF($J$2:$J$501, CQ21)-DF21-DE21 -> 14
A22: 2 | B22: Amazon | C22: 4 | D22: =CONCATENATE((IF(BM22=1, "CN", "")),(IF(BQ22=1, " NZ", "")),(IF(BU22=1, " SBT", "")),(IF(BY22=1, " RE100", ""))) -> NZ | E22: DT | F22: 45474 | G22: AJ | H22: 30425 | J22: Retail | K22: United States of America (USA) | L22: North America | M22: N | P22: N | Q22: Removed | T22: No | V22: 43983 | W22: 2020 | X22: N | AA22: N | AN22: C | AO22: Scope 1 and 2 | AP22: Net Zero | AQ22: C | AR22: 2040 | AS22: 2019 | AW22: Y | AX22: https://sustainability.aboutamazon.com/2022-sustainability-report.pdf https://s3.amazonaws.com/sustainabledevelopment.report/2023/sustainable-development-report-2023.pdf | AY22: 2023 | AZ22: Y | BA22: https://sustainability.aboutamazon.com/2023-sustainability-report.pdf | BP22: 1 | BQ22: 1 | BZ22: 1 | CB22: 1 | CC22: 1 | CE22: 1 | CH22: 1 | CM22: =MAX(U22,AR22) -> 2040 | CQ22: sum | CR22: =SUM(CR5:CR21) -> 4 | CS22: =SUM(CS5:CS21) -> 148 | CT22: =SUM(CT5:CT21) -> 21 | CU22: =SUM(CU5:CU21) -> 19 | CV22: =SUM(CV5:CV21) -> 40 | CW22: =SUM(CW5:CW21) -> 18 | CX22: =SUM(CX5:CX21) -> 40 | CY22: =SUM(CY5:CY21) -> 47 | ... DG22: =SUM(DG5:DG21) -> 284
A23: 328 | B23: America Movil | C23: 349 | D23: =CONCATENATE((IF(BM23=1, "CN", "")),(IF(BQ23=1, " NZ", "")),(IF(BU23=1, " SBT", "")),(IF(BY23=1, " RE100", ""))) -> SBT | E23: EC | F23: 45482 | G23: DT | H23: 4291.5 | J23: Telecommunications and media | K23: United States of America (USA) | L23: North America | M23: N | P23: Y | Q23: Targets Set | R23: 1.5Â°C | S23: 2030 | T23: No | V23: 44044 | W23: 2020 | X23: N | AA23: N | AN23: N | AQ23: N | BS23: 1 | BU23: 1 | CE23: 1 | CG23: 1 | CH23: 1 | CR23: SBTi short term | CU23: RE100 | CX23: Carbon Neutral | DA23: Net Zero | DD23: sum
A24: 278 | B24: American Airlines Group | C24: 291 | D24: =CONCATENATE((IF(BM24=1, "CN", "")),(IF(BQ24=1, " NZ", "")),(IF(BU24=1, " SBT", "")),(IF(BY24=1, " RE100", ""))) -> NZ SBT | E24: DT | F24: 45478 | G24: AJ | H24: 822 | J24: Transportation and Logistics | K24: United States of America (USA) | L24: North America | M24: N | P24: Y | Q24: Targets Set | R24: Well-below 2Â°C | S24: 2035 | T24: No | V24: 44652 | W24: 2022 | X24: N | AA24: N | AN24: C | AO24: undefined | AP24: Net Zero | AQ24: C | AR24: 2050 | AS24: 2020 | AW24: Y | AX24: https://s202.q4cdn.com/986123435/files/images/esg/American-Airlines-Sustainability-Report-2023.pdf https://www.unpri.org/pri-blog/seven-major-companies-that-committed-to-net-zero-emissions-in-2020/6909.article | BP24: 1 | BQ24: 1 | BT24: 1 | BU24: 1 | BZ24: 1 | CB24: 1 | CC24: 1 | CE24: 1 | CH24: 1 | CM24: =MAX(U24,AR24) -> 2050 | CQ24: region | CR24: <=2024 | CS24: 2025-2030 | CT24: 2031-2060 | CU24: <=2024 | CV24: 2025-2030 | CW24: 2031-2060 | CX24: <=2024 | CY24: 2025-2030 | CZ24: 2031-2060 | DA24: <=2024 | DB24: 2025-2030 | DC24: 2031-2060
A25: 195 | B25: American Express | C25: 253 | D25: =CONCATENATE((IF(BM25=1, "CN", "")),(IF(BQ25=1, " NZ", "")),(IF(BU25=1, " SBT", "")),(IF(BY25=1, " RE100", ""))) -> CN NZ SBT RE100 | E25: AJ | F25: 45477 | G25: AJ | H25: 8374 | J25: Financial services | K25: United States of America (USA) | L25: North America | M25: Y | N25: 2020 | O25: 2025 | P25: N | Q25: Committed | S25: 2030 | T25: No | V25: 44440 | W25: 2021 | X25: C | Y25: operations - scope 1, 2 and partial 3 | Z25: carbon neutral | AA25: C | AB25: 2018 | AC25: 2018 | AG25: Y | AH25: 2023 | AI25: Y | AJ25: https://www.americanexpress.com/content/dam/amex/en-us/newsroom/pdfs/AXP_2022-2023_ESG_Report.pdf | AL25: https://www.americanexpress.com/content/dam/amex/en-us/newsroom/pdfs/AXP-2021-2022-ESG-Report.pdf | AN25: V | AO25: undefined but SBTi approved | AP25: Net Zero | AQ25: V | AR25: 2035 | AS25: 2021 | AW25: U | AX25: https://www.americanexpress.com/content/dam/amex/en-us/newsroom/pdfs/AXP-2021-2022-ESG-Report.pdf | BJ25: 1 | BM25: 1 | BP25: 1 | BQ25: 1 | BS25: 1 | BU25: 1 | BW25: 1 | BY25: 1 | BZ25: 1 | CA25: 1 | CB25: 1 | CC25: 1 | CE25: 1 | CF25: 1 | CG25: 1 | CH25: 1 | CK25: 1 | CL25: 1 | CM25: =MAX(U25,AR25) -> 2035 | CQ25: Asia | CR25: =COUNTIFS($L$2:$L$501,CQ25,$S$2:$S$501,"<=2024") -> 0 | CS25: =COUNTIFS($L$2:$L$501,CQ25,$S$2:$S$501,">=2025",$S$2:$S$501,"<=2030") -> 30 | CT25: =COUNTIFS($L$2:$L$501,CQ25,$S$2:$S$501,">2030") -> 4 | CU25: =COUNTIFS($L$2:$L$501,CQ25,$O$2:$O$501,"<=2024") -> 1 | CV25: =COUNTIFS($L$2:$L$501,CQ25,$O$2:$O$501,">=2025",$O$2:$O$501,"<=2030") -> 3 | CW25: =COUNTIFS($L$2:$L$501,CQ25,$O$5:$O$504,">2030") -> 8 | CX25: =COUNTIFS($L$2:$L$501,CQ25,$AB$2:$AB$501,"<=2024") -> 3 | CY25: =COUNTIFS($L$2:$L$501,CQ25,$AB$2:$AB$501,">=2024",$AB$2:$AB$501,"<=2030") -> 15 | CZ25: =COUNTIFS($L$2:$L$501,CQ25,$AB$2:$AB$501,">2030") -> 89 | DA25: =COUNTIFS($L$2:$L$501,CQ25,$CM$2:$CM$501,"<=2024") -> 0 | DB25: =COUNTIFS($L$2:$L$501,CQ25,$CM$2:$CM$501,">=2025",$CM$2:$CM$501,"<=2030") -> 3 | DC25: =COUNTIFS($L$2:$L$501,CQ25,$CM$2:$CM$501,">2030") -> 46 | DD25: =SUM(CR25:DC25) -> 202 | DE25: =COUNTIFS($L$2:$L$501, CQ25, $BF$2:$BF$501, "Y") -> 6 | DF25: =COUNTIFS($L$2:$L$501, CQ25, $BF$2:$BF$501, "N") -> 16 | DG25: =COUNTIFS($L$2:$L$501, CQ25)-DF25-DE25 -> 188
A26: 231 | B26: Anheuser-Busch InBev | C26: 241 | D26: =CONCATENATE((IF(BM26=1, "CN", "")),(IF(BQ26=1, " NZ", "")),(IF(BU26=1, " SBT", "")),(IF(BY26=1, " RE100", ""))) -> NZ SBT RE100 | E26: DT | F26: 45477 | G26: DT | H26: 5341 | J26: Food, beverages and agriculture | K26: Belgium | L26: Europe | M26: Y | N26: 2017 | O26: 2025 | P26: Y | Q26: Targets Set | R26: 1.5°C | S26: 2025 | T26: Yes | W26: 2018 | X26: N | AA26: N | AN26: V | AO26: Scope 1, 2 and 3 | AP26: Net Zero | AQ26: V | AR26: 2040 | AS26: 2021 | AW26: Y | AX26: https://www.ab-inbev.com/assets/pressreleases/2023/AB%20InBev_2022%20ESG%20Report_FINAL.pdf | BP26: 1 | BQ26: 1 | BS26: 1 | BU26: 1 | BW26: 1 | BY26: 1 | BZ26: 1 | CB26: 1 | CC26: 1 | CE26: 1 | CG26: 1 | CH26: 1 | CK26: 1 | CL26: 1 | CM26: =MAX(U26,AR26) -> 2040 | CQ26: Europe | CR26: =COUNTIFS($L$2:$L$501,CQ26,$S$2:$S$501,"<=2024") -> 1 | CS26: =COUNTIFS($L$2:$L$501,CQ26,$S$2:$S$501,">=2025",$S$2:$S$501,"<=2030") -> 64 | CT26: =COUNTIFS($L$2:$L$501,CQ26,$S$2:$S$501,">2030") -> 5 | CU26: =COUNTIFS($L$2:$L$501,CQ26,$O$2:$O$501,"<=2024") -> 9 | CV26: =COUNTIFS($L$2:$L$501,CQ26,$O$2:$O$501,">=2025",$O$2:$O$501,"<=2030") -> 21 | CW26: =COUNTIFS($L$2:$L$501,CQ26,$O$5:$O$504,">2030") -> 5 | CX26: =COUNTIFS($L$2:$L$501,CQ26,$AB$2:$AB$501,"<=2024") -> 13 | CY26: =COUNTIFS($L$2:$L$501,CQ26,$AB$2:$AB$501,">=2024",$AB$2:$AB$501,"<=2030") -> 16 | CZ26: =COUNTIFS($L$2:$L$501,CQ26,$AB$2:$AB$501,">2030") -> 31 | DA26: =COUNTIFS($L$2:$L$501,CQ26,$CM$2:$CM$501,"<=2024") -> 0 | DB26: =COUNTIFS($L$2:$L$501,CQ26,$CM$2:$CM$501,">=2025",$CM$2:$CM$501,"<=2030") -> 11 | DC26: =COUNTIFS($L$2:$L$501,CQ26,$CM$2:$CM$501,">2030") -> 73 | DD26: =SUM(CR26:DC26) -> 249 | DE26: =COUNTIFS($L$2:$L$501, CQ26, $BF$2:$BF$501, "Y") -> 6 | DF26: =COUNTIFS($L$2:$L$501, CQ26, $BF$2:$BF$501, "N") -> 10 | DG26: =COUNTIFS($L$2:$L$501, CQ26)-DF26-DE26 -> 101
A27: 371 | B27: Ansteel Group | C27: 283 | D27: =CONCATENATE((IF(BM27=1, "CN", "")),(IF(BQ27=1, " NZ", "")),(IF(BU27=1, " SBT", "")),(IF(BY27=1, " RE100", ""))) | E27: AJ | F27: 45478 | G27: AJ | H27: -83.1 | J27: Metals and mining | K27: China | L27: Asia | M27: N | P27: N | X27: G | Y27: organization | Z27: carbon neutrality | AA27: G | AB27: 2060 | AC27: 2021 | AL27: http://en.ansteel.cn/upload/pdf/2021.pdf | AN27: N | AQ27: N | CQ27: North America | CR27: =COUNTIFS($L$2:$L$501,CQ27,$S$2:$S$501,"<=2024") -> 3 | CS27: =COUNTIFS($L$2:$L$501,CQ27,$S$2:$S$501,">=2025",$S$2:$S$501,"<=2030") -> 52 | CT27: =COUNTIFS($L$2:$L$501,CQ27,$S$2:$S$501,">2030") -> 12 | CU27: =COUNTIFS($L$2:$L$501,CQ27,$O$2:$O$501,"<=2024") -> 9 | CV27: =COUNTIFS($L$2:$L$501,CQ27,$O$2:$O$501,">=2025",$O$2:$O$501,"<=2030") -> 13 | CW27: =COUNTIFS($L$2:$L$501,CQ27,$O$5:$O$504,">2030") -> 5 | CX27: =COUNTIFS($L$2:$L$501,CQ27,$AB$2:$AB$501,"<=2024") -> 21 | CY27: =COUNTIFS($L$2:$L$501,CQ27,$AB$2:$AB$501,">=2024",$AB$2:$AB$501,"<=2030") -> 14 | CZ27: =COUNTIFS($L$2:$L$501,CQ27,$AB$2:$AB$501,">2030") -> 17 | DA27: =COUNTIFS($L$2:$L$501,CQ27,$CM$2:$CM$501,"<=2024") -> 3 | DB27: =COUNTIFS($L$2:$L$501,CQ27,$CM$2:$CM$501,">=2025",$CM$2:$CM$501,"<=2030") -> 8 | DC27: =COUNTIFS($L$2:$L$501,CQ27,$CM$2:$CM$501,">2030") -> 71 | DD27: =SUM(CR27:DC27) -> 228 | DE27: =COUNTIFS($L$2:$L$501, CQ27, $BF$2:$BF$501, "Y") -> 8 | DF27: =COUNTIFS($L$2:$L$501, CQ27, $BF$2:$BF$501, "N") -> 14 | DG27: =COUNTIFS($L$2:$L$501, CQ27)-DF27-DE27 -> 135
A28: 323 | B28: ANZ Group Holdings | D28: =CONCATENATE((IF(BM28=1, "CN", "")),(IF(BQ28=1, " NZ", "")),(IF(BU28=1, " SBT", "")),(IF(BY28=1, " RE100", ""))) -> NZ RE100 | E28: AJ | F28: 45511 | H28: 4724 | I28: Banks: Commercial and Savings | J28: Financial services | K28: Australia | L28: Other | M28: Y | N28: 2019 | O28: 2025 | P28: N | X28: N | AA28: N | AN28: C | AO28: scope 1 and 290& reduction and financed emissions | AP28: Net Zero | AQ28: C | AR28: 2050 | AS28: 2021 | AW28: U | AX28: https://www.anz.com.au/about-us/esg/environmental-sustainability/climate-change/ | AY28: 2023 | AZ28: Y | BA28: https://www.anz.com.au/content/dam/anzcomau/about-us/anz-2023-esg-supplement.pdf | BP28: 1 | BQ28: 1 | BW28: 1 | BY28: 1 | BZ28: 1 | CB28: 1 | CE28: 1 | CG28: 1 | CH28: 1 | CM28: =MAX(U28,AR28) -> 2050 | CQ28: other | CR28: =COUNTIFS($L$2:$L$501,CQ28,$S$2:$S$501,"<=2024") -> 0 | CS28: =COUNTIFS($L$2:$L$501,CQ28,$S$2:$S$501,">=2025",$S$2:$S$501,"<=2030") -> 2 | CT28: =COUNTIFS($L$2:$L$501,CQ28,$S$2:$S$501,">2030") -> 0 | CU28: =COUNTIFS($L$2:$L$501,CQ28,$O$2:$O$501,"<=2024") -> 0 | CV28: =COUNTIFS($L$2:$L$501,CQ28,$O$2:$O$501,">=2025",$O$2:$O$501,"<=2030") -> 3 | CW28: =COUNTIFS($L$2:$L$501,CQ28,$O$5:$O$504,">2030") -> 0 | CX28: =COUNTIFS($L$2:$L$501,CQ28,$AB$2:$AB$501,"<=2024") -> 3 | CY28: =COUNTIFS($L$2:$L$501,CQ28,$AB$2:$AB$501,">=2024",$AB$2:$AB$501,"<=2030") -> 2 | CZ28: =COUNTIFS($L$2:$L$501,CQ28,$AB$2:$AB$501,">2030") -> 1 | DA28: =COUNTIFS($L$2:$L$501,CQ28,$CM$2:$CM$501,"<=2024") -> 0 | DB28: =COUNTIFS($L$2:$L$501,CQ28,$CM$2:$CM$501,">=2025",$CM$2:$CM$501,"<=2030") -> 0 | DC28: =COUNTIFS($L$2:$L$501,CQ28,$CM$2:$CM$501,">2030") -> 11 | DD28: =SUM(CR28:DC28) -> 22 | DE28: =COUNTIFS($L$2:$L$501, CQ28, $BF$2:$BF$501, "Y") -> 1 | DF28: =COUNTIFS($L$2:$L$501, CQ28, $BF$2:$BF$501, "N") -> 2 | DG28: =COUNTIFS($L$2:$L$501, CQ28)-DF28-DE28 -> 13
A29: 491 | B29: Apollo Global Management | D29: =CONCATENATE((IF(BM29=1, "CN", "")),(IF(BQ29=1, " NZ", "")),(IF(BU29=1, " SBT", "")),(IF(BY29=1, " RE100", ""))) -> CN | E29: AJ | F29: 45512 | H29: 5047 | I29: Diversified Financials | J29: Financial services | K29: United States of America (USA) | L29: North America | M29: N | P29: N | X29: C | Y29: Scope 1 and 2 GHG emissions | Z29: carbon-neutral | AA29: C | AB29: 2023 | AC29: 2023 | AG29: Y | AH29: 2023 | AI29: Y | AJ29: https://www.apollo.com/content/dam/apolloaem/documents/insights/apollo-2023-sustainability-report-june-2024.pdf | AL29: https://www.apollo.com/content/dam/apolloaem/documents/insights/apollo-2023-sustainability-report-june-2024.pdf | AN29: N | AQ29: N | BJ29: 1 | BM29: 1 | BZ29: 1 | CA29: 1 | CB29: 1 | CC29: 1 | CE29: 1 | CF29: 1 | CG29: 1 | CH29: 1 | CQ29: sum | CR29: =SUM(CR25:CR28) -> 4 | CS29: =SUM(CS25:CS28) -> 148 | CT29: =SUM(CT25:CT28) -> 21 | CU29: =SUM(CU25:CU28) -> 19 | CV29: =SUM(CV25:CV28) -> 40 | CW29: =SUM(CW25:CW28) -> 18 | CX29: =SUM(CX25:CX28) -> 40 | CY29: =SUM(CY25:CY28) -> 47 | ... DG29: =SUM(DG25:DG28) -> 437
A30: 7 | B30: Apple | C30: 8 | D30: =CONCATENATE((IF(BM30=1, "CN", "")),(IF(BQ30=1, " NZ", "")),(IF(BU30=1, " SBT", "")),(IF(BY30=1, " RE100", ""))) -> CN SBT RE100 | E30: DT | F30: 45474 | G30: AJ | H30: 96995 | J30: Technology | K30: United States of America (USA) | L30: North America | M30: Y | N30: 2016 | O30: 2021 | P30: Y | Q30: Targets Set | R30: 1.5Â°C | S30: 2030 | T30: No | V30: 44317 | W30: 2021 | X30: C, V | Y30: corporate operations, entire value chain | Z30: carbon neutrality | AA30: C | AB30: 2020 | AC30: 2020 | AD30: V | AE30: 2030 | AF30: 2020 | AG30: R | AH30: 2024 | AI30: Y | AJ30: https://www.apple.com/environment/pdf/Apple_Environmental_Progress_Report_2024.pdf | AL30: https://www.apple.com/environment/pdf/Apple_Environmental_Progress_Report_2024.pdf | AM30: Achieve carbon neutrality for our entire carbon footprint by 2030 â€” reducing related emissions by 75 percent compared with 2015. Since 2015, weâ€™ve reduced emissions by over 55 percent across our value chain.We achieved carbon neutrality in 2020 by expanding energy efficiency initiatives, sourcing 100 percent renewable electricity for Apple facilities, and investing in high-quality carbon credits to offset the remaining hard-to-decarbonize corporate emissions. | AN30: N | AQ30: N | BJ30: 1 | BM30: 1 | BS30: 1 | BU30: 1 | BV30: 1 | BY30: 1 | BZ30: 1 | CA30: 1 | CB30: 1 | CC30: 1 | CE30: 1 | CF30: 1 | CG30: 1 | CH30: 1
A31: 190 | B31: ArcelorMittal | C31: 155 | D31: =CONCATENATE((IF(BM31=1, "CN", "")),(IF(BQ31=1, " NZ", "")),(IF(BU31=1, " SBT", "")),(IF(BY31=1, " RE100", ""))) -> CN NZ | E31: DT | F31: 45476 | G31: AJ | H31: 919 | J31: Metals and mining | K31: Luxembourg | L31: Europe | M31: N | P31: N | Q31: Removed | T31: No | V31: 44593 | W31: 2022 | X31: C | Y31: Scope 1 and 2 | Z31: Carbon Neutral | AA31: C | AB31: 2050 | AC31: 2020 | AG31: Y | AI31: Y | AL31: https://corporate.arcelormittal.com/media/vrqovnik/arcelor-mittal-integrated-annual-review-2023.pdf | AN31: C | AO31: Scope 1 and 2 | AP31: Net Zero | AQ31: C | AR31: 2050 | AS31: 2020 | AW31: Y | AX31: https://corporate.arcelormittal.com/climate-action/leading-our-industry-s-efforts-to-decarbonise | BL31: 1 | BM31: 1 | BP31: 1 | BQ31: 1 | BZ31: 1 | CB31: 1 | CC31: 1 | CE31: 1 | CH31: 1 | CM31: =MAX(U31,AR31) -> 2050
A32: 117 | B32: Archer Daniels Midland | C32: 98 | D32: =CONCATENATE((IF(BM32=1, "CN", "")),(IF(BQ32=1, " NZ", "")),(IF(BU32=1, " SBT", "")),(IF(BY32=1, " RE100", ""))) -> SBT | E32: EC | F32: 45475 | G32: DT | H32: 3483 | J32: Food, beverages and agriculture | K32: United States of America (USA) | L32: North America | M32: N | P32: N | Q32: Committed | S32: 2030 | T32: No | V32: 44652 | W32: 2022 | X32: N | AA32: N | AL32: https://www.adm.com/globalassets/sustainability/sustainability-reports/final_archer-daniels-midland-adm_2023-corporate-sustainability-report_51424.pdf | AN32: N | AQ32: N | AX32: https://www.adm.com/globalassets/sustainability/sustainability-reports/final_archer-daniels-midland-adm_2023-corporate-sustainability-report_51424.pdf | BS32: 1 | BU32: 1 | CE32: 1 | CG32: 1 | CH32: 1
A33: 481 | B33: Arrow Electronics | C33: 404 | D33: =CONCATENATE((IF(BM33=1, "CN", "")),(IF(BQ33=1, " NZ", "")),(IF(BU33=1, " SBT", "")),(IF(BY33=1, " RE100", ""))) -> SBT | E33: DT * | F33: 45511 | G33: DT | H33: 903.5 | J33: Retail | K33: United States of America (USA) | L33: North America | M33: N | P33: N | Q33: Committed | S33: 2030 | T33: No | V33: 45170 | W33: 2023 | X33: N | AA33: N | AN33: N | AQ33: N | BS33: 1 | BU33: 1 | CE33: 1 | CG33: 1 | CH33: 1
A34: 245 | B34: Assicurazioni Generali | C34: 137 | D34: =CONCATENATE((IF(BM34=1, "CN", "")),(IF(BQ34=1, " NZ", "")),(IF(BU34=1, " SBT", "")),(IF(BY34=1, " RE100", ""))) -> NZ | E34: AJ | F34: 45476 | G34: AJ | H34: 4050.7 | J34: Financial services | K34: Italy | L34: Europe | M34: N | P34: N | X34: N | AA34: N | AN34: C, F | AO34: operational activities, insurance portfolio | AP34: Net-Zero emissions | AQ34: C | AR34: 2040 | AS34: 2021 | AT34: F | AU34: 2050 | AV34: 2021 | AW34: R | AX34: https://www.generali.com/media/press-releases/all/2021/Generali-updates-its-strategy-for-climate-protection | BC34: https://www.generali.com/doc/jcr:10e8853d-1fa8-44b2-958e-3ca826a3bd30/Annual%20Integrated%20Report%20and%20Consolidated%20Financial%20Statements%202023_Generali%20Group_final_interactive.pdf/lang:en/Annual_Integrated_Report_and_Consolidated_Financial_Statements_2023_Generali_Group_final_interactive.pdf | BD34: Y | BE34: https://www.generali.com/sustainability/our-commitment-to-the-environment-and-climate | BF34: N | BP34: 1 | BQ34: 1 | BZ34: 1 | CB34: 1 | CC34: 1 | CE34: 1 | CH34: 1 | CK34: 1 | CL34: 1 | CM34: =MAX(U34,AR34) -> 2040
A35: 329 | B35: AstraZeneca | C35: 331 | D35: =CONCATENATE((IF(BM35=1, "CN", "")),(IF(BQ35=1, " NZ", "")),(IF(BU35=1, " SBT", "")),(IF(BY35=1, " RE100", ""))) -> NZ SBT RE100 | E35: EC | F35: 45482 | G35: DT | H35: 5955 | J35: Health care and pharmaceuticals | K35: United Kingdom | L35: Europe | M35: Y | N35: 2016 | O35: 2025 | P35: Y | Q35: Targets Set | R35: 1.5Â°C | S35: 2026 | T35: Yes | U35: 2045 | V35: 44470 | W35: 2021 | X35: N | AA35: N | AN35: V | AO35: value chain (Scopes 1, 2 and 3) | AP35: Net Zero | AQ35: V | AR35: 2045 | AS35: 2020 | AW35: Y | AX35: https://www.astrazeneca.com/content/dam/az/Sustainability/2024/pdf/Ambition-Zero-Carbon-Infographic-2023.pdf | BC35: https://www.astrazeneca.com/media-centre/press-releases/2020/astrazenecas-ambition-zero-carbon-strategy-to-eliminate-emissions-by-2025-and-be-carbon-negative-across-the-entire-value-chain-by-2030-22012020.html#modal-historic-confirmation | BP35: 1 | BQ35: 1 | BS35: 1 | BU35: 1 | BW35: 1 | BY35: 1 | BZ35: 1 | CB35: 1 | CC35: 1 | CE35: 1 | CG35: 1 | CH35: 1 | CK35: 1 | CL35: 1 | CM35: =MAX(U35,AR35) -> 2045
A36: 74 | B36: AT&T | C36: 78 | D36: =CONCATENATE((IF(BM36=1, "CN", "")),(IF(BQ36=1, " NZ", "")),(IF(BU36=1, " SBT", "")),(IF(BY36=1, " RE100", ""))) -> CN SBT | E36: DT - AJ | F36: 45475 | G36: DT | H36: 14400 | J36: Telecommunications and media | K36: United States of America (USA) | L36: North America | M36: N | P36: Y | Q36: Targets Set | R36: 1.5Â°C | S36: 2024 | T36: No | V36: 43891 | W36: 2020 | X36: C | Y36: entire global operations | Z36: carbon neutral | AA36: C | AB36: 2035 | AC36: 2018 | AG36: Y | AI36: Y | AL36: https://about.att.com/ecms/dam/csr/2019/environment/ClimateStrategyTransitionPlan.pdf https://sustainability.att.com/progress/esg-data | AM36: Though AT&T aims to reduce our footprint to as close to zero emissions as possible, there may be some sources of emissions that cannot be eliminated. In these cases, we will invest in high-quality carbon ofsets to cover the associated emissions. | AN36: N | AQ36: N | BL36: 1 | BM36: 1 | BS36: 1 | BU36: 1 | BZ36: 1 | CB36: 1 | CC36: 1 | CE36: 1 | CG36: 1 | CH36: 1
A37: 147 | B37: Aviation Industry Corp. of China | C37: 150 | D37: =CONCATENATE((IF(BM37=1, "CN", "")),(IF(BQ37=1, " NZ", "")),(IF(BU37=1, " SBT", "")),(IF(BY37=1, " RE100", ""))) -> NZ | E37: DT | F37: 45476 | G37: AJ | H37: 1644.1 | J37: Aerospace and defense | K37: China | L37: Asia | M37: N | P37: N | X37: I | AA37: I | AN37: V | AO37: Scope 1, 2 and 3 | AP37: Net Zero | AQ37: V | AR37: 2050 | AS37: 2021 | AW37: Y | AX37: https://calec.china-airlines.com/csr/en/download/2022/2022-en-CSR.pdf | BC37: CAL complies with the IATA and national carbon reduction targets by leading the industry in announcing the â€œtarget for achieving net zero carbon emissions by 2050â€ in October 2021 | BP37: 1 | BQ37: 1 | BZ37: 1 | CB37: 1 | CC37: 1 | CE37: 1 | CH37: 1 | CK37: 1 | CL37: 1 | CM37: =MAX(U37,AR37) -> 2050
A38: 126 | B38: AXA | C38: 91 | D38: =CONCATENATE((IF(BM38=1, "CN", "")),(IF(BQ38=1, " NZ", "")),(IF(BU38=1, " SBT", "")),(IF(BY38=1, " RE100", ""))) -> CN NZ SBT RE100 | E38: DT - AJ | F38: 45475 | G38: DT | H38: 7771.7 | J38: Financial services | K38: France | L38: Europe | M38: Y | N38: 2017 | O38: 2025 | P38: N | Q38: Committed | S38: 2030 | T38: No | V38: 42156 | W38: 2015 | X38: C, V | Y38: operations, Scope 3 business travel, IT equipment manufacturing and purchased services, and upstream energy emissions | Z38: carbon neutral | AA38: C | AB38: 2020 | AC38: 2020 | AD38: V | AE38: 2025 | AF38: 2020 | AG38: Y | AH38: 2024 | AI38: Y | AJ38: https://www-axa-com.cdn.axa-contento-118412.eu/www-axa-com/8b8dfa69-13e3-4c34-bae3-8fb939102a2d_axa_climate_and_biodiversity_report_2024_va.pdf | AL38: https://www.axa.com/en/commitments/environmental-footprint-management | AN38: F | AO38: insurance and reinsurance underwriting portfolios | AP38: Net-Zero greenhouse gas emissions | AQ38: F | AR38: 2050 | AS38: 2023 | AW38: U | AX38: https://www.axa.com/en/commitments/axa-net-zero-strategy-for-investment-and-underwriting | BJ38: 1 | BM38: 1 | BP38: 1 | BQ38: 1 | BS38: 1 | BU38: 1 | BW38: 1 | BY38: 1 | BZ38: 1 | CA38: 1 | CB38: 1 | CC38: 1 | CE38: 1 | CF38: 1 | CG38: 1 | CH38: 1 | CK38: 1 | CL38: 1 | CM38: =MAX(U38,AR38) -> 2050
