Workbook

Sheet target portfolio 
A1: company | B1: country | C1: sector | D1: 2021 cc yes/no | E1: 2022 cc yes/no | F1: 2023 cc yes/no | G1: 2024 cc yes/no | H1: 2025 cc yes/no | I1: 2021 cn | J1: 2022 cn | K1: 2023 cn | L1: 2024 cn | M1: 2025 cn | N1: 2021 re | O1: 2022 re | P1: 2023 re | Q1: 2024 re | R1: 2025 re | S1: 2021 sbti nt | T1: 2022 sbti nt | U1: 2023 sbti nt | V1: 2024 sbti nt | W1: 2025 sbti nt | X1: 2021 nz | Y1: 2022 nz | Z1: 2023 nz | AA1: 2024 nz | AB1: 2025 nz
A2: 3M | E2: =_xlfn.XLOOKUP(A2,'2022'!A:A,'2022'!AA:AA) | F2: =_xlfn.XLOOKUP(A2,'2023'!B:B,'2023'!AG:AG) -> U | G2: =_xlfn.XLOOKUP(A2,'2024'!B:B,'2024'!BL:BL) -> 1 | H2: =_xlfn.XLOOKUP(A2,'2025'!A:A,'2025'!G:G) -> #N/A | I2: =_xlfn.XLOOKUP(A2,'2021'!A:A,'2021'!U:U) -> 1 | J2: =_xlfn.XLOOKUP(A2,'2022'!A:A,'2022'!V:V) -> 1 | K2: =_xlfn.XLOOKUP(A2,'2023'!B:B,'2023'!AD:AD) -> 1 | L2: =_xlfn.XLOOKUP(A2,'2024'!B:B,'2024'!AV:AV) -> 1 | M2: =_xlfn.XLOOKUP(A2,'2025'!A:A,'2025'!G:G) -> #N/A | N2: =_xlfn.XLOOKUP(A2,'2021'!A:A,'2021'!E:E) -> Y | O2: =_xlfn.XLOOKUP(A2,'2022'!A:A,'2022'!E:E) -> Y | P2: =_xlfn.XLOOKUP(A2,'2023'!B:B,'2023'!G:G) -> Y | Q2: =_xlfn.XLOOKUP(A2,'2024'!B:B,'2024'!BH:BH) -> 1 | R2: =_xlfn.XLOOKUP(A2,'2025'!A:A,'2025'!B:B) -> #N/A | S2: =_xlfn.XLOOKUP(A2,'2021'!A:A,'2021'!X:X) | T2: =_xlfn.XLOOKUP(A2,'2022'!A:A,'2022'!X:X) | U2: =_xlfn.XLOOKUP(A2,'2023'!B:B,'2023'!AF:AF) | V2: =_xlfn.XLOOKUP(A2,'2024'!B:B,'2024'!BW:BW) | W2: =_xlfn.XLOOKUP(A2,'2025'!A:A,'2025'!C:C) -> #N/A | X2: =_xlfn.XLOOKUP(A2,'2021'!A:A,'2021'!V:V) | Y2: =_xlfn.XLOOKUP(A2,'2022'!A:A,'2022'!W:W) | Z2: =_xlfn.XLOOKUP(A2,'2023'!B:B,'2023'!AE:AE) | AA2: =_xlfn.XLOOKUP(A2,'2024'!B:B,'2024'!AZ:AZ) -> 0 | AB2: =_xlfn.XLOOKUP(A2,'2025'!A:A,'2025'!F:F) -> #N/A
A3: ABB | E3: =_xlfn.XLOOKUP(A3,'2022'!A:A,'2022'!AA:AA) -> Y | F3: =_xlfn.XLOOKUP(A3,'2023'!B:B,'2023'!AG:AG) -> #N/A | G3: =_xlfn.XLOOKUP(A3,'2024'!B:B,'2024'!BL:BL) -> 1 | H3: =_xlfn.XLOOKUP(A3,'2025'!A:A,'2025'!G:G) -> 0 | I3: =_xlfn.XLOOKUP(A3,'2021'!A:A,'2021'!U:U) -> 1 | J3: =_xlfn.XLOOKUP(A3,'2022'!A:A,'2022'!V:V) -> 1 | K3: =_xlfn.XLOOKUP(A3,'2023'!B:B,'2023'!AD:AD) -> #N/A | L3: =_xlfn.XLOOKUP(A3,'2024'!B:B,'2024'!AV:AV) | M3: =_xlfn.XLOOKUP(A3,'2025'!A:A,'2025'!G:G) -> 0 | N3: =_xlfn.XLOOKUP(A3,'2021'!A:A,'2021'!E:E) -> Y | O3: =_xlfn.XLOOKUP(A3,'2022'!A:A,'2022'!E:E) -> Y | P3: =_xlfn.XLOOKUP(A3,'2023'!B:B,'2023'!G:G) -> #N/A | Q3: =_xlfn.XLOOKUP(A3,'2024'!B:B,'2024'!BH:BH) -> 1 | R3: =_xlfn.XLOOKUP(A3,'2025'!A:A,'2025'!B:B) -> 1 | S3: =_xlfn.XLOOKUP(A3,'2021'!A:A,'2021'!X:X) -> 1 | T3: =_xlfn.XLOOKUP(A3,'2022'!A:A,'2022'!X:X) -> 1 | U3: =_xlfn.XLOOKUP(A3,'2023'!B:B,'2023'!AF:AF) -> #N/A | V3: =_xlfn.XLOOKUP(A3,'2024'!B:B,'2024'!BW:BW) -> 1 | W3: =_xlfn.XLOOKUP(A3,'2025'!A:A,'2025'!C:C) -> 1 | X3: =_xlfn.XLOOKUP(A3,'2021'!A:A,'2021'!V:V) | Y3: =_xlfn.XLOOKUP(A3,'2022'!A:A,'2022'!W:W) | Z3: =_xlfn.XLOOKUP(A3,'2023'!B:B,'2023'!AE:AE) -> #N/A | AA3: =_xlfn.XLOOKUP(A3,'2024'!B:B,'2024'!AZ:AZ) -> 1 | AB3: =_xlfn.XLOOKUP(A3,'2025'!A:A,'2025'!F:F) -> 1
A4: ACS | E4: =_xlfn.XLOOKUP(A4,'2022'!A:A,'2022'!AA:AA) | F4: =_xlfn.XLOOKUP(A4,'2023'!B:B,'2023'!AG:AG) -> Y | G4: =_xlfn.XLOOKUP(A4,'2024'!B:B,'2024'!BL:BL) -> 0 | H4: =_xlfn.XLOOKUP(A4,'2025'!A:A,'2025'!G:G) -> 1 | I4: =_xlfn.XLOOKUP(A4,'2021'!A:A,'2021'!U:U) | J4: =_xlfn.XLOOKUP(A4,'2022'!A:A,'2022'!V:V) -> 1 | K4: =_xlfn.XLOOKUP(A4,'2023'!B:B,'2023'!AD:AD) -> 1 | L4: =_xlfn.XLOOKUP(A4,'2024'!B:B,'2024'!AV:AV) -> 1 | M4: =_xlfn.XLOOKUP(A4,'2025'!A:A,'2025'!G:G) -> 1 | N4: =_xlfn.XLOOKUP(A4,'2021'!A:A,'2021'!E:E) -> 0 | O4: =_xlfn.XLOOKUP(A4,'2022'!A:A,'2022'!E:E) -> 0 | P4: =_xlfn.XLOOKUP(A4,'2023'!B:B,'2023'!G:G) -> 0 | Q4: =_xlfn.XLOOKUP(A4,'2024'!B:B,'2024'!BH:BH) -> 0 | R4: =_xlfn.XLOOKUP(A4,'2025'!A:A,'2025'!B:B) -> 0 | S4: =_xlfn.XLOOKUP(A4,'2021'!A:A,'2021'!X:X) | T4: =_xlfn.XLOOKUP(A4,'2022'!A:A,'2022'!X:X) | U4: =_xlfn.XLOOKUP(A4,'2023'!B:B,'2023'!AF:AF) | V4: =_xlfn.XLOOKUP(A4,'2024'!B:B,'2024'!BW:BW) | W4: =_xlfn.XLOOKUP(A4,'2025'!A:A,'2025'!C:C) -> 0 | X4: =_xlfn.XLOOKUP(A4,'2021'!A:A,'2021'!V:V) | Y4: =_xlfn.XLOOKUP(A4,'2022'!A:A,'2022'!W:W) | Z4: =_xlfn.XLOOKUP(A4,'2023'!B:B,'2023'!AE:AE) | AA4: =_xlfn.XLOOKUP(A4,'2024'!B:B,'2024'!AZ:AZ) -> 0 | AB4: =_xlfn.XLOOKUP(A4,'2025'!A:A,'2025'!F:F) -> 1
A5: AEON | E5: =_xlfn.XLOOKUP(A5,'2022'!A:A,'2022'!AA:AA) -> N | F5: =_xlfn.XLOOKUP(A5,'2023'!B:B,'2023'!AG:AG) -> 0 | G5: =_xlfn.XLOOKUP(A5,'2024'!B:B,'2024'!BL:BL) -> 1 | H5: =_xlfn.XLOOKUP(A5,'2025'!A:A,'2025'!G:G) -> 0 | I5: =_xlfn.XLOOKUP(A5,'2021'!A:A,'2021'!U:U) | J5: =_xlfn.XLOOKUP(A5,'2022'!A:A,'2022'!V:V) | K5: =_xlfn.XLOOKUP(A5,'2023'!B:B,'2023'!AD:AD) | L5: =_xlfn.XLOOKUP(A5,'2024'!B:B,'2024'!AV:AV) | M5: =_xlfn.XLOOKUP(A5,'2025'!A:A,'2025'!G:G) -> 0 | N5: =_xlfn.XLOOKUP(A5,'2021'!A:A,'2021'!E:E) -> Y | O5: =_xlfn.XLOOKUP(A5,'2022'!A:A,'2022'!E:E) -> Y | P5: =_xlfn.XLOOKUP(A5,'2023'!B:B,'2023'!G:G) -> Y | Q5: =_xlfn.XLOOKUP(A5,'2024'!B:B,'2024'!BH:BH) -> 1 | R5: =_xlfn.XLOOKUP(A5,'2025'!A:A,'2025'!B:B) -> 1 | S5: =_xlfn.XLOOKUP(A5,'2021'!A:A,'2021'!X:X) -> 1 | T5: =_xlfn.XLOOKUP(A5,'2022'!A:A,'2022'!X:X) -> 1 | U5: =_xlfn.XLOOKUP(A5,'2023'!B:B,'2023'!AF:AF) -> 1 | V5: =_xlfn.XLOOKUP(A5,'2024'!B:B,'2024'!BW:BW) -> 1 | W5: =_xlfn.XLOOKUP(A5,'2025'!A:A,'2025'!C:C) -> 1 | X5: =_xlfn.XLOOKUP(A5,'2021'!A:A,'2021'!V:V) -> 1 | Y5: =_xlfn.XLOOKUP(A5,'2022'!A:A,'2022'!W:W) -> 1 | Z5: =_xlfn.XLOOKUP(A5,'2023'!B:B,'2023'!AE:AE) -> 1 | AA5: =_xlfn.XLOOKUP(A5,'2024'!B:B,'2024'!AZ:AZ) -> 1 | AB5: =_xlfn.XLOOKUP(A5,'2025'!A:A,'2025'!F:F) -> 1
A6: AIA Group | E6: =_xlfn.XLOOKUP(A6,'2022'!A:A,'2022'!AA:AA) | F6: =_xlfn.XLOOKUP(A6,'2023'!B:B,'2023'!AG:AG) -> #N/A | G6: =_xlfn.XLOOKUP(A6,'2024'!B:B,'2024'!BL:BL) -> 0 | H6: =_xlfn.XLOOKUP(A6,'2025'!A:A,'2025'!G:G) -> 0 | I6: =_xlfn.XLOOKUP(A6,'2021'!A:A,'2021'!U:U) | J6: =_xlfn.XLOOKUP(A6,'2022'!A:A,'2022'!V:V) | K6: =_xlfn.XLOOKUP(A6,'2023'!B:B,'2023'!AD:AD) -> #N/A | L6: =_xlfn.XLOOKUP(A6,'2024'!B:B,'2024'!AV:AV) | M6: =_xlfn.XLOOKUP(A6,'2025'!A:A,'2025'!G:G) -> 0 | N6: =_xlfn.XLOOKUP(A6,'2021'!A:A,'2021'!E:E) -> 0 | O6: =_xlfn.XLOOKUP(A6,'2022'!A:A,'2022'!E:E) -> 0 | P6: =_xlfn.XLOOKUP(A6,'2023'!B:B,'2023'!G:G) -> #N/A | Q6: =_xlfn.XLOOKUP(A6,'2024'!B:B,'2024'!BH:BH) -> 0 | R6: =_xlfn.XLOOKUP(A6,'2025'!A:A,'2025'!B:B) -> 0 | S6: =_xlfn.XLOOKUP(A6,'2021'!A:A,'2021'!X:X) | T6: =_xlfn.XLOOKUP(A6,'2022'!A:A,'2022'!X:X) | U6: =_xlfn.XLOOKUP(A6,'2023'!B:B,'2023'!AF:AF) -> #N/A | V6: =_xlfn.XLOOKUP(A6,'2024'!B:B,'2024'!BW:BW) -> 1 | W6: =_xlfn.XLOOKUP(A6,'2025'!A:A,'2025'!C:C) -> 1 | X6: =_xlfn.XLOOKUP(A6,'2021'!A:A,'2021'!V:V) | Y6: =_xlfn.XLOOKUP(A6,'2022'!A:A,'2022'!W:W) -> 1 | Z6: =_xlfn.XLOOKUP(A6,'2023'!B:B,'2023'!AE:AE) -> #N/A | AA6: =_xlfn.XLOOKUP(A6,'2024'!B:B,'2024'!AZ:AZ) -> 1 | AB6: =_xlfn.XLOOKUP(A6,'2025'!A:A,'2025'!F:F) -> 1
A7: AIG | E7: =_xlfn.XLOOKUP(A7,'2022'!A:A,'2022'!AA:AA) -> #N/A | F7: =_xlfn.XLOOKUP(A7,'2023'!B:B,'2023'!AG:AG) -> #N/A | G7: =_xlfn.XLOOKUP(A7,'2024'!B:B,'2024'!BL:BL) -> 0 | H7: =_xlfn.XLOOKUP(A7,'2025'!A:A,'2025'!G:G) -> #N/A | I7: =_xlfn.XLOOKUP(A7,'2021'!A:A,'2021'!U:U) -> #N/A | J7: =_xlfn.XLOOKUP(A7,'2022'!A:A,'2022'!V:V) -> #N/A | K7: =_xlfn.XLOOKUP(A7,'2023'!B:B,'2023'!AD:AD) -> #N/A | L7: =_xlfn.XLOOKUP(A7,'2024'!B:B,'2024'!AV:AV) | M7: =_xlfn.XLOOKUP(A7,'2025'!A:A,'2025'!G:G) -> #N/A | N7: =_xlfn.XLOOKUP(A7,'2021'!A:A,'2021'!E:E) -> #N/A | O7: =_xlfn.XLOOKUP(A7,'2022'!A:A,'2022'!E:E) -> #N/A | P7: =_xlfn.XLOOKUP(A7,'2023'!B:B,'2023'!G:G) -> #N/A | Q7: =_xlfn.XLOOKUP(A7,'2024'!B:B,'2024'!BH:BH) -> 0 | R7: =_xlfn.XLOOKUP(A7,'2025'!A:A,'2025'!B:B) -> #N/A | S7: =_xlfn.XLOOKUP(A7,'2021'!A:A,'2021'!X:X) -> #N/A | T7: =_xlfn.XLOOKUP(A7,'2022'!A:A,'2022'!X:X) -> #N/A | U7: =_xlfn.XLOOKUP(A7,'2023'!B:B,'2023'!AF:AF) -> #N/A | V7: =_xlfn.XLOOKUP(A7,'2024'!B:B,'2024'!BW:BW) | W7: =_xlfn.XLOOKUP(A7,'2025'!A:A,'2025'!C:C) -> #N/A | X7: =_xlfn.XLOOKUP(A7,'2021'!A:A,'2021'!V:V) -> #N/A | Y7: =_xlfn.XLOOKUP(A7,'2022'!A:A,'2022'!W:W) -> #N/A | Z7: =_xlfn.XLOOKUP(A7,'2023'!B:B,'2023'!AE:AE) -> #N/A | AA7: =_xlfn.XLOOKUP(A7,'2024'!B:B,'2024'!AZ:AZ) -> 1 | AB7: =_xlfn.XLOOKUP(A7,'2025'!A:A,'2025'!F:F) -> #N/A
A8: ANZ Group Holdings | E8: =_xlfn.XLOOKUP(A8,'2022'!A:A,'2022'!AA:AA) -> #N/A | F8: =_xlfn.XLOOKUP(A8,'2023'!B:B,'2023'!AG:AG) -> #N/A | G8: =_xlfn.XLOOKUP(A8,'2024'!B:B,'2024'!BL:BL) -> 0 | H8: =_xlfn.XLOOKUP(A8,'2025'!A:A,'2025'!G:G) -> 1 | I8: =_xlfn.XLOOKUP(A8,'2021'!A:A,'2021'!U:U) -> #N/A | J8: =_xlfn.XLOOKUP(A8,'2022'!A:A,'2022'!V:V) -> #N/A | K8: =_xlfn.XLOOKUP(A8,'2023'!B:B,'2023'!AD:AD) -> #N/A | L8: =_xlfn.XLOOKUP(A8,'2024'!B:B,'2024'!AV:AV) | M8: =_xlfn.XLOOKUP(A8,'2025'!A:A,'2025'!G:G) -> 1 | N8: =_xlfn.XLOOKUP(A8,'2021'!A:A,'2021'!E:E) -> #N/A | O8: =_xlfn.XLOOKUP(A8,'2022'!A:A,'2022'!E:E) -> #N/A | P8: =_xlfn.XLOOKUP(A8,'2023'!B:B,'2023'!G:G) -> #N/A | Q8: =_xlfn.XLOOKUP(A8,'2024'!B:B,'2024'!BH:BH) -> 1 | R8: =_xlfn.XLOOKUP(A8,'2025'!A:A,'2025'!B:B) -> 1 | S8: =_xlfn.XLOOKUP(A8,'2021'!A:A,'2021'!X:X) -> #N/A | T8: =_xlfn.XLOOKUP(A8,'2022'!A:A,'2022'!X:X) -> #N/A | U8: =_xlfn.XLOOKUP(A8,'2023'!B:B,'2023'!AF:AF) -> #N/A | V8: =_xlfn.XLOOKUP(A8,'2024'!B:B,'2024'!BW:BW) | W8: =_xlfn.XLOOKUP(A8,'2025'!A:A,'2025'!C:C) -> 0 | X8: =_xlfn.XLOOKUP(A8,'2021'!A:A,'2021'!V:V) -> #N/A | Y8: =_xlfn.XLOOKUP(A8,'2022'!A:A,'2022'!W:W) -> #N/A | Z8: =_xlfn.XLOOKUP(A8,'2023'!B:B,'2023'!AE:AE) -> #N/A | AA8: =_xlfn.XLOOKUP(A8,'2024'!B:B,'2024'!AZ:AZ) -> 1 | AB8: =_xlfn.XLOOKUP(A8,'2025'!A:A,'2025'!F:F) -> 0
A9: AT&T | E9: =_xlfn.XLOOKUP(A9,'2022'!A:A,'2022'!AA:AA) | F9: =_xlfn.XLOOKUP(A9,'2023'!B:B,'2023'!AG:AG) -> Y | G9: =_xlfn.XLOOKUP(A9,'2024'!B:B,'2024'!BL:BL) -> 1 | H9: =_xlfn.XLOOKUP(A9,'2025'!A:A,'2025'!G:G) -> 1 | I9: =_xlfn.XLOOKUP(A9,'2021'!A:A,'2021'!U:U) -> 1 | J9: =_xlfn.XLOOKUP(A9,'2022'!A:A,'2022'!V:V) -> 1 | K9: =_xlfn.XLOOKUP(A9,'2023'!B:B,'2023'!AD:AD) -> 1 | L9: =_xlfn.XLOOKUP(A9,'2024'!B:B,'2024'!AV:AV) -> 1 | M9: =_xlfn.XLOOKUP(A9,'2025'!A:A,'2025'!G:G) -> 1 | N9: =_xlfn.XLOOKUP(A9,'2021'!A:A,'2021'!E:E) -> 0 | O9: =_xlfn.XLOOKUP(A9,'2022'!A:A,'2022'!E:E) -> 0 | P9: =_xlfn.XLOOKUP(A9,'2023'!B:B,'2023'!G:G) -> 0 | Q9: =_xlfn.XLOOKUP(A9,'2024'!B:B,'2024'!BH:BH) -> 0 | R9: =_xlfn.XLOOKUP(A9,'2025'!A:A,'2025'!B:B) -> 0 | S9: =_xlfn.XLOOKUP(A9,'2021'!A:A,'2021'!X:X) -> 1 | T9: =_xlfn.XLOOKUP(A9,'2022'!A:A,'2022'!X:X) -> 1 | U9: =_xlfn.XLOOKUP(A9,'2023'!B:B,'2023'!AF:AF) -> 1 | V9: =_xlfn.XLOOKUP(A9,'2024'!B:B,'2024'!BW:BW) -> 1 | W9: =_xlfn.XLOOKUP(A9,'2025'!A:A,'2025'!C:C) -> 1 | X9: =_xlfn.XLOOKUP(A9,'2021'!A:A,'2021'!V:V) | Y9: =_xlfn.XLOOKUP(A9,'2022'!A:A,'2022'!W:W) | Z9: =_xlfn.XLOOKUP(A9,'2023'!B:B,'2023'!AE:AE) | AA9: =_xlfn.XLOOKUP(A9,'2024'!B:B,'2024'!AZ:AZ) -> 0 | AB9: =_xlfn.XLOOKUP(A9,'2025'!A:A,'2025'!F:F) -> 1
A10: AXA | E10: =_xlfn.XLOOKUP(A10,'2022'!A:A,'2022'!AA:AA) -> Y | F10: =_xlfn.XLOOKUP(A10,'2023'!B:B,'2023'!AG:AG) -> Y | G10: =_xlfn.XLOOKUP(A10,'2024'!B:B,'2024'!BL:BL) -> 1 | H10: =_xlfn.XLOOKUP(A10,'2025'!A:A,'2025'!G:G) -> 1 | I10: =_xlfn.XLOOKUP(A10,'2021'!A:A,'2021'!U:U) -> 1 | J10: =_xlfn.XLOOKUP(A10,'2022'!A:A,'2022'!V:V) -> 1 | K10: =_xlfn.XLOOKUP(A10,'2023'!B:B,'2023'!AD:AD) | L10: =_xlfn.XLOOKUP(A10,'2024'!B:B,'2024'!AV:AV) | M10: =_xlfn.XLOOKUP(A10,'2025'!A:A,'2025'!G:G) -> 1 | N10: =_xlfn.XLOOKUP(A10,'2021'!A:A,'2021'!E:E) -> Y | O10: =_xlfn.XLOOKUP(A10,'2022'!A:A,'2022'!E:E) -> Y | P10: =_xlfn.XLOOKUP(A10,'2023'!B:B,'2023'!G:G) -> Y | Q10: =_xlfn.XLOOKUP(A10,'2024'!B:B,'2024'!BH:BH) -> 1 | R10: =_xlfn.XLOOKUP(A10,'2025'!A:A,'2025'!B:B) -> 1 | S10: =_xlfn.XLOOKUP(A10,'2021'!A:A,'2021'!X:X) | T10: =_xlfn.XLOOKUP(A10,'2022'!A:A,'2022'!X:X) | U10: =_xlfn.XLOOKUP(A10,'2023'!B:B,'2023'!AF:AF) | V10: =_xlfn.XLOOKUP(A10,'2024'!B:B,'2024'!BW:BW) | W10: =_xlfn.XLOOKUP(A10,'2025'!A:A,'2025'!C:C) -> 0 | X10: =_xlfn.XLOOKUP(A10,'2021'!A:A,'2021'!V:V) -> 1 | Y10: =_xlfn.XLOOKUP(A10,'2022'!A:A,'2022'!W:W) -> 1 | Z10: =_xlfn.XLOOKUP(A10,'2023'!B:B,'2023'!AE:AE) -> 1 | AA10: =_xlfn.XLOOKUP(A10,'2024'!B:B,'2024'!AZ:AZ) -> 1 | AB10: =_xlfn.XLOOKUP(A10,'2025'!A:A,'2025'!F:F) -> 1
A11: AbbVie | E11: =_xlfn.XLOOKUP(A11,'2022'!A:A,'2022'!AA:AA) | F11: =_xlfn.XLOOKUP(A11,'2023'!B:B,'2023'!AG:AG) -> 0 | G11: =_xlfn.XLOOKUP(A11,'2024'!B:B,'2024'!BL:BL) -> 1 | H11: =_xlfn.XLOOKUP(A11,'2025'!A:A,'2025'!G:G) -> 0 | I11: =_xlfn.XLOOKUP(A11,'2021'!A:A,'2021'!U:U) | J11: =_xlfn.XLOOKUP(A11,'2022'!A:A,'2022'!V:V) | K11: =_xlfn.XLOOKUP(A11,'2023'!B:B,'2023'!AD:AD) | L11: =_xlfn.XLOOKUP(A11,'2024'!B:B,'2024'!AV:AV) | M11: =_xlfn.XLOOKUP(A11,'2025'!A:A,'2025'!G:G) -> 0 | N11: =_xlfn.XLOOKUP(A11,'2021'!A:A,'2021'!E:E) -> 0 | O11: =_xlfn.XLOOKUP(A11,'2022'!A:A,'2022'!E:E) -> 0 | P11: =_xlfn.XLOOKUP(A11,'2023'!B:B,'2023'!G:G) -> 0 | Q11: =_xlfn.XLOOKUP(A11,'2024'!B:B,'2024'!BH:BH) -> 0 | R11: =_xlfn.XLOOKUP(A11,'2025'!A:A,'2025'!B:B) -> 0 | S11: =_xlfn.XLOOKUP(A11,'2021'!A:A,'2021'!X:X) | T11: =_xlfn.XLOOKUP(A11,'2022'!A:A,'2022'!X:X) | U11: =_xlfn.XLOOKUP(A11,'2023'!B:B,'2023'!AF:AF) -> 1 | V11: =_xlfn.XLOOKUP(A11,'2024'!B:B,'2024'!BW:BW) -> 1 | W11: =_xlfn.XLOOKUP(A11,'2025'!A:A,'2025'!C:C) -> 1 | X11: =_xlfn.XLOOKUP(A11,'2021'!A:A,'2021'!V:V) | Y11: =_xlfn.XLOOKUP(A11,'2022'!A:A,'2022'!W:W) | Z11: =_xlfn.XLOOKUP(A11,'2023'!B:B,'2023'!AE:AE) | AA11: =_xlfn.XLOOKUP(A11,'2024'!B:B,'2024'!AZ:AZ) -> 1 | AB11: =_xlfn.XLOOKUP(A11,'2025'!A:A,'2025'!F:F) -> 0
A12: Abbott Laboratories | E12: =_xlfn.XLOOKUP(A12,'2022'!A:A,'2022'!AA:AA) | F12: =_xlfn.XLOOKUP(A12,'2023'!B:B,'2023'!AG:AG) -> 0 | G12: =_xlfn.XLOOKUP(A12,'2024'!B:B,'2024'!BL:BL) -> 0 | H12: =_xlfn.XLOOKUP(A12,'2025'!A:A,'2025'!G:G) -> 0 | I12: =_xlfn.XLOOKUP(A12,'2021'!A:A,'2021'!U:U) | J12: =_xlfn.XLOOKUP(A12,'2022'!A:A,'2022'!V:V) | K12: =_xlfn.XLOOKUP(A12,'2023'!B:B,'2023'!AD:AD) | L12: =_xlfn.XLOOKUP(A12,'2024'!B:B,'2024'!AV:AV) | M12: =_xlfn.XLOOKUP(A12,'2025'!A:A,'2025'!G:G) -> 0 | N12: =_xlfn.XLOOKUP(A12,'2021'!A:A,'2021'!E:E) -> 0 | O12: =_xlfn.XLOOKUP(A12,'2022'!A:A,'2022'!E:E) -> 0 | P12: =_xlfn.XLOOKUP(A12,'2023'!B:B,'2023'!G:G) -> 0 | Q12: =_xlfn.XLOOKUP(A12,'2024'!B:B,'2024'!BH:BH) -> 0 | R12: =_xlfn.XLOOKUP(A12,'2025'!A:A,'2025'!B:B) -> 0 | S12: =_xlfn.XLOOKUP(A12,'2021'!A:A,'2021'!X:X) | T12: =_xlfn.XLOOKUP(A12,'2022'!A:A,'2022'!X:X) | U12: =_xlfn.XLOOKUP(A12,'2023'!B:B,'2023'!AF:AF) -> 1 | V12: =_xlfn.XLOOKUP(A12,'2024'!B:B,'2024'!BW:BW) -> 1 | W12: =_xlfn.XLOOKUP(A12,'2025'!A:A,'2025'!C:C) -> 0 | X12: =_xlfn.XLOOKUP(A12,'2021'!A:A,'2021'!V:V) | Y12: =_xlfn.XLOOKUP(A12,'2022'!A:A,'2022'!W:W) | Z12: =_xlfn.XLOOKUP(A12,'2023'!B:B,'2023'!AE:AE) | AA12: =_xlfn.XLOOKUP(A12,'2024'!B:B,'2024'!AZ:AZ) -> 0 | AB12: =_xlfn.XLOOKUP(A12,'2025'!A:A,'2025'!F:F) -> 1
A13: Accenture | E13: =_xlfn.XLOOKUP(A13,'2022'!A:A,'2022'!AA:AA) | F13: =_xlfn.XLOOKUP(A13,'2023'!B:B,'2023'!AG:AG) -> 0 | G13: =_xlfn.XLOOKUP(A13,'2024'!B:B,'2024'!BL:BL) -> 1 | H13: =_xlfn.XLOOKUP(A13,'2025'!A:A,'2025'!G:G) -> 0 | I13: =_xlfn.XLOOKUP(A13,'2021'!A:A,'2021'!U:U) | J13: =_xlfn.XLOOKUP(A13,'2022'!A:A,'2022'!V:V) | K13: =_xlfn.XLOOKUP(A13,'2023'!B:B,'2023'!AD:AD) | L13: =_xlfn.XLOOKUP(A13,'2024'!B:B,'2024'!AV:AV) | M13: =_xlfn.XLOOKUP(A13,'2025'!A:A,'2025'!G:G) -> 0 | N13: =_xlfn.XLOOKUP(A13,'2021'!A:A,'2021'!E:E) -> Y | O13: =_xlfn.XLOOKUP(A13,'2022'!A:A,'2022'!E:E) -> Y | P13: =_xlfn.XLOOKUP(A13,'2023'!B:B,'2023'!G:G) -> Y | Q13: =_xlfn.XLOOKUP(A13,'2024'!B:B,'2024'!BH:BH) -> 1 | R13: =_xlfn.XLOOKUP(A13,'2025'!A:A,'2025'!B:B) -> 1 | S13: =_xlfn.XLOOKUP(A13,'2021'!A:A,'2021'!X:X) -> 1 | T13: =_xlfn.XLOOKUP(A13,'2022'!A:A,'2022'!X:X) -> 1 | U13: =_xlfn.XLOOKUP(A13,'2023'!B:B,'2023'!AF:AF) -> 1 | V13: =_xlfn.XLOOKUP(A13,'2024'!B:B,'2024'!BW:BW) -> 1 | W13: =_xlfn.XLOOKUP(A13,'2025'!A:A,'2025'!C:C) -> 1 | X13: =_xlfn.XLOOKUP(A13,'2021'!A:A,'2021'!V:V) -> 1 | Y13: =_xlfn.XLOOKUP(A13,'2022'!A:A,'2022'!W:W) -> 1 | Z13: =_xlfn.XLOOKUP(A13,'2023'!B:B,'2023'!AE:AE) -> 1 | AA13: =_xlfn.XLOOKUP(A13,'2024'!B:B,'2024'!AZ:AZ) -> 1 | AB13: =_xlfn.XLOOKUP(A13,'2025'!A:A,'2025'!F:F) -> 1
... A652: Zurich Insurance Group | E652: =_xlfn.XLOOKUP(A652,'2022'!A:A,'2022'!AA:AA) -> Y | F652: =_xlfn.XLOOKUP(A652,'2023'!B:B,'2023'!AG:AG) -> Y | G652: =_xlfn.XLOOKUP(A652,'2024'!B:B,'2024'!BL:BL) -> 1 | H652: =_xlfn.XLOOKUP(A652,'2025'!A:A,'2025'!G:G) -> 1 | I652: =_xlfn.XLOOKUP(A652,'2021'!A:A,'2021'!U:U) -> 1 | J652: =_xlfn.XLOOKUP(A652,'2022'!A:A,'2022'!V:V) -> 1 | K652: =_xlfn.XLOOKUP(A652,'2023'!B:B,'2023'!AD:AD) | L652: =_xlfn.XLOOKUP(A652,'2024'!B:B,'2024'!AV:AV) | M652: =_xlfn.XLOOKUP(A652,'2025'!A:A,'2025'!G:G) -> 1 | N652: =_xlfn.XLOOKUP(A652,'2021'!A:A,'2021'!E:E) -> Y | O652: =_xlfn.XLOOKUP(A652,'2022'!A:A,'2022'!E:E) -> Y | P652: =_xlfn.XLOOKUP(A652,'2023'!B:B,'2023'!G:G) -> Y | Q652: =_xlfn.XLOOKUP(A652,'2024'!B:B,'2024'!BH:BH) -> 1 | R652: =_xlfn.XLOOKUP(A652,'2025'!A:A,'2025'!B:B) -> 1 | S652: =_xlfn.XLOOKUP(A652,'2021'!A:A,'2021'!X:X) | T652: =_xlfn.XLOOKUP(A652,'2022'!A:A,'2022'!X:X) | U652: =_xlfn.XLOOKUP(A652,'2023'!B:B,'2023'!AF:AF) | V652: =_xlfn.XLOOKUP(A652,'2024'!B:B,'2024'!BW:BW) | W652: =_xlfn.XLOOKUP(A652,'2025'!A:A,'2025'!C:C) -> 0 | X652: =_xlfn.XLOOKUP(A652,'2021'!A:A,'2021'!V:V) -> 1 | Y652: =_xlfn.XLOOKUP(A652,'2022'!A:A,'2022'!W:W) -> 1 | Z652: =_xlfn.XLOOKUP(A652,'2023'!B:B,'2023'!AE:AE) -> 1 | AA652: =_xlfn.XLOOKUP(A652,'2024'!B:B,'2024'!AZ:AZ) -> 1 | AB652: =_xlfn.XLOOKUP(A652,'2025'!A:A,'2025'!F:F) -> 1
E653: =_xlfn.XLOOKUP(A653,'2022'!A:A,'2022'!AA:AA) -> #N/A | F653: =_xlfn.XLOOKUP(A653,'2023'!B:B,'2023'!AG:AG) -> #N/A | G653: =_xlfn.XLOOKUP(A653,'2024'!B:B,'2024'!BL:BL) -> #N/A | H653: =_xlfn.XLOOKUP(A653,'2025'!A:A,'2025'!G:G) | I653: =_xlfn.XLOOKUP(A653,'2021'!A:A,'2021'!U:U) -> #N/A | J653: =_xlfn.XLOOKUP(A653,'2022'!A:A,'2022'!V:V) -> #N/A | K653: =_xlfn.XLOOKUP(A653,'2023'!B:B,'2023'!AD:AD) -> #N/A | L653: =_xlfn.XLOOKUP(A653,'2024'!B:B,'2024'!AV:AV) -> #N/A | M653: =_xlfn.XLOOKUP(A653,'2025'!A:A,'2025'!G:G) | N653: =_xlfn.XLOOKUP(A653,'2021'!A:A,'2021'!E:E) -> #N/A | O653: =_xlfn.XLOOKUP(A653,'2022'!A:A,'2022'!E:E) -> #N/A | P653: =_xlfn.XLOOKUP(A653,'2023'!B:B,'2023'!G:G) -> #N/A | Q653: =_xlfn.XLOOKUP(A653,'2024'!B:B,'2024'!BH:BH) -> #N/A | R653: =_xlfn.XLOOKUP(A653,'2025'!A:A,'2025'!B:B) | S653: =_xlfn.XLOOKUP(A653,'2021'!A:A,'2021'!X:X) -> #N/A | T653: =_xlfn.XLOOKUP(A653,'2022'!A:A,'2022'!X:X) -> #N/A | U653: =_xlfn.XLOOKUP(A653,'2023'!B:B,'2023'!AF:AF) -> #N/A | V653: =_xlfn.XLOOKUP(A653,'2024'!B:B,'2024'!BW:BW) -> #N/A | W653: =_xlfn.XLOOKUP(A653,'2025'!A:A,'2025'!C:C) | X653: =_xlfn.XLOOKUP(A653,'2021'!A:A,'2021'!V:V) -> #N/A | Y653: =_xlfn.XLOOKUP(A653,'2022'!A:A,'2022'!W:W) -> #N/A | Z653: =_xlfn.XLOOKUP(A653,'2023'!B:B,'2023'!AE:AE) -> #N/A | AA653: =_xlfn.XLOOKUP(A653,'2024'!B:B,'2024'!AZ:AZ) -> #N/A | AB653: =_xlfn.XLOOKUP(A653,'2025'!A:A,'2025'!F:F)
E654: =_xlfn.XLOOKUP(A654,'2022'!A:A,'2022'!AA:AA) -> #N/A | F654: =_xlfn.XLOOKUP(A654,'2023'!B:B,'2023'!AG:AG) -> #N/A | G654: =_xlfn.XLOOKUP(A654,'2024'!B:B,'2024'!BL:BL) -> #N/A | H654: =_xlfn.XLOOKUP(A654,'2025'!A:A,'2025'!G:G) | I654: =_xlfn.XLOOKUP(A654,'2021'!A:A,'2021'!U:U) -> #N/A | J654: =_xlfn.XLOOKUP(A654,'2022'!A:A,'2022'!V:V) -> #N/A | K654: =_xlfn.XLOOKUP(A654,'2023'!B:B,'2023'!AD:AD) -> #N/A | L654: =_xlfn.XLOOKUP(A654,'2024'!B:B,'2024'!AV:AV) -> #N/A | M654: =_xlfn.XLOOKUP(A654,'2025'!A:A,'2025'!G:G) | N654: =_xlfn.XLOOKUP(A654,'2021'!A:A,'2021'!E:E) -> #N/A | O654: =_xlfn.XLOOKUP(A654,'2022'!A:A,'2022'!E:E) -> #N/A | P654: =_xlfn.XLOOKUP(A654,'2023'!B:B,'2023'!G:G) -> #N/A | Q654: =_xlfn.XLOOKUP(A654,'2024'!B:B,'2024'!BH:BH) -> #N/A | R654: =_xlfn.XLOOKUP(A654,'2025'!A:A,'2025'!B:B) | S654: =_xlfn.XLOOKUP(A654,'2021'!A:A,'2021'!X:X) -> #N/A | T654: =_xlfn.XLOOKUP(A654,'2022'!A:A,'2022'!X:X) -> #N/A | U654: =_xlfn.XLOOKUP(A654,'2023'!B:B,'2023'!AF:AF) -> #N/A | V654: =_xlfn.XLOOKUP(A654,'2024'!B:B,'2024'!BW:BW) -> #N/A | W654: =_xlfn.XLOOKUP(A654,'2025'!A:A,'2025'!C:C) | X654: =_xlfn.XLOOKUP(A654,'2021'!A:A,'2021'!V:V) -> #N/A | Y654: =_xlfn.XLOOKUP(A654,'2022'!A:A,'2022'!W:W) -> #N/A | Z654: =_xlfn.XLOOKUP(A654,'2023'!B:B,'2023'!AE:AE) -> #N/A | AA654: =_xlfn.XLOOKUP(A654,'2024'!B:B,'2024'!AZ:AZ) -> #N/A | AB654: =_xlfn.XLOOKUP(A654,'2025'!A:A,'2025'!F:F)
E655: =_xlfn.XLOOKUP(A655,'2022'!A:A,'2022'!AA:AA) -> #N/A | F655: =_xlfn.XLOOKUP(A655,'2023'!B:B,'2023'!AG:AG) -> #N/A | G655: =_xlfn.XLOOKUP(A655,'2024'!B:B,'2024'!BL:BL) -> #N/A | H655: =_xlfn.XLOOKUP(A655,'2025'!A:A,'2025'!G:G) | I655: =_xlfn.XLOOKUP(A655,'2021'!A:A,'2021'!U:U) -> #N/A | J655: =_xlfn.XLOOKUP(A655,'2022'!A:A,'2022'!V:V) -> #N/A | K655: =_xlfn.XLOOKUP(A655,'2023'!B:B,'2023'!AD:AD) -> #N/A | L655: =_xlfn.XLOOKUP(A655,'2024'!B:B,'2024'!AV:AV) -> #N/A | M655: =_xlfn.XLOOKUP(A655,'2025'!A:A,'2025'!G:G) | N655: =_xlfn.XLOOKUP(A655,'2021'!A:A,'2021'!E:E) -> #N/A | O655: =_xlfn.XLOOKUP(A655,'2022'!A:A,'2022'!E:E) -> #N/A | P655: =_xlfn.XLOOKUP(A655,'2023'!B:B,'2023'!G:G) -> #N/A | Q655: =_xlfn.XLOOKUP(A655,'2024'!B:B,'2024'!BH:BH) -> #N/A | R655: =_xlfn.XLOOKUP(A655,'2025'!A:A,'2025'!B:B) | S655: =_xlfn.XLOOKUP(A655,'2021'!A:A,'2021'!X:X) -> #N/A | T655: =_xlfn.XLOOKUP(A655,'2022'!A:A,'2022'!X:X) -> #N/A | U655: =_xlfn.XLOOKUP(A655,'2023'!B:B,'2023'!AF:AF) -> #N/A | V655: =_xlfn.XLOOKUP(A655,'2024'!B:B,'2024'!BW:BW) -> #N/A | W655: =_xlfn.XLOOKUP(A655,'2025'!A:A,'2025'!C:C) | X655: =_xlfn.XLOOKUP(A655,'2021'!A:A,'2021'!V:V) -> #N/A | Y655: =_xlfn.XLOOKUP(A655,'2022'!A:A,'2022'!W:W) -> #N/A | Z655: =_xlfn.XLOOKUP(A655,'2023'!B:B,'2023'!AE:AE) -> #N/A | AA655: =_xlfn.XLOOKUP(A655,'2024'!B:B,'2024'!AZ:AZ) -> #N/A | AB655: =_xlfn.XLOOKUP(A655,'2025'!A:A,'2025'!F:F)
E656: =_xlfn.XLOOKUP(A656,'2022'!A:A,'2022'!AA:AA) -> #N/A | F656: =_xlfn.XLOOKUP(A656,'2023'!B:B,'2023'!AG:AG) -> #N/A | G656: =_xlfn.XLOOKUP(A656,'2024'!B:B,'2024'!BL:BL) -> #N/A | H656: =_xlfn.XLOOKUP(A656,'2025'!A:A,'2025'!G:G) | I656: =_xlfn.XLOOKUP(A656,'2021'!A:A,'2021'!U:U) -> #N/A | J656: =_xlfn.XLOOKUP(A656,'2022'!A:A,'2022'!V:V) -> #N/A | K656: =_xlfn.XLOOKUP(A656,'2023'!B:B,'2023'!AD:AD) -> #N/A | L656: =_xlfn.XLOOKUP(A656,'2024'!B:B,'2024'!AV:AV) -> #N/A | M656: =_xlfn.XLOOKUP(A656,'2025'!A:A,'2025'!G:G) | N656: =_xlfn.XLOOKUP(A656,'2021'!A:A,'2021'!E:E) -> #N/A | O656: =_xlfn.XLOOKUP(A656,'2022'!A:A,'2022'!E:E) -> #N/A | P656: =_xlfn.XLOOKUP(A656,'2023'!B:B,'2023'!G:G) -> #N/A | Q656: =_xlfn.XLOOKUP(A656,'2024'!B:B,'2024'!BH:BH) -> #N/A | R656: =_xlfn.XLOOKUP(A656,'2025'!A:A,'2025'!B:B) | S656: =_xlfn.XLOOKUP(A656,'2021'!A:A,'2021'!X:X) -> #N/A | T656: =_xlfn.XLOOKUP(A656,'2022'!A:A,'2022'!X:X) -> #N/A | U656: =_xlfn.XLOOKUP(A656,'2023'!B:B,'2023'!AF:AF) -> #N/A | V656: =_xlfn.XLOOKUP(A656,'2024'!B:B,'2024'!BW:BW) -> #N/A | W656: =_xlfn.XLOOKUP(A656,'2025'!A:A,'2025'!C:C) | X656: =_xlfn.XLOOKUP(A656,'2021'!A:A,'2021'!V:V) -> #N/A | Y656: =_xlfn.XLOOKUP(A656,'2022'!A:A,'2022'!W:W) -> #N/A | Z656: =_xlfn.XLOOKUP(A656,'2023'!B:B,'2023'!AE:AE) -> #N/A | AA656: =_xlfn.XLOOKUP(A656,'2024'!B:B,'2024'!AZ:AZ) -> #N/A | AB656: =_xlfn.XLOOKUP(A656,'2025'!A:A,'2025'!F:F)
E657: =_xlfn.XLOOKUP(A657,'2022'!A:A,'2022'!AA:AA) -> #N/A | F657: =_xlfn.XLOOKUP(A657,'2023'!B:B,'2023'!AG:AG) -> #N/A | G657: =_xlfn.XLOOKUP(A657,'2024'!B:B,'2024'!BL:BL) -> #N/A | H657: =_xlfn.XLOOKUP(A657,'2025'!A:A,'2025'!G:G) | I657: =_xlfn.XLOOKUP(A657,'2021'!A:A,'2021'!U:U) -> #N/A | J657: =_xlfn.XLOOKUP(A657,'2022'!A:A,'2022'!V:V) -> #N/A | K657: =_xlfn.XLOOKUP(A657,'2023'!B:B,'2023'!AD:AD) -> #N/A | L657: =_xlfn.XLOOKUP(A657,'2024'!B:B,'2024'!AV:AV) -> #N/A | M657: =_xlfn.XLOOKUP(A657,'2025'!A:A,'2025'!G:G) | N657: =_xlfn.XLOOKUP(A657,'2021'!A:A,'2021'!E:E) -> #N/A | O657: =_xlfn.XLOOKUP(A657,'2022'!A:A,'2022'!E:E) -> #N/A | P657: =_xlfn.XLOOKUP(A657,'2023'!B:B,'2023'!G:G) -> #N/A | Q657: =_xlfn.XLOOKUP(A657,'2024'!B:B,'2024'!BH:BH) -> #N/A | R657: =_xlfn.XLOOKUP(A657,'2025'!A:A,'2025'!B:B) | S657: =_xlfn.XLOOKUP(A657,'2021'!A:A,'2021'!X:X) -> #N/A | T657: =_xlfn.XLOOKUP(A657,'2022'!A:A,'2022'!X:X) -> #N/A | U657: =_xlfn.XLOOKUP(A657,'2023'!B:B,'2023'!AF:AF) -> #N/A | V657: =_xlfn.XLOOKUP(A657,'2024'!B:B,'2024'!BW:BW) -> #N/A | W657: =_xlfn.XLOOKUP(A657,'2025'!A:A,'2025'!C:C) | X657: =_xlfn.XLOOKUP(A657,'2021'!A:A,'2021'!V:V) -> #N/A | Y657: =_xlfn.XLOOKUP(A657,'2022'!A:A,'2022'!W:W) -> #N/A | Z657: =_xlfn.XLOOKUP(A657,'2023'!B:B,'2023'!AE:AE) -> #N/A | AA657: =_xlfn.XLOOKUP(A657,'2024'!B:B,'2024'!AZ:AZ) -> #N/A | AB657: =_xlfn.XLOOKUP(A657,'2025'!A:A,'2025'!F:F)
E658: =_xlfn.XLOOKUP(A658,'2022'!A:A,'2022'!AA:AA) -> #N/A | F658: =_xlfn.XLOOKUP(A658,'2023'!B:B,'2023'!AG:AG) -> #N/A | G658: =_xlfn.XLOOKUP(A658,'2024'!B:B,'2024'!BL:BL) -> #N/A | H658: =_xlfn.XLOOKUP(A658,'2025'!A:A,'2025'!G:G) | I658: =_xlfn.XLOOKUP(A658,'2021'!A:A,'2021'!U:U) -> #N/A | J658: =_xlfn.XLOOKUP(A658,'2022'!A:A,'2022'!V:V) -> #N/A | K658: =_xlfn.XLOOKUP(A658,'2023'!B:B,'2023'!AD:AD) -> #N/A | L658: =_xlfn.XLOOKUP(A658,'2024'!B:B,'2024'!AV:AV) -> #N/A | M658: =_xlfn.XLOOKUP(A658,'2025'!A:A,'2025'!G:G) | N658: =_xlfn.XLOOKUP(A658,'2021'!A:A,'2021'!E:E) -> #N/A | O658: =_xlfn.XLOOKUP(A658,'2022'!A:A,'2022'!E:E) -> #N/A | P658: =_xlfn.XLOOKUP(A658,'2023'!B:B,'2023'!G:G) -> #N/A | Q658: =_xlfn.XLOOKUP(A658,'2024'!B:B,'2024'!BH:BH) -> #N/A | R658: =_xlfn.XLOOKUP(A658,'2025'!A:A,'2025'!B:B) | S658: =_xlfn.XLOOKUP(A658,'2021'!A:A,'2021'!X:X) -> #N/A | T658: =_xlfn.XLOOKUP(A658,'2022'!A:A,'2022'!X:X) -> #N/A | U658: =_xlfn.XLOOKUP(A658,'2023'!B:B,'2023'!AF:AF) -> #N/A | V658: =_xlfn.XLOOKUP(A658,'2024'!B:B,'2024'!BW:BW) -> #N/A | W658: =_xlfn.XLOOKUP(A658,'2025'!A:A,'2025'!C:C) | X658: =_xlfn.XLOOKUP(A658,'2021'!A:A,'2021'!V:V) -> #N/A | Y658: =_xlfn.XLOOKUP(A658,'2022'!A:A,'2022'!W:W) -> #N/A | Z658: =_xlfn.XLOOKUP(A658,'2023'!B:B,'2023'!AE:AE) -> #N/A | AA658: =_xlfn.XLOOKUP(A658,'2024'!B:B,'2024'!AZ:AZ) -> #N/A | AB658: =_xlfn.XLOOKUP(A658,'2025'!A:A,'2025'!F:F)
E659: =_xlfn.XLOOKUP(A659,'2022'!A:A,'2022'!AA:AA) -> #N/A | F659: =_xlfn.XLOOKUP(A659,'2023'!B:B,'2023'!AG:AG) -> #N/A | G659: =_xlfn.XLOOKUP(A659,'2024'!B:B,'2024'!BL:BL) -> #N/A | H659: =_xlfn.XLOOKUP(A659,'2025'!A:A,'2025'!G:G) | I659: =_xlfn.XLOOKUP(A659,'2021'!A:A,'2021'!U:U) -> #N/A | J659: =_xlfn.XLOOKUP(A659,'2022'!A:A,'2022'!V:V) -> #N/A | K659: =_xlfn.XLOOKUP(A659,'2023'!B:B,'2023'!AD:AD) -> #N/A | L659: =_xlfn.XLOOKUP(A659,'2024'!B:B,'2024'!AV:AV) -> #N/A | M659: =_xlfn.XLOOKUP(A659,'2025'!A:A,'2025'!G:G) | N659: =_xlfn.XLOOKUP(A659,'2021'!A:A,'2021'!E:E) -> #N/A | O659: =_xlfn.XLOOKUP(A659,'2022'!A:A,'2022'!E:E) -> #N/A | P659: =_xlfn.XLOOKUP(A659,'2023'!B:B,'2023'!G:G) -> #N/A | Q659: =_xlfn.XLOOKUP(A659,'2024'!B:B,'2024'!BH:BH) -> #N/A | R659: =_xlfn.XLOOKUP(A659,'2025'!A:A,'2025'!B:B) | S659: =_xlfn.XLOOKUP(A659,'2021'!A:A,'2021'!X:X) -> #N/A | T659: =_xlfn.XLOOKUP(A659,'2022'!A:A,'2022'!X:X) -> #N/A | U659: =_xlfn.XLOOKUP(A659,'2023'!B:B,'2023'!AF:AF) -> #N/A | V659: =_xlfn.XLOOKUP(A659,'2024'!B:B,'2024'!BW:BW) -> #N/A | W659: =_xlfn.XLOOKUP(A659,'2025'!A:A,'2025'!C:C) | X659: =_xlfn.XLOOKUP(A659,'2021'!A:A,'2021'!V:V) -> #N/A | Y659: =_xlfn.XLOOKUP(A659,'2022'!A:A,'2022'!W:W) -> #N/A | Z659: =_xlfn.XLOOKUP(A659,'2023'!B:B,'2023'!AE:AE) -> #N/A | AA659: =_xlfn.XLOOKUP(A659,'2024'!B:B,'2024'!AZ:AZ) -> #N/A | AB659: =_xlfn.XLOOKUP(A659,'2025'!A:A,'2025'!F:F)
E660: =_xlfn.XLOOKUP(A660,'2022'!A:A,'2022'!AA:AA) -> #N/A | F660: =_xlfn.XLOOKUP(A660,'2023'!B:B,'2023'!AG:AG) -> #N/A | G660: =_xlfn.XLOOKUP(A660,'2024'!B:B,'2024'!BL:BL) -> #N/A | H660: =_xlfn.XLOOKUP(A660,'2025'!A:A,'2025'!G:G) | I660: =_xlfn.XLOOKUP(A660,'2021'!A:A,'2021'!U:U) -> #N/A | J660: =_xlfn.XLOOKUP(A660,'2022'!A:A,'2022'!V:V) -> #N/A | K660: =_xlfn.XLOOKUP(A660,'2023'!B:B,'2023'!AD:AD) -> #N/A | L660: =_xlfn.XLOOKUP(A660,'2024'!B:B,'2024'!AV:AV) -> #N/A | M660: =_xlfn.XLOOKUP(A660,'2025'!A:A,'2025'!G:G) | N660: =_xlfn.XLOOKUP(A660,'2021'!A:A,'2021'!E:E) -> #N/A | O660: =_xlfn.XLOOKUP(A660,'2022'!A:A,'2022'!E:E) -> #N/A | P660: =_xlfn.XLOOKUP(A660,'2023'!B:B,'2023'!G:G) -> #N/A | Q660: =_xlfn.XLOOKUP(A660,'2024'!B:B,'2024'!BH:BH) -> #N/A | R660: =_xlfn.XLOOKUP(A660,'2025'!A:A,'2025'!B:B) | S660: =_xlfn.XLOOKUP(A660,'2021'!A:A,'2021'!X:X) -> #N/A | T660: =_xlfn.XLOOKUP(A660,'2022'!A:A,'2022'!X:X) -> #N/A | U660: =_xlfn.XLOOKUP(A660,'2023'!B:B,'2023'!AF:AF) -> #N/A | V660: =_xlfn.XLOOKUP(A660,'2024'!B:B,'2024'!BW:BW) -> #N/A | W660: =_xlfn.XLOOKUP(A660,'2025'!A:A,'2025'!C:C) | X660: =_xlfn.XLOOKUP(A660,'2021'!A:A,'2021'!V:V) -> #N/A | Y660: =_xlfn.XLOOKUP(A660,'2022'!A:A,'2022'!W:W) -> #N/A | Z660: =_xlfn.XLOOKUP(A660,'2023'!B:B,'2023'!AE:AE) -> #N/A | AA660: =_xlfn.XLOOKUP(A660,'2024'!B:B,'2024'!AZ:AZ) -> #N/A | AB660: =_xlfn.XLOOKUP(A660,'2025'!A:A,'2025'!F:F)
E661: =_xlfn.XLOOKUP(A661,'2022'!A:A,'2022'!AA:AA) -> #N/A | F661: =_xlfn.XLOOKUP(A661,'2023'!B:B,'2023'!AG:AG) -> #N/A | G661: =_xlfn.XLOOKUP(A661,'2024'!B:B,'2024'!BL:BL) -> #N/A | H661: =_xlfn.XLOOKUP(A661,'2025'!A:A,'2025'!G:G) | I661: =_xlfn.XLOOKUP(A661,'2021'!A:A,'2021'!U:U) -> #N/A | J661: =_xlfn.XLOOKUP(A661,'2022'!A:A,'2022'!V:V) -> #N/A | K661: =_xlfn.XLOOKUP(A661,'2023'!B:B,'2023'!AD:AD) -> #N/A | L661: =_xlfn.XLOOKUP(A661,'2024'!B:B,'2024'!AV:AV) -> #N/A | M661: =_xlfn.XLOOKUP(A661,'2025'!A:A,'2025'!G:G) | N661: =_xlfn.XLOOKUP(A661,'2021'!A:A,'2021'!E:E) -> #N/A | O661: =_xlfn.XLOOKUP(A661,'2022'!A:A,'2022'!E:E) -> #N/A | P661: =_xlfn.XLOOKUP(A661,'2023'!B:B,'2023'!G:G) -> #N/A | Q661: =_xlfn.XLOOKUP(A661,'2024'!B:B,'2024'!BH:BH) -> #N/A | R661: =_xlfn.XLOOKUP(A661,'2025'!A:A,'2025'!B:B) | S661: =_xlfn.XLOOKUP(A661,'2021'!A:A,'2021'!X:X) -> #N/A | T661: =_xlfn.XLOOKUP(A661,'2022'!A:A,'2022'!X:X) -> #N/A | U661: =_xlfn.XLOOKUP(A661,'2023'!B:B,'2023'!AF:AF) -> #N/A | V661: =_xlfn.XLOOKUP(A661,'2024'!B:B,'2024'!BW:BW) -> #N/A | W661: =_xlfn.XLOOKUP(A661,'2025'!A:A,'2025'!C:C) | X661: =_xlfn.XLOOKUP(A661,'2021'!A:A,'2021'!V:V) -> #N/A | Y661: =_xlfn.XLOOKUP(A661,'2022'!A:A,'2022'!W:W) -> #N/A | Z661: =_xlfn.XLOOKUP(A661,'2023'!B:B,'2023'!AE:AE) -> #N/A | AA661: =_xlfn.XLOOKUP(A661,'2024'!B:B,'2024'!AZ:AZ) -> #N/A | AB661: =_xlfn.XLOOKUP(A661,'2025'!A:A,'2025'!F:F)
E662: =_xlfn.XLOOKUP(A662,'2022'!A:A,'2022'!AA:AA) -> #N/A | F662: =_xlfn.XLOOKUP(A662,'2023'!B:B,'2023'!AG:AG) -> #N/A | G662: =_xlfn.XLOOKUP(A662,'2024'!B:B,'2024'!BL:BL) -> #N/A | H662: =_xlfn.XLOOKUP(A662,'2025'!A:A,'2025'!G:G) | I662: =_xlfn.XLOOKUP(A662,'2021'!A:A,'2021'!U:U) -> #N/A | J662: =_xlfn.XLOOKUP(A662,'2022'!A:A,'2022'!V:V) -> #N/A | K662: =_xlfn.XLOOKUP(A662,'2023'!B:B,'2023'!AD:AD) -> #N/A | L662: =_xlfn.XLOOKUP(A662,'2024'!B:B,'2024'!AV:AV) -> #N/A | M662: =_xlfn.XLOOKUP(A662,'2025'!A:A,'2025'!G:G) | N662: =_xlfn.XLOOKUP(A662,'2021'!A:A,'2021'!E:E) -> #N/A | O662: =_xlfn.XLOOKUP(A662,'2022'!A:A,'2022'!E:E) -> #N/A | P662: =_xlfn.XLOOKUP(A662,'2023'!B:B,'2023'!G:G) -> #N/A | Q662: =_xlfn.XLOOKUP(A662,'2024'!B:B,'2024'!BH:BH) -> #N/A | R662: =_xlfn.XLOOKUP(A662,'2025'!A:A,'2025'!B:B) | S662: =_xlfn.XLOOKUP(A662,'2021'!A:A,'2021'!X:X) -> #N/A | T662: =_xlfn.XLOOKUP(A662,'2022'!A:A,'2022'!X:X) -> #N/A | U662: =_xlfn.XLOOKUP(A662,'2023'!B:B,'2023'!AF:AF) -> #N/A | V662: =_xlfn.XLOOKUP(A662,'2024'!B:B,'2024'!BW:BW) -> #N/A | W662: =_xlfn.XLOOKUP(A662,'2025'!A:A,'2025'!C:C) | X662: =_xlfn.XLOOKUP(A662,'2021'!A:A,'2021'!V:V) -> #N/A | Y662: =_xlfn.XLOOKUP(A662,'2022'!A:A,'2022'!W:W) -> #N/A | Z662: =_xlfn.XLOOKUP(A662,'2023'!B:B,'2023'!AE:AE) -> #N/A | AA662: =_xlfn.XLOOKUP(A662,'2024'!B:B,'2024'!AZ:AZ) -> #N/A | AB662: =_xlfn.XLOOKUP(A662,'2025'!A:A,'2025'!F:F)
E663: =_xlfn.XLOOKUP(A663,'2022'!A:A,'2022'!AA:AA) -> #N/A | F663: =_xlfn.XLOOKUP(A663,'2023'!B:B,'2023'!AG:AG) -> #N/A | G663: =_xlfn.XLOOKUP(A663,'2024'!B:B,'2024'!BL:BL) -> #N/A | H663: =_xlfn.XLOOKUP(A663,'2025'!A:A,'2025'!G:G) | I663: =_xlfn.XLOOKUP(A663,'2021'!A:A,'2021'!U:U) -> #N/A | J663: =_xlfn.XLOOKUP(A663,'2022'!A:A,'2022'!V:V) -> #N/A | K663: =_xlfn.XLOOKUP(A663,'2023'!B:B,'2023'!AD:AD) -> #N/A | L663: =_xlfn.XLOOKUP(A663,'2024'!B:B,'2024'!AV:AV) -> #N/A | M663: =_xlfn.XLOOKUP(A663,'2025'!A:A,'2025'!G:G) | N663: =_xlfn.XLOOKUP(A663,'2021'!A:A,'2021'!E:E) -> #N/A | O663: =_xlfn.XLOOKUP(A663,'2022'!A:A,'2022'!E:E) -> #N/A | P663: =_xlfn.XLOOKUP(A663,'2023'!B:B,'2023'!G:G) -> #N/A | Q663: =_xlfn.XLOOKUP(A663,'2024'!B:B,'2024'!BH:BH) -> #N/A | R663: =_xlfn.XLOOKUP(A663,'2025'!A:A,'2025'!B:B) | S663: =_xlfn.XLOOKUP(A663,'2021'!A:A,'2021'!X:X) -> #N/A | T663: =_xlfn.XLOOKUP(A663,'2022'!A:A,'2022'!X:X) -> #N/A | U663: =_xlfn.XLOOKUP(A663,'2023'!B:B,'2023'!AF:AF) -> #N/A | V663: =_xlfn.XLOOKUP(A663,'2024'!B:B,'2024'!BW:BW) -> #N/A | W663: =_xlfn.XLOOKUP(A663,'2025'!A:A,'2025'!C:C) | X663: =_xlfn.XLOOKUP(A663,'2021'!A:A,'2021'!V:V) -> #N/A | Y663: =_xlfn.XLOOKUP(A663,'2022'!A:A,'2022'!W:W) -> #N/A | Z663: =_xlfn.XLOOKUP(A663,'2023'!B:B,'2023'!AE:AE) -> #N/A | AA663: =_xlfn.XLOOKUP(A663,'2024'!B:B,'2024'!AZ:AZ) -> #N/A | AB663: =_xlfn.XLOOKUP(A663,'2025'!A:A,'2025'!F:F)
E664: =_xlfn.XLOOKUP(A664,'2022'!A:A,'2022'!AA:AA) -> #N/A | F664: =_xlfn.XLOOKUP(A664,'2023'!B:B,'2023'!AG:AG) -> #N/A | G664: =_xlfn.XLOOKUP(A664,'2024'!B:B,'2024'!BL:BL) -> #N/A | H664: =_xlfn.XLOOKUP(A664,'2025'!A:A,'2025'!G:G) | I664: =_xlfn.XLOOKUP(A664,'2021'!A:A,'2021'!U:U) -> #N/A | J664: =_xlfn.XLOOKUP(A664,'2022'!A:A,'2022'!V:V) -> #N/A | K664: =_xlfn.XLOOKUP(A664,'2023'!B:B,'2023'!AD:AD) -> #N/A | L664: =_xlfn.XLOOKUP(A664,'2024'!B:B,'2024'!AV:AV) -> #N/A | M664: =_xlfn.XLOOKUP(A664,'2025'!A:A,'2025'!G:G) | N664: =_xlfn.XLOOKUP(A664,'2021'!A:A,'2021'!E:E) -> #N/A | O664: =_xlfn.XLOOKUP(A664,'2022'!A:A,'2022'!E:E) -> #N/A | P664: =_xlfn.XLOOKUP(A664,'2023'!B:B,'2023'!G:G) -> #N/A | Q664: =_xlfn.XLOOKUP(A664,'2024'!B:B,'2024'!BH:BH) -> #N/A | R664: =_xlfn.XLOOKUP(A664,'2025'!A:A,'2025'!B:B) | S664: =_xlfn.XLOOKUP(A664,'2021'!A:A,'2021'!X:X) -> #N/A | T664: =_xlfn.XLOOKUP(A664,'2022'!A:A,'2022'!X:X) -> #N/A | U664: =_xlfn.XLOOKUP(A664,'2023'!B:B,'2023'!AF:AF) -> #N/A | V664: =_xlfn.XLOOKUP(A664,'2024'!B:B,'2024'!BW:BW) -> #N/A | W664: =_xlfn.XLOOKUP(A664,'2025'!A:A,'2025'!C:C) | X664: =_xlfn.XLOOKUP(A664,'2021'!A:A,'2021'!V:V) -> #N/A | Y664: =_xlfn.XLOOKUP(A664,'2022'!A:A,'2022'!W:W) -> #N/A | Z664: =_xlfn.XLOOKUP(A664,'2023'!B:B,'2023'!AE:AE) -> #N/A | AA664: =_xlfn.XLOOKUP(A664,'2024'!B:B,'2024'!AZ:AZ) -> #N/A | AB664: =_xlfn.XLOOKUP(A664,'2025'!A:A,'2025'!F:F)
... E685: =_xlfn.XLOOKUP(A685,'2022'!A:A,'2022'!AA:AA) -> #N/A | F685: =_xlfn.XLOOKUP(A685,'2023'!B:B,'2023'!AG:AG) -> #N/A | G685: =_xlfn.XLOOKUP(A685,'2024'!B:B,'2024'!BL:BL) -> #N/A | H685: =_xlfn.XLOOKUP(A685,'2025'!A:A,'2025'!G:G) | I685: =_xlfn.XLOOKUP(A685,'2021'!A:A,'2021'!U:U) -> #N/A | J685: =_xlfn.XLOOKUP(A685,'2022'!A:A,'2022'!V:V) -> #N/A | K685: =_xlfn.XLOOKUP(A685,'2023'!B:B,'2023'!AD:AD) -> #N/A | L685: =_xlfn.XLOOKUP(A685,'2024'!B:B,'2024'!AV:AV) -> #N/A | M685: =_xlfn.XLOOKUP(A685,'2025'!A:A,'2025'!G:G) | N685: =_xlfn.XLOOKUP(A685,'2021'!A:A,'2021'!E:E) -> #N/A | O685: =_xlfn.XLOOKUP(A685,'2022'!A:A,'2022'!E:E) -> #N/A | P685: =_xlfn.XLOOKUP(A685,'2023'!B:B,'2023'!G:G) -> #N/A | Q685: =_xlfn.XLOOKUP(A685,'2024'!B:B,'2024'!BH:BH) -> #N/A | R685: =_xlfn.XLOOKUP(A685,'2025'!A:A,'2025'!B:B) | S685: =_xlfn.XLOOKUP(A685,'2021'!A:A,'2021'!X:X) -> #N/A | T685: =_xlfn.XLOOKUP(A685,'2022'!A:A,'2022'!X:X) -> #N/A | U685: =_xlfn.XLOOKUP(A685,'2023'!B:B,'2023'!AF:AF) -> #N/A | V685: =_xlfn.XLOOKUP(A685,'2024'!B:B,'2024'!BW:BW) -> #N/A | W685: =_xlfn.XLOOKUP(A685,'2025'!A:A,'2025'!C:C) | X685: =_xlfn.XLOOKUP(A685,'2021'!A:A,'2021'!V:V) -> #N/A | Y685: =_xlfn.XLOOKUP(A685,'2022'!A:A,'2022'!W:W) -> #N/A | Z685: =_xlfn.XLOOKUP(A685,'2023'!B:B,'2023'!AE:AE) -> #N/A | AA685: =_xlfn.XLOOKUP(A685,'2024'!B:B,'2024'!AZ:AZ) -> #N/A | AB685: =_xlfn.XLOOKUP(A685,'2025'!A:A,'2025'!F:F)

Sheet CN_NZ
A1: company | B1: 2021-CN | C1: 2021-NZ | D1: 2022-CN | E1: 2022-NZ | F1: 2023-CN | G1: 2023-NZ | H1: 2024-CN | I1: 2024-NZ | J1: 2025-CN | K1: 2025-NZ
A2: {=_xlfn.UNIQUE(_xlfn.VSTACK('2025'!A3:A502,'2024'!A3:A502,'2023'!B3:B502,'2022'!A3:A502,'2021'!A3:A502))} -> Walmart | B2: =_xlfn.XLOOKUP(A2,'2021'!A:A,'2021'!U:U, "") | C2: =_xlfn.XLOOKUP(A2,'2021'!A:A,'2021'!V:V,"") -> 1 | D2: =_xlfn.XLOOKUP(A2,'2022'!A:A,'2022'!V:V,"") | E2: =_xlfn.XLOOKUP(A2,'2022'!A:A,'2022'!W:W,"") -> 1 | F2: =_xlfn.XLOOKUP(A2,'2023'!B:B,'2023'!AD:AD,"") | G2: =_xlfn.XLOOKUP(A2,'2023'!B:B,'2023'!AE:AE,"") -> 1 | H2: =_xlfn.XLOOKUP(A2,'2024'!B:B,'2024'!AV:AV,"") | I2: =_xlfn.XLOOKUP(A2,'2024'!B:B,'2024'!AZ:AZ,"") -> 1 | J2: =_xlfn.XLOOKUP(A2,'2025'!A:A,'2025'!E:E,"") -> 0 | K2: =_xlfn.XLOOKUP(A2,'2025'!A:A,'2025'!F:F,"") -> 1
A3: Amazon | B3: =_xlfn.XLOOKUP(A3,'2021'!A:A,'2021'!U:U, "") | C3: =_xlfn.XLOOKUP(A3,'2021'!A:A,'2021'!V:V,"") -> 1 | D3: =_xlfn.XLOOKUP(A3,'2022'!A:A,'2022'!V:V,"") | E3: =_xlfn.XLOOKUP(A3,'2022'!A:A,'2022'!W:W,"") -> 1 | F3: =_xlfn.XLOOKUP(A3,'2023'!B:B,'2023'!AD:AD,"") | G3: =_xlfn.XLOOKUP(A3,'2023'!B:B,'2023'!AE:AE,"") -> 1 | H3: =_xlfn.XLOOKUP(A3,'2024'!B:B,'2024'!AV:AV,"") | I3: =_xlfn.XLOOKUP(A3,'2024'!B:B,'2024'!AZ:AZ,"") -> 1 | J3: =_xlfn.XLOOKUP(A3,'2025'!A:A,'2025'!E:E,"") -> 0 | K3: =_xlfn.XLOOKUP(A3,'2025'!A:A,'2025'!F:F,"") -> 1
A4: State Grid | B4: =_xlfn.XLOOKUP(A4,'2021'!A:A,'2021'!U:U, "") | C4: =_xlfn.XLOOKUP(A4,'2021'!A:A,'2021'!V:V,"") | D4: =_xlfn.XLOOKUP(A4,'2022'!A:A,'2022'!V:V,"") | E4: =_xlfn.XLOOKUP(A4,'2022'!A:A,'2022'!W:W,"") | F4: =_xlfn.XLOOKUP(A4,'2023'!B:B,'2023'!AD:AD,"") | G4: =_xlfn.XLOOKUP(A4,'2023'!B:B,'2023'!AE:AE,"") | H4: =_xlfn.XLOOKUP(A4,'2024'!B:B,'2024'!AV:AV,"") | I4: =_xlfn.XLOOKUP(A4,'2024'!B:B,'2024'!AZ:AZ,"") -> 0 | J4: =_xlfn.XLOOKUP(A4,'2025'!A:A,'2025'!E:E,"") -> 0 | K4: =_xlfn.XLOOKUP(A4,'2025'!A:A,'2025'!F:F,"") -> 0
A5: Saudi Aramco | B5: =_xlfn.XLOOKUP(A5,'2021'!A:A,'2021'!U:U, "") | C5: =_xlfn.XLOOKUP(A5,'2021'!A:A,'2021'!V:V,"") | D5: =_xlfn.XLOOKUP(A5,'2022'!A:A,'2022'!V:V,"") | E5: =_xlfn.XLOOKUP(A5,'2022'!A:A,'2022'!W:W,"") -> 1 | F5: =_xlfn.XLOOKUP(A5,'2023'!B:B,'2023'!AD:AD,"") | G5: =_xlfn.XLOOKUP(A5,'2023'!B:B,'2023'!AE:AE,"") -> 1 | H5: =_xlfn.XLOOKUP(A5,'2024'!B:B,'2024'!AV:AV,"") | I5: =_xlfn.XLOOKUP(A5,'2024'!B:B,'2024'!AZ:AZ,"") -> 1 | J5: =_xlfn.XLOOKUP(A5,'2025'!A:A,'2025'!E:E,"") -> 0 | K5: =_xlfn.XLOOKUP(A5,'2025'!A:A,'2025'!F:F,"") -> 1
A6: China National Petroleum | B6: =_xlfn.XLOOKUP(A6,'2021'!A:A,'2021'!U:U, "") | C6: =_xlfn.XLOOKUP(A6,'2021'!A:A,'2021'!V:V,"") -> 1 | D6: =_xlfn.XLOOKUP(A6,'2022'!A:A,'2022'!V:V,"") | E6: =_xlfn.XLOOKUP(A6,'2022'!A:A,'2022'!W:W,"") -> 1 | F6: =_xlfn.XLOOKUP(A6,'2023'!B:B,'2023'!AD:AD,"") | G6: =_xlfn.XLOOKUP(A6,'2023'!B:B,'2023'!AE:AE,"") | H6: =_xlfn.XLOOKUP(A6,'2024'!B:B,'2024'!AV:AV,"") | I6: =_xlfn.XLOOKUP(A6,'2024'!B:B,'2024'!AZ:AZ,"") -> 0 | J6: =_xlfn.XLOOKUP(A6,'2025'!A:A,'2025'!E:E,"") -> 0 | K6: =_xlfn.XLOOKUP(A6,'2025'!A:A,'2025'!F:F,"") -> 1
A7: Sinopec Group | B7: =_xlfn.XLOOKUP(A7,'2021'!A:A,'2021'!U:U, "") -> 1 | C7: =_xlfn.XLOOKUP(A7,'2021'!A:A,'2021'!V:V,"") | D7: =_xlfn.XLOOKUP(A7,'2022'!A:A,'2022'!V:V,"") | E7: =_xlfn.XLOOKUP(A7,'2022'!A:A,'2022'!W:W,"") | F7: =_xlfn.XLOOKUP(A7,'2023'!B:B,'2023'!AD:AD,"") | G7: =_xlfn.XLOOKUP(A7,'2023'!B:B,'2023'!AE:AE,"") | H7: =_xlfn.XLOOKUP(A7,'2024'!B:B,'2024'!AV:AV,"") | I7: =_xlfn.XLOOKUP(A7,'2024'!B:B,'2024'!AZ:AZ,"") -> 0 | J7: =_xlfn.XLOOKUP(A7,'2025'!A:A,'2025'!E:E,"") -> 1 | K7: =_xlfn.XLOOKUP(A7,'2025'!A:A,'2025'!F:F,"") -> 0
A8: UnitedHealth Group | B8: =_xlfn.XLOOKUP(A8,'2021'!A:A,'2021'!U:U, "") | C8: =_xlfn.XLOOKUP(A8,'2021'!A:A,'2021'!V:V,"") | D8: =_xlfn.XLOOKUP(A8,'2022'!A:A,'2022'!V:V,"") | E8: =_xlfn.XLOOKUP(A8,'2022'!A:A,'2022'!W:W,"") -> 1 | F8: =_xlfn.XLOOKUP(A8,'2023'!B:B,'2023'!AD:AD,"") | G8: =_xlfn.XLOOKUP(A8,'2023'!B:B,'2023'!AE:AE,"") -> 1 | H8: =_xlfn.XLOOKUP(A8,'2024'!B:B,'2024'!AV:AV,"") | I8: =_xlfn.XLOOKUP(A8,'2024'!B:B,'2024'!AZ:AZ,"") -> 1 | J8: =_xlfn.XLOOKUP(A8,'2025'!A:A,'2025'!E:E,"") -> 0 | K8: =_xlfn.XLOOKUP(A8,'2025'!A:A,'2025'!F:F,"") -> 1
A9: Apple | B9: =_xlfn.XLOOKUP(A9,'2021'!A:A,'2021'!U:U, "") -> 1 | C9: =_xlfn.XLOOKUP(A9,'2021'!A:A,'2021'!V:V,"") -> 1 | D9: =_xlfn.XLOOKUP(A9,'2022'!A:A,'2022'!V:V,"") -> 1 | E9: =_xlfn.XLOOKUP(A9,'2022'!A:A,'2022'!W:W,"") | F9: =_xlfn.XLOOKUP(A9,'2023'!B:B,'2023'!AD:AD,"") -> 1 | G9: =_xlfn.XLOOKUP(A9,'2023'!B:B,'2023'!AE:AE,"") | H9: =_xlfn.XLOOKUP(A9,'2024'!B:B,'2024'!AV:AV,"") -> 1 | I9: =_xlfn.XLOOKUP(A9,'2024'!B:B,'2024'!AZ:AZ,"") -> 0 | J9: =_xlfn.XLOOKUP(A9,'2025'!A:A,'2025'!E:E,"") -> 1 | K9: =_xlfn.XLOOKUP(A9,'2025'!A:A,'2025'!F:F,"") -> 0
A10: CVS Health | B10: =_xlfn.XLOOKUP(A10,'2021'!A:A,'2021'!U:U, "") | C10: =_xlfn.XLOOKUP(A10,'2021'!A:A,'2021'!V:V,"") | D10: =_xlfn.XLOOKUP(A10,'2022'!A:A,'2022'!V:V,"") -> 1 | E10: =_xlfn.XLOOKUP(A10,'2022'!A:A,'2022'!W:W,"") -> 1 | F10: =_xlfn.XLOOKUP(A10,'2023'!B:B,'2023'!AD:AD,"") | G10: =_xlfn.XLOOKUP(A10,'2023'!B:B,'2023'!AE:AE,"") -> 1 | H10: =_xlfn.XLOOKUP(A10,'2024'!B:B,'2024'!AV:AV,"") | I10: =_xlfn.XLOOKUP(A10,'2024'!B:B,'2024'!AZ:AZ,"") -> 1 | J10: =_xlfn.XLOOKUP(A10,'2025'!A:A,'2025'!E:E,"") -> 0 | K10: =_xlfn.XLOOKUP(A10,'2025'!A:A,'2025'!F:F,"") -> 1
A11: Berkshire Hathaway | B11: =_xlfn.XLOOKUP(A11,'2021'!A:A,'2021'!U:U, "") | C11: =_xlfn.XLOOKUP(A11,'2021'!A:A,'2021'!V:V,"") | D11: =_xlfn.XLOOKUP(A11,'2022'!A:A,'2022'!V:V,"") | E11: =_xlfn.XLOOKUP(A11,'2022'!A:A,'2022'!W:W,"") | F11: =_xlfn.XLOOKUP(A11,'2023'!B:B,'2023'!AD:AD,"") | G11: =_xlfn.XLOOKUP(A11,'2023'!B:B,'2023'!AE:AE,"") | H11: =_xlfn.XLOOKUP(A11,'2024'!B:B,'2024'!AV:AV,"") | I11: =_xlfn.XLOOKUP(A11,'2024'!B:B,'2024'!AZ:AZ,"") -> 0 | J11: =_xlfn.XLOOKUP(A11,'2025'!A:A,'2025'!E:E,"") -> 0 | K11: =_xlfn.XLOOKUP(A11,'2025'!A:A,'2025'!F:F,"") -> 0
A12: McKesson | B12: =_xlfn.XLOOKUP(A12,'2021'!A:A,'2021'!U:U, "") | C12: =_xlfn.XLOOKUP(A12,'2021'!A:A,'2021'!V:V,"") | D12: =_xlfn.XLOOKUP(A12,'2022'!A:A,'2022'!V:V,"") -> 1 | E12: =_xlfn.XLOOKUP(A12,'2022'!A:A,'2022'!W:W,"") | F12: =_xlfn.XLOOKUP(A12,'2023'!B:B,'2023'!AD:AD,"") | G12: =_xlfn.XLOOKUP(A12,'2023'!B:B,'2023'!AE:AE,"") | H12: =_xlfn.XLOOKUP(A12,'2024'!B:B,'2024'!AV:AV,"") | I12: =_xlfn.XLOOKUP(A12,'2024'!B:B,'2024'!AZ:AZ,"") -> 0 | J12: =_xlfn.XLOOKUP(A12,'2025'!A:A,'2025'!E:E,"") -> 0 | K12: =_xlfn.XLOOKUP(A12,'2025'!A:A,'2025'!F:F,"") -> 0
A13: Volkswagen | B13: =_xlfn.XLOOKUP(A13,'2021'!A:A,'2021'!U:U, "") -> 1 | C13: =_xlfn.XLOOKUP(A13,'2021'!A:A,'2021'!V:V,"") | D13: =_xlfn.XLOOKUP(A13,'2022'!A:A,'2022'!V:V,"") -> 1 | E13: =_xlfn.XLOOKUP(A13,'2022'!A:A,'2022'!W:W,"") | F13: =_xlfn.XLOOKUP(A13,'2023'!B:B,'2023'!AD:AD,"") -> 1 | G13: =_xlfn.XLOOKUP(A13,'2023'!B:B,'2023'!AE:AE,"") | H13: =_xlfn.XLOOKUP(A13,'2024'!B:B,'2024'!AV:AV,"") -> 1 | I13: =_xlfn.XLOOKUP(A13,'2024'!B:B,'2024'!AZ:AZ,"") -> 0 | J13: =_xlfn.XLOOKUP(A13,'2025'!A:A,'2025'!E:E,"") -> 1 | K13: =_xlfn.XLOOKUP(A13,'2025'!A:A,'2025'!F:F,"") -> 0
A14: Alphabet | B14: =_xlfn.XLOOKUP(A14,'2021'!A:A,'2021'!U:U, "") -> 1 | C14: =_xlfn.XLOOKUP(A14,'2021'!A:A,'2021'!V:V,"") | D14: =_xlfn.XLOOKUP(A14,'2022'!A:A,'2022'!V:V,"") -> 1 | E14: =_xlfn.XLOOKUP(A14,'2022'!A:A,'2022'!W:W,"") -> 1 | F14: =_xlfn.XLOOKUP(A14,'2023'!B:B,'2023'!AD:AD,"") | G14: =_xlfn.XLOOKUP(A14,'2023'!B:B,'2023'!AE:AE,"") -> 1 | H14: =_xlfn.XLOOKUP(A14,'2024'!B:B,'2024'!AV:AV,"") | I14: =_xlfn.XLOOKUP(A14,'2024'!B:B,'2024'!AZ:AZ,"") -> 1 | J14: =_xlfn.XLOOKUP(A14,'2025'!A:A,'2025'!E:E,"") -> 0 | K14: =_xlfn.XLOOKUP(A14,'2025'!A:A,'2025'!F:F,"") -> 1
... A501: Heineken | B501: =_xlfn.XLOOKUP(A501,'2021'!A:A,'2021'!U:U, "") | C501: =_xlfn.XLOOKUP(A501,'2021'!A:A,'2021'!V:V,"") | D501: =_xlfn.XLOOKUP(A501,'2022'!A:A,'2022'!V:V,"") | E501: =_xlfn.XLOOKUP(A501,'2022'!A:A,'2022'!W:W,"") | F501: =_xlfn.XLOOKUP(A501,'2023'!B:B,'2023'!AD:AD,"") | G501: =_xlfn.XLOOKUP(A501,'2023'!B:B,'2023'!AE:AE,"") | H501: =_xlfn.XLOOKUP(A501,'2024'!B:B,'2024'!AV:AV,"") | I501: =_xlfn.XLOOKUP(A501,'2024'!B:B,'2024'!AZ:AZ,"") -> 1 | J501: =_xlfn.XLOOKUP(A501,'2025'!A:A,'2025'!E:E,"") -> 0 | K501: =_xlfn.XLOOKUP(A501,'2025'!A:A,'2025'!F:F,"") -> 1
A502: 489 | B502: =_xlfn.XLOOKUP(A502,'2021'!A:A,'2021'!U:U, "") | C502: =_xlfn.XLOOKUP(A502,'2021'!A:A,'2021'!V:V,"") | D502: =_xlfn.XLOOKUP(A502,'2022'!A:A,'2022'!V:V,"") | E502: =_xlfn.XLOOKUP(A502,'2022'!A:A,'2022'!W:W,"") | F502: =_xlfn.XLOOKUP(A502,'2023'!B:B,'2023'!AD:AD,"") | G502: =_xlfn.XLOOKUP(A502,'2023'!B:B,'2023'!AE:AE,"") | H502: =_xlfn.XLOOKUP(A502,'2024'!B:B,'2024'!AV:AV,"") | I502: =_xlfn.XLOOKUP(A502,'2024'!B:B,'2024'!AZ:AZ,"") | J502: =_xlfn.XLOOKUP(A502,'2025'!A:A,'2025'!E:E,"") | K502: =_xlfn.XLOOKUP(A502,'2025'!A:A,'2025'!F:F,"")
A503: 498 | B503: =_xlfn.XLOOKUP(A503,'2021'!A:A,'2021'!U:U, "") | C503: =_xlfn.XLOOKUP(A503,'2021'!A:A,'2021'!V:V,"") | D503: =_xlfn.XLOOKUP(A503,'2022'!A:A,'2022'!V:V,"") | E503: =_xlfn.XLOOKUP(A503,'2022'!A:A,'2022'!W:W,"") | F503: =_xlfn.XLOOKUP(A503,'2023'!B:B,'2023'!AD:AD,"") | G503: =_xlfn.XLOOKUP(A503,'2023'!B:B,'2023'!AE:AE,"") | H503: =_xlfn.XLOOKUP(A503,'2024'!B:B,'2024'!AV:AV,"") | I503: =_xlfn.XLOOKUP(A503,'2024'!B:B,'2024'!AZ:AZ,"") | J503: =_xlfn.XLOOKUP(A503,'2025'!A:A,'2025'!E:E,"") | K503: =_xlfn.XLOOKUP(A503,'2025'!A:A,'2025'!F:F,"")
A504: 376 | B504: =_xlfn.XLOOKUP(A504,'2021'!A:A,'2021'!U:U, "") | C504: =_xlfn.XLOOKUP(A504,'2021'!A:A,'2021'!V:V,"") | D504: =_xlfn.XLOOKUP(A504,'2022'!A:A,'2022'!V:V,"") | E504: =_xlfn.XLOOKUP(A504,'2022'!A:A,'2022'!W:W,"") | F504: =_xlfn.XLOOKUP(A504,'2023'!B:B,'2023'!AD:AD,"") | G504: =_xlfn.XLOOKUP(A504,'2023'!B:B,'2023'!AE:AE,"") | H504: =_xlfn.XLOOKUP(A504,'2024'!B:B,'2024'!AV:AV,"") | I504: =_xlfn.XLOOKUP(A504,'2024'!B:B,'2024'!AZ:AZ,"") | J504: =_xlfn.XLOOKUP(A504,'2025'!A:A,'2025'!E:E,"") | K504: =_xlfn.XLOOKUP(A504,'2025'!A:A,'2025'!F:F,"")
A505: 259 | B505: =_xlfn.XLOOKUP(A505,'2021'!A:A,'2021'!U:U, "") | C505: =_xlfn.XLOOKUP(A505,'2021'!A:A,'2021'!V:V,"") | D505: =_xlfn.XLOOKUP(A505,'2022'!A:A,'2022'!V:V,"") | E505: =_xlfn.XLOOKUP(A505,'2022'!A:A,'2022'!W:W,"") | F505: =_xlfn.XLOOKUP(A505,'2023'!B:B,'2023'!AD:AD,"") | G505: =_xlfn.XLOOKUP(A505,'2023'!B:B,'2023'!AE:AE,"") | H505: =_xlfn.XLOOKUP(A505,'2024'!B:B,'2024'!AV:AV,"") | I505: =_xlfn.XLOOKUP(A505,'2024'!B:B,'2024'!AZ:AZ,"") | J505: =_xlfn.XLOOKUP(A505,'2025'!A:A,'2025'!E:E,"") | K505: =_xlfn.XLOOKUP(A505,'2025'!A:A,'2025'!F:F,"")
A506: 211 | B506: =_xlfn.XLOOKUP(A506,'2021'!A:A,'2021'!U:U, "") | C506: =_xlfn.XLOOKUP(A506,'2021'!A:A,'2021'!V:V,"") | D506: =_xlfn.XLOOKUP(A506,'2022'!A:A,'2022'!V:V,"") | E506: =_xlfn.XLOOKUP(A506,'2022'!A:A,'2022'!W:W,"") | F506: =_xlfn.XLOOKUP(A506,'2023'!B:B,'2023'!AD:AD,"") | G506: =_xlfn.XLOOKUP(A506,'2023'!B:B,'2023'!AE:AE,"") | H506: =_xlfn.XLOOKUP(A506,'2024'!B:B,'2024'!AV:AV,"") | I506: =_xlfn.XLOOKUP(A506,'2024'!B:B,'2024'!AZ:AZ,"") | J506: =_xlfn.XLOOKUP(A506,'2025'!A:A,'2025'!E:E,"") | K506: =_xlfn.XLOOKUP(A506,'2025'!A:A,'2025'!F:F,"")
A507: 391 | B507: =_xlfn.XLOOKUP(A507,'2021'!A:A,'2021'!U:U, "") | C507: =_xlfn.XLOOKUP(A507,'2021'!A:A,'2021'!V:V,"") | D507: =_xlfn.XLOOKUP(A507,'2022'!A:A,'2022'!V:V,"") | E507: =_xlfn.XLOOKUP(A507,'2022'!A:A,'2022'!W:W,"") | F507: =_xlfn.XLOOKUP(A507,'2023'!B:B,'2023'!AD:AD,"") | G507: =_xlfn.XLOOKUP(A507,'2023'!B:B,'2023'!AE:AE,"") | H507: =_xlfn.XLOOKUP(A507,'2024'!B:B,'2024'!AV:AV,"") | I507: =_xlfn.XLOOKUP(A507,'2024'!B:B,'2024'!AZ:AZ,"") | J507: =_xlfn.XLOOKUP(A507,'2025'!A:A,'2025'!E:E,"") | K507: =_xlfn.XLOOKUP(A507,'2025'!A:A,'2025'!F:F,"")
A508: 203 | B508: =_xlfn.XLOOKUP(A508,'2021'!A:A,'2021'!U:U, "") | C508: =_xlfn.XLOOKUP(A508,'2021'!A:A,'2021'!V:V,"") | D508: =_xlfn.XLOOKUP(A508,'2022'!A:A,'2022'!V:V,"") | E508: =_xlfn.XLOOKUP(A508,'2022'!A:A,'2022'!W:W,"") | F508: =_xlfn.XLOOKUP(A508,'2023'!B:B,'2023'!AD:AD,"") | G508: =_xlfn.XLOOKUP(A508,'2023'!B:B,'2023'!AE:AE,"") | H508: =_xlfn.XLOOKUP(A508,'2024'!B:B,'2024'!AV:AV,"") | I508: =_xlfn.XLOOKUP(A508,'2024'!B:B,'2024'!AZ:AZ,"") | J508: =_xlfn.XLOOKUP(A508,'2025'!A:A,'2025'!E:E,"") | K508: =_xlfn.XLOOKUP(A508,'2025'!A:A,'2025'!F:F,"")
A509: 34 | B509: =_xlfn.XLOOKUP(A509,'2021'!A:A,'2021'!U:U, "") | C509: =_xlfn.XLOOKUP(A509,'2021'!A:A,'2021'!V:V,"") | D509: =_xlfn.XLOOKUP(A509,'2022'!A:A,'2022'!V:V,"") | E509: =_xlfn.XLOOKUP(A509,'2022'!A:A,'2022'!W:W,"") | F509: =_xlfn.XLOOKUP(A509,'2023'!B:B,'2023'!AD:AD,"") | G509: =_xlfn.XLOOKUP(A509,'2023'!B:B,'2023'!AE:AE,"") | H509: =_xlfn.XLOOKUP(A509,'2024'!B:B,'2024'!AV:AV,"") | I509: =_xlfn.XLOOKUP(A509,'2024'!B:B,'2024'!AZ:AZ,"") | J509: =_xlfn.XLOOKUP(A509,'2025'!A:A,'2025'!E:E,"") | K509: =_xlfn.XLOOKUP(A509,'2025'!A:A,'2025'!F:F,"")
A510: 446 | B510: =_xlfn.XLOOKUP(A510,'2021'!A:A,'2021'!U:U, "") | C510: =_xlfn.XLOOKUP(A510,'2021'!A:A,'2021'!V:V,"") | D510: =_xlfn.XLOOKUP(A510,'2022'!A:A,'2022'!V:V,"") | E510: =_xlfn.XLOOKUP(A510,'2022'!A:A,'2022'!W:W,"") | F510: =_xlfn.XLOOKUP(A510,'2023'!B:B,'2023'!AD:AD,"") | G510: =_xlfn.XLOOKUP(A510,'2023'!B:B,'2023'!AE:AE,"") | H510: =_xlfn.XLOOKUP(A510,'2024'!B:B,'2024'!AV:AV,"") | I510: =_xlfn.XLOOKUP(A510,'2024'!B:B,'2024'!AZ:AZ,"") | J510: =_xlfn.XLOOKUP(A510,'2025'!A:A,'2025'!E:E,"") | K510: =_xlfn.XLOOKUP(A510,'2025'!A:A,'2025'!F:F,"")
A511: 324 | B511: =_xlfn.XLOOKUP(A511,'2021'!A:A,'2021'!U:U, "") | C511: =_xlfn.XLOOKUP(A511,'2021'!A:A,'2021'!V:V,"") | D511: =_xlfn.XLOOKUP(A511,'2022'!A:A,'2022'!V:V,"") | E511: =_xlfn.XLOOKUP(A511,'2022'!A:A,'2022'!W:W,"") | F511: =_xlfn.XLOOKUP(A511,'2023'!B:B,'2023'!AD:AD,"") | G511: =_xlfn.XLOOKUP(A511,'2023'!B:B,'2023'!AE:AE,"") | H511: =_xlfn.XLOOKUP(A511,'2024'!B:B,'2024'!AV:AV,"") | I511: =_xlfn.XLOOKUP(A511,'2024'!B:B,'2024'!AZ:AZ,"") | J511: =_xlfn.XLOOKUP(A511,'2025'!A:A,'2025'!E:E,"") | K511: =_xlfn.XLOOKUP(A511,'2025'!A:A,'2025'!F:F,"")
A512: 496 | B512: =_xlfn.XLOOKUP(A512,'2021'!A:A,'2021'!U:U, "") | C512: =_xlfn.XLOOKUP(A512,'2021'!A:A,'2021'!V:V,"") | D512: =_xlfn.XLOOKUP(A512,'2022'!A:A,'2022'!V:V,"") | E512: =_xlfn.XLOOKUP(A512,'2022'!A:A,'2022'!W:W,"") | F512: =_xlfn.XLOOKUP(A512,'2023'!B:B,'2023'!AD:AD,"") | G512: =_xlfn.XLOOKUP(A512,'2023'!B:B,'2023'!AE:AE,"") | H512: =_xlfn.XLOOKUP(A512,'2024'!B:B,'2024'!AV:AV,"") | I512: =_xlfn.XLOOKUP(A512,'2024'!B:B,'2024'!AZ:AZ,"") | J512: =_xlfn.XLOOKUP(A512,'2025'!A:A,'2025'!E:E,"") | K512: =_xlfn.XLOOKUP(A512,'2025'!A:A,'2025'!F:F,"")
A513: 183 | B513: =_xlfn.XLOOKUP(A513,'2021'!A:A,'2021'!U:U, "") | C513: =_xlfn.XLOOKUP(A513,'2021'!A:A,'2021'!V:V,"") | D513: =_xlfn.XLOOKUP(A513,'2022'!A:A,'2022'!V:V,"") | E513: =_xlfn.XLOOKUP(A513,'2022'!A:A,'2022'!W:W,"") | F513: =_xlfn.XLOOKUP(A513,'2023'!B:B,'2023'!AD:AD,"") | G513: =_xlfn.XLOOKUP(A513,'2023'!B:B,'2023'!AE:AE,"") | H513: =_xlfn.XLOOKUP(A513,'2024'!B:B,'2024'!AV:AV,"") | I513: =_xlfn.XLOOKUP(A513,'2024'!B:B,'2024'!AZ:AZ,"") | J513: =_xlfn.XLOOKUP(A513,'2025'!A:A,'2025'!E:E,"") | K513: =_xlfn.XLOOKUP(A513,'2025'!A:A,'2025'!F:F,"")
... A1001: 224 | B1001: =_xlfn.XLOOKUP(A1001,'2021'!A:A,'2021'!U:U, "") | C1001: =_xlfn.XLOOKUP(A1001,'2021'!A:A,'2021'!V:V,"") | D1001: =_xlfn.XLOOKUP(A1001,'2022'!A:A,'2022'!V:V,"") | E1001: =_xlfn.XLOOKUP(A1001,'2022'!A:A,'2022'!W:W,"") | F1001: =_xlfn.XLOOKUP(A1001,'2023'!B:B,'2023'!AD:AD,"") | G1001: =_xlfn.XLOOKUP(A1001,'2023'!B:B,'2023'!AE:AE,"") | H1001: =_xlfn.XLOOKUP(A1001,'2024'!B:B,'2024'!AV:AV,"") | I1001: =_xlfn.XLOOKUP(A1001,'2024'!B:B,'2024'!AZ:AZ,"") | J1001: =_xlfn.XLOOKUP(A1001,'2025'!A:A,'2025'!E:E,"") | K1001: =_xlfn.XLOOKUP(A1001,'2025'!A:A,'2025'!F:F,"")
A1002: AmerisourceBergen | B1002: =_xlfn.XLOOKUP(A1002,'2021'!A:A,'2021'!U:U, "") | C1002: =_xlfn.XLOOKUP(A1002,'2021'!A:A,'2021'!V:V,"") | D1002: =_xlfn.XLOOKUP(A1002,'2022'!A:A,'2022'!V:V,"") | E1002: =_xlfn.XLOOKUP(A1002,'2022'!A:A,'2022'!W:W,"") | F1002: =_xlfn.XLOOKUP(A1002,'2023'!B:B,'2023'!AD:AD,"") | G1002: =_xlfn.XLOOKUP(A1002,'2023'!B:B,'2023'!AE:AE,"") | H1002: =_xlfn.XLOOKUP(A1002,'2024'!B:B,'2024'!AV:AV,"") | I1002: =_xlfn.XLOOKUP(A1002,'2024'!B:B,'2024'!AZ:AZ,"") | J1002: =_xlfn.XLOOKUP(A1002,'2025'!A:A,'2025'!E:E,"") | K1002: =_xlfn.XLOOKUP(A1002,'2025'!A:A,'2025'!F:F,"")
A1003: Sinochem Holdings | B1003: =_xlfn.XLOOKUP(A1003,'2021'!A:A,'2021'!U:U, "") | C1003: =_xlfn.XLOOKUP(A1003,'2021'!A:A,'2021'!V:V,"") | D1003: =_xlfn.XLOOKUP(A1003,'2022'!A:A,'2022'!V:V,"") | E1003: =_xlfn.XLOOKUP(A1003,'2022'!A:A,'2022'!W:W,"") | F1003: =_xlfn.XLOOKUP(A1003,'2023'!B:B,'2023'!AD:AD,"") | G1003: =_xlfn.XLOOKUP(A1003,'2023'!B:B,'2023'!AE:AE,"") | H1003: =_xlfn.XLOOKUP(A1003,'2024'!B:B,'2024'!AV:AV,"") | I1003: =_xlfn.XLOOKUP(A1003,'2024'!B:B,'2024'!AZ:AZ,"") -> 0 | J1003: =_xlfn.XLOOKUP(A1003,'2025'!A:A,'2025'!E:E,"") | K1003: =_xlfn.XLOOKUP(A1003,'2025'!A:A,'2025'!F:F,"")
A1004: Electricité de France | B1004: =_xlfn.XLOOKUP(A1004,'2021'!A:A,'2021'!U:U, "") -> 1 | C1004: =_xlfn.XLOOKUP(A1004,'2021'!A:A,'2021'!V:V,"") | D1004: =_xlfn.XLOOKUP(A1004,'2022'!A:A,'2022'!V:V,"") -> 1 | E1004: =_xlfn.XLOOKUP(A1004,'2022'!A:A,'2022'!W:W,"") | F1004: =_xlfn.XLOOKUP(A1004,'2023'!B:B,'2023'!AD:AD,"") | G1004: =_xlfn.XLOOKUP(A1004,'2023'!B:B,'2023'!AE:AE,"") -> 1 | H1004: =_xlfn.XLOOKUP(A1004,'2024'!B:B,'2024'!AV:AV,"") | I1004: =_xlfn.XLOOKUP(A1004,'2024'!B:B,'2024'!AZ:AZ,"") | J1004: =_xlfn.XLOOKUP(A1004,'2025'!A:A,'2025'!E:E,"") | K1004: =_xlfn.XLOOKUP(A1004,'2025'!A:A,'2025'!F:F,"")
A1005: SK Group | B1005: =_xlfn.XLOOKUP(A1005,'2021'!A:A,'2021'!U:U, "") | C1005: =_xlfn.XLOOKUP(A1005,'2021'!A:A,'2021'!V:V,"") | D1005: =_xlfn.XLOOKUP(A1005,'2022'!A:A,'2022'!V:V,"") | E1005: =_xlfn.XLOOKUP(A1005,'2022'!A:A,'2022'!W:W,"") -> 1 | F1005: =_xlfn.XLOOKUP(A1005,'2023'!B:B,'2023'!AD:AD,"") | G1005: =_xlfn.XLOOKUP(A1005,'2023'!B:B,'2023'!AE:AE,"") -> 1 | H1005: =_xlfn.XLOOKUP(A1005,'2024'!B:B,'2024'!AV:AV,"") | I1005: =_xlfn.XLOOKUP(A1005,'2024'!B:B,'2024'!AZ:AZ,"") | J1005: =_xlfn.XLOOKUP(A1005,'2025'!A:A,'2025'!E:E,"") | K1005: =_xlfn.XLOOKUP(A1005,'2025'!A:A,'2025'!F:F,"")
A1006: Deutsche Post DHL Group | B1006: =_xlfn.XLOOKUP(A1006,'2021'!A:A,'2021'!U:U, "") | C1006: =_xlfn.XLOOKUP(A1006,'2021'!A:A,'2021'!V:V,"") -> 1 | D1006: =_xlfn.XLOOKUP(A1006,'2022'!A:A,'2022'!V:V,"") | E1006: =_xlfn.XLOOKUP(A1006,'2022'!A:A,'2022'!W:W,"") -> 1 | F1006: =_xlfn.XLOOKUP(A1006,'2023'!B:B,'2023'!AD:AD,"") | G1006: =_xlfn.XLOOKUP(A1006,'2023'!B:B,'2023'!AE:AE,"") -> 1 | H1006: =_xlfn.XLOOKUP(A1006,'2024'!B:B,'2024'!AV:AV,"") | I1006: =_xlfn.XLOOKUP(A1006,'2024'!B:B,'2024'!AZ:AZ,"") | J1006: =_xlfn.XLOOKUP(A1006,'2025'!A:A,'2025'!E:E,"") | K1006: =_xlfn.XLOOKUP(A1006,'2025'!A:A,'2025'!F:F,"")
A1007: Nippon Telegraph and Telephone | B1007: =_xlfn.XLOOKUP(A1007,'2021'!A:A,'2021'!U:U, "") | C1007: =_xlfn.XLOOKUP(A1007,'2021'!A:A,'2021'!V:V,"") | D1007: =_xlfn.XLOOKUP(A1007,'2022'!A:A,'2022'!V:V,"") -> 1 | E1007: =_xlfn.XLOOKUP(A1007,'2022'!A:A,'2022'!W:W,"") | F1007: =_xlfn.XLOOKUP(A1007,'2023'!B:B,'2023'!AD:AD,"") -> 1 | G1007: =_xlfn.XLOOKUP(A1007,'2023'!B:B,'2023'!AE:AE,"") | H1007: =_xlfn.XLOOKUP(A1007,'2024'!B:B,'2024'!AV:AV,"") -> 1 | I1007: =_xlfn.XLOOKUP(A1007,'2024'!B:B,'2024'!AZ:AZ,"") -> 0 | J1007: =_xlfn.XLOOKUP(A1007,'2025'!A:A,'2025'!E:E,"") | K1007: =_xlfn.XLOOKUP(A1007,'2025'!A:A,'2025'!F:F,"")
A1008: Brookfield Asset Management | B1008: =_xlfn.XLOOKUP(A1008,'2021'!A:A,'2021'!U:U, "") | C1008: =_xlfn.XLOOKUP(A1008,'2021'!A:A,'2021'!V:V,"") -> 1 | D1008: =_xlfn.XLOOKUP(A1008,'2022'!A:A,'2022'!V:V,"") | E1008: =_xlfn.XLOOKUP(A1008,'2022'!A:A,'2022'!W:W,"") -> 1 | F1008: =_xlfn.XLOOKUP(A1008,'2023'!B:B,'2023'!AD:AD,"") | G1008: =_xlfn.XLOOKUP(A1008,'2023'!B:B,'2023'!AE:AE,"") -> 1 | H1008: =_xlfn.XLOOKUP(A1008,'2024'!B:B,'2024'!AV:AV,"") | I1008: =_xlfn.XLOOKUP(A1008,'2024'!B:B,'2024'!AZ:AZ,"") | J1008: =_xlfn.XLOOKUP(A1008,'2025'!A:A,'2025'!E:E,"") | K1008: =_xlfn.XLOOKUP(A1008,'2025'!A:A,'2025'!F:F,"")
A1009: Amer International Group | B1009: =_xlfn.XLOOKUP(A1009,'2021'!A:A,'2021'!U:U, "") | C1009: =_xlfn.XLOOKUP(A1009,'2021'!A:A,'2021'!V:V,"") | D1009: =_xlfn.XLOOKUP(A1009,'2022'!A:A,'2022'!V:V,"") | E1009: =_xlfn.XLOOKUP(A1009,'2022'!A:A,'2022'!W:W,"") | F1009: =_xlfn.XLOOKUP(A1009,'2023'!B:B,'2023'!AD:AD,"") | G1009: =_xlfn.XLOOKUP(A1009,'2023'!B:B,'2023'!AE:AE,"") | H1009: =_xlfn.XLOOKUP(A1009,'2024'!B:B,'2024'!AV:AV,"") | I1009: =_xlfn.XLOOKUP(A1009,'2024'!B:B,'2024'!AZ:AZ,"") | J1009: =_xlfn.XLOOKUP(A1009,'2025'!A:A,'2025'!E:E,"") | K1009: =_xlfn.XLOOKUP(A1009,'2025'!A:A,'2025'!F:F,"")
A1010: Crédit Agricole | B1010: =_xlfn.XLOOKUP(A1010,'2021'!A:A,'2021'!U:U, "") | C1010: =_xlfn.XLOOKUP(A1010,'2021'!A:A,'2021'!V:V,"") -> 1 | D1010: =_xlfn.XLOOKUP(A1010,'2022'!A:A,'2022'!V:V,"") | E1010: =_xlfn.XLOOKUP(A1010,'2022'!A:A,'2022'!W:W,"") | F1010: =_xlfn.XLOOKUP(A1010,'2023'!B:B,'2023'!AD:AD,"") -> 1 | G1010: =_xlfn.XLOOKUP(A1010,'2023'!B:B,'2023'!AE:AE,"") | H1010: =_xlfn.XLOOKUP(A1010,'2024'!B:B,'2024'!AV:AV,"") | I1010: =_xlfn.XLOOKUP(A1010,'2024'!B:B,'2024'!AZ:AZ,"") | J1010: =_xlfn.XLOOKUP(A1010,'2025'!A:A,'2025'!E:E,"") | K1010: =_xlfn.XLOOKUP(A1010,'2025'!A:A,'2025'!F:F,"")
A1011: Aviation Industry Corp. of China | B1011: =_xlfn.XLOOKUP(A1011,'2021'!A:A,'2021'!U:U, "") | C1011: =_xlfn.XLOOKUP(A1011,'2021'!A:A,'2021'!V:V,"") | D1011: =_xlfn.XLOOKUP(A1011,'2022'!A:A,'2022'!V:V,"") | E1011: =_xlfn.XLOOKUP(A1011,'2022'!A:A,'2022'!W:W,"") -> 1 | F1011: =_xlfn.XLOOKUP(A1011,'2023'!B:B,'2023'!AD:AD,"") | G1011: =_xlfn.XLOOKUP(A1011,'2023'!B:B,'2023'!AE:AE,"") | H1011: =_xlfn.XLOOKUP(A1011,'2024'!B:B,'2024'!AV:AV,"") | I1011: =_xlfn.XLOOKUP(A1011,'2024'!B:B,'2024'!AZ:AZ,"") -> 1 | J1011: =_xlfn.XLOOKUP(A1011,'2025'!A:A,'2025'!E:E,"") | K1011: =_xlfn.XLOOKUP(A1011,'2025'!A:A,'2025'!F:F,"")
A1012: General Electric | B1012: =_xlfn.XLOOKUP(A1012,'2021'!A:A,'2021'!U:U, "") -> 1 | C1012: =_xlfn.XLOOKUP(A1012,'2021'!A:A,'2021'!V:V,"") -> 1 | D1012: =_xlfn.XLOOKUP(A1012,'2022'!A:A,'2022'!V:V,"") -> 1 | E1012: =_xlfn.XLOOKUP(A1012,'2022'!A:A,'2022'!W:W,"") -> 1 | F1012: =_xlfn.XLOOKUP(A1012,'2023'!B:B,'2023'!AD:AD,"") | G1012: =_xlfn.XLOOKUP(A1012,'2023'!B:B,'2023'!AE:AE,"") -> 1 | H1012: =_xlfn.XLOOKUP(A1012,'2024'!B:B,'2024'!AV:AV,"") | I1012: =_xlfn.XLOOKUP(A1012,'2024'!B:B,'2024'!AZ:AZ,"") -> 1 | J1012: =_xlfn.XLOOKUP(A1012,'2025'!A:A,'2025'!E:E,"") | K1012: =_xlfn.XLOOKUP(A1012,'2025'!A:A,'2025'!F:F,"")
A1013: China Merchants Group | B1013: =_xlfn.XLOOKUP(A1013,'2021'!A:A,'2021'!U:U, "") | C1013: =_xlfn.XLOOKUP(A1013,'2021'!A:A,'2021'!V:V,"") | D1013: =_xlfn.XLOOKUP(A1013,'2022'!A:A,'2022'!V:V,"") | E1013: =_xlfn.XLOOKUP(A1013,'2022'!A:A,'2022'!W:W,"") | F1013: =_xlfn.XLOOKUP(A1013,'2023'!B:B,'2023'!AD:AD,"") | G1013: =_xlfn.XLOOKUP(A1013,'2023'!B:B,'2023'!AE:AE,"") | H1013: =_xlfn.XLOOKUP(A1013,'2024'!B:B,'2024'!AV:AV,"") | I1013: =_xlfn.XLOOKUP(A1013,'2024'!B:B,'2024'!AZ:AZ,"") | J1013: =_xlfn.XLOOKUP(A1013,'2025'!A:A,'2025'!E:E,"") | K1013: =_xlfn.XLOOKUP(A1013,'2025'!A:A,'2025'!F:F,"")
...

Sheet sbti nz
A1: company | B1: 2021 sbti nt | C1: 2021 nz | D1: 2022 sbti nt | E1: 2022 nz | F1: 2023 sbti nt | G1: 2023 nz | H1: 2024 sbti nt | I1: 2024 nz | J1: 2025 sbti nt | K1: 2025 nz
A2: {=_xlfn.UNIQUE(_xlfn.VSTACK(sbti!A3:A502,sbti!F3:F503,sbti!L3:L502,sbti!R3:R502,sbti!W3:W502))} -> Walmart | B2: =_xlfn.XLOOKUP(A2,'2021'!A:A,'2021'!X:X,"") -> 1 | C2: =_xlfn.XLOOKUP(A2,'2021'!A:A,'2021'!V:V,"") -> 1 | D2: =_xlfn.XLOOKUP(A2,'2022'!A:A,'2022'!X:X,"") -> 1 | E2: =_xlfn.XLOOKUP(A2,'2022'!A:A,'2022'!W:W,"") -> 1 | F2: =_xlfn.XLOOKUP(A2,'2023'!B:B,'2023'!AF:AF,"") -> 1 | G2: =_xlfn.XLOOKUP(A2,'2023'!B:B,'2023'!AE:AE,"") -> 1 | H2: =_xlfn.XLOOKUP(A2,'2024'!B:B,'2024'!BW:BW,"") -> 1 | I2: =_xlfn.XLOOKUP(A2,'2024'!B:B,'2024'!AZ:AZ,"") -> 1 | J2: =_xlfn.XLOOKUP(A2,'2025'!A:A,'2025'!C:C,"") -> 1 | K2: =_xlfn.XLOOKUP(A2,'2025'!A:A,'2025'!F:F,"") -> 1
A3: Amazon | B3: =_xlfn.XLOOKUP(A3,'2021'!A:A,'2021'!X:X,"") | C3: =_xlfn.XLOOKUP(A3,'2021'!A:A,'2021'!V:V,"") -> 1 | D3: =_xlfn.XLOOKUP(A3,'2022'!A:A,'2022'!X:X,"") | E3: =_xlfn.XLOOKUP(A3,'2022'!A:A,'2022'!W:W,"") -> 1 | F3: =_xlfn.XLOOKUP(A3,'2023'!B:B,'2023'!AF:AF,"") | G3: =_xlfn.XLOOKUP(A3,'2023'!B:B,'2023'!AE:AE,"") -> 1 | H3: =_xlfn.XLOOKUP(A3,'2024'!B:B,'2024'!BW:BW,"") | I3: =_xlfn.XLOOKUP(A3,'2024'!B:B,'2024'!AZ:AZ,"") -> 1 | J3: =_xlfn.XLOOKUP(A3,'2025'!A:A,'2025'!C:C,"") -> 0 | K3: =_xlfn.XLOOKUP(A3,'2025'!A:A,'2025'!F:F,"") -> 1
